Workbook

Sheet Prezzo
A1: LISTINO — TELAIO FISSO (TF75) — C75S SENZA VETRO — RAL 7016 (costo +213%)
A2: H/L | B2: 500 | C2: 600 | D2: 700 | E2: 800 | F2: 900 | G2: 1000 | H2: 1100 | I2: 1200 | J2: 1300 | K2: 1400 | L2: 1500 | M2: 1600 | N2: 1700 | O2: 1800 | P2: 1900 | Q2: 2000 | R2: 2100 | S2: 2200 | T2: 2300 | U2: 2400 | V2: 2500 | W2: 2600 | X2: 2700 | Y2: 2800 | Z2: 2900 | AA2: 3000
A3: 600 | B3: =ROUND(ROUND((((Coefficienti!$B$1+Coefficienti!$B$2*B$2+Coefficienti!$B$3*$A3)*Parametri!$B$1+(Coefficienti!$B$4+Coefficienti!$B$5*B$2+Coefficienti!$B$6*$A3)*Parametri!$B$2)*(1-Parametri!$B$3)+((Coefficienti!$B$7+Coefficienti!$B$8*B$2+Coefficienti!$B$9*$A3)+Coefficienti!$B$10)*(1-Parametri!$B$4))*(1+Parametri!$B$5)+FerrGriglia!B2+Coefficienti!$B$11*Parametri!$B$6,2)*(1+Parametri!$B$7),2) | C3: =ROUND(ROUND((((Coefficienti!$B$1+Coefficienti!$B$2*C$2+Coefficienti!$B$3*$A3)*Parametri!$B$1+(Coefficienti!$B$4+Coefficienti!$B$5*C$2+Coefficienti!$B$6*$A3)*Parametri!$B$2)*(1-Parametri!$B$3)+((Coefficienti!$B$7+Coefficienti!$B$8*C$2+Coefficienti!$B$9*$A3)+Coefficienti!$B$10)*(1-Parametri!$B$4))*(1+Parametri!$B$5)+FerrGriglia!C2+Coefficienti!$B$11*Parametri!$B$6,2)*(1+Parametri!$B$7),2) | D3: =ROUND(ROUND((((Coefficienti!$B$1+Coefficienti!$B$2*D$2+Coefficienti!$B$3*$A3)*Parametri!$B$1+(Coefficienti!$B$4+Coefficienti!$B$5*D$2+Coefficienti!$B$6*$A3)*Parametri!$B$2)*(1-Parametri!$B$3)+((Coefficienti!$B$7+Coefficienti!$B$8*D$2+Coefficienti!$B$9*$A3)+Coefficienti!$B$10)*(1-Parametri!$B$4))*(1+Parametri!$B$5)+FerrGriglia!D2+Coefficienti!$B$11*Parametri!$B$6,2)*(1+Parametri!$B$7),2) | E3: =ROUND(ROUND((((Coefficienti!$B$1+Coefficienti!$B$2*E$2+Coefficienti!$B$3*$A3)*Parametri!$B$1+(Coefficienti!$B$4+Coefficienti!$B$5*E$2+Coefficienti!$B$6*$A3)*Parametri!$B$2)*(1-Parametri!$B$3)+((Coefficienti!$B$7+Coefficienti!$B$8*E$2+Coefficienti!$B$9*$A3)+Coefficienti!$B$10)*(1-Parametri!$B$4))*(1+Parametri!$B$5)+FerrGriglia!E2+Coefficienti!$B$11*Parametri!$B$6,2)*(1+Parametri!$B$7),2) | F3: =ROUND(ROUND((((Coefficienti!$B$1+Coefficienti!$B$2*F$2+Coefficienti!$B$3*$A3)*Parametri!$B$1+(Coefficienti!$B$4+Coefficienti!$B$5*F$2+Coefficienti!$B$6*$A3)*Parametri!$B$2)*(1-Parametri!$B$3)+((Coefficienti!$B$7+Coefficienti!$B$8*F$2+Coefficienti!$B$9*$A3)+Coefficienti!$B$10)*(1-Parametri!$B$4))*(1+Parametri!$B$5)+FerrGriglia!F2+Coefficienti!$B$11*Parametri!$B$6,2)*(1+Parametri!$B$7),2) | G3: =ROUND(ROUND((((Coefficienti!$B$1+Coefficienti!$B$2*G$2+Coefficienti!$B$3*$A3)*Parametri!$B$1+(Coefficienti!$B$4+Coefficienti!$B$5*G$2+Coefficienti!$B$6*$A3)*Parametri!$B$2)*(1-Parametri!$B$3)+((Coefficienti!$B$7+Coefficienti!$B$8*G$2+Coefficienti!$B$9*$A3)+Coefficienti!$B$10)*(1-Parametri!$B$4))*(1+Parametri!$B$5)+FerrGriglia!G2+Coefficienti!$B$11*Parametri!$B$6,2)*(1+Parametri!$B$7),2) | H3: =ROUND(ROUND((((Coefficienti!$B$1+Coefficienti!$B$2*H$2+Coefficienti!$B$3*$A3)*Parametri!$B$1+(Coefficienti!$B$4+Coefficienti!$B$5*H$2+Coefficienti!$B$6*$A3)*Parametri!$B$2)*(1-Parametri!$B$3)+((Coefficienti!$B$7+Coefficienti!$B$8*H$2+Coefficienti!$B$9*$A3)+Coefficienti!$B$10)*(1-Parametri!$B$4))*(1+Parametri!$B$5)+FerrGriglia!H2+Coefficienti!$B$11*Parametri!$B$6,2)*(1+Parametri!$B$7),2) | I3: =ROUND(ROUND((((Coefficienti!$B$1+Coefficienti!$B$2*I$2+Coefficienti!$B$3*$A3)*Parametri!$B$1+(Coefficienti!$B$4+Coefficienti!$B$5*I$2+Coefficienti!$B$6*$A3)*Parametri!$B$2)*(1-Parametri!$B$3)+((Coefficienti!$B$7+Coefficienti!$B$8*I$2+Coefficienti!$B$9*$A3)+Coefficienti!$B$10)*(1-Parametri!$B$4))*(1+Parametri!$B$5)+FerrGriglia!I2+Coefficienti!$B$11*Parametri!$B$6,2)*(1+Parametri!$B$7),2) | ... AA3: =ROUND(ROUND((((Coefficienti!$B$1+Coefficienti!$B$2*AA$2+Coefficienti!$B$3*$A3)*Parametri!$B$1+(Coefficienti!$B$4+Coefficienti!$B$5*AA$2+Coefficienti!$B$6*$A3)*Parametri!$B$2)*(1-Parametri!$B$3)+((Coefficienti!$B$7+Coefficienti!$B$8*AA$2+Coefficienti!$B$9*$A3)+Coefficienti!$B$10)*(1-Parametri!$B$4))*(1+Parametri!$B$5)+FerrGriglia!AA2+Coefficienti!$B$11*Parametri!$B$6,2)*(1+Parametri!$B$7),2)
A4: 700 | B4: =ROUND(ROUND((((Coefficienti!$B$1+Coefficienti!$B$2*B$2+Coefficienti!$B$3*$A4)*Parametri!$B$1+(Coefficienti!$B$4+Coefficienti!$B$5*B$2+Coefficienti!$B$6*$A4)*Parametri!$B$2)*(1-Parametri!$B$3)+((Coefficienti!$B$7+Coefficienti!$B$8*B$2+Coefficienti!$B$9*$A4)+Coefficienti!$B$10)*(1-Parametri!$B$4))*(1+Parametri!$B$5)+FerrGriglia!B3+Coefficienti!$B$11*Parametri!$B$6,2)*(1+Parametri!$B$7),2) | C4: =ROUND(ROUND((((Coefficienti!$B$1+Coefficienti!$B$2*C$2+Coefficienti!$B$3*$A4)*Parametri!$B$1+(Coefficienti!$B$4+Coefficienti!$B$5*C$2+Coefficienti!$B$6*$A4)*Parametri!$B$2)*(1-Parametri!$B$3)+((Coefficienti!$B$7+Coefficienti!$B$8*C$2+Coefficienti!$B$9*$A4)+Coefficienti!$B$10)*(1-Parametri!$B$4))*(1+Parametri!$B$5)+FerrGriglia!C3+Coefficienti!$B$11*Parametri!$B$6,2)*(1+Parametri!$B$7),2) | D4: =ROUND(ROUND((((Coefficienti!$B$1+Coefficienti!$B$2*D$2+Coefficienti!$B$3*$A4)*Parametri!$B$1+(Coefficienti!$B$4+Coefficienti!$B$5*D$2+Coefficienti!$B$6*$A4)*Parametri!$B$2)*(1-Parametri!$B$3)+((Coefficienti!$B$7+Coefficienti!$B$8*D$2+Coefficienti!$B$9*$A4)+Coefficienti!$B$10)*(1-Parametri!$B$4))*(1+Parametri!$B$5)+FerrGriglia!D3+Coefficienti!$B$11*Parametri!$B$6,2)*(1+Parametri!$B$7),2) | E4: =ROUND(ROUND((((Coefficienti!$B$1+Coefficienti!$B$2*E$2+Coefficienti!$B$3*$A4)*Parametri!$B$1+(Coefficienti!$B$4+Coefficienti!$B$5*E$2+Coefficienti!$B$6*$A4)*Parametri!$B$2)*(1-Parametri!$B$3)+((Coefficienti!$B$7+Coefficienti!$B$8*E$2+Coefficienti!$B$9*$A4)+Coefficienti!$B$10)*(1-Parametri!$B$4))*(1+Parametri!$B$5)+FerrGriglia!E3+Coefficienti!$B$11*Parametri!$B$6,2)*(1+Parametri!$B$7),2) | F4: =ROUND(ROUND((((Coefficienti!$B$1+Coefficienti!$B$2*F$2+Coefficienti!$B$3*$A4)*Parametri!$B$1+(Coefficienti!$B$4+Coefficienti!$B$5*F$2+Coefficienti!$B$6*$A4)*Parametri!$B$2)*(1-Parametri!$B$3)+((Coefficienti!$B$7+Coefficienti!$B$8*F$2+Coefficienti!$B$9*$A4)+Coefficienti!$B$10)*(1-Parametri!$B$4))*(1+Parametri!$B$5)+FerrGriglia!F3+Coefficienti!$B$11*Parametri!$B$6,2)*(1+Parametri!$B$7),2) | G4: =ROUND(ROUND((((Coefficienti!$B$1+Coefficienti!$B$2*G$2+Coefficienti!$B$3*$A4)*Parametri!$B$1+(Coefficienti!$B$4+Coefficienti!$B$5*G$2+Coefficienti!$B$6*$A4)*Parametri!$B$2)*(1-Parametri!$B$3)+((Coefficienti!$B$7+Coefficienti!$B$8*G$2+Coefficienti!$B$9*$A4)+Coefficienti!$B$10)*(1-Parametri!$B$4))*(1+Parametri!$B$5)+FerrGriglia!G3+Coefficienti!$B$11*Parametri!$B$6,2)*(1+Parametri!$B$7),2) | H4: =ROUND(ROUND((((Coefficienti!$B$1+Coefficienti!$B$2*H$2+Coefficienti!$B$3*$A4)*Parametri!$B$1+(Coefficienti!$B$4+Coefficienti!$B$5*H$2+Coefficienti!$B$6*$A4)*Parametri!$B$2)*(1-Parametri!$B$3)+((Coefficienti!$B$7+Coefficienti!$B$8*H$2+Coefficienti!$B$9*$A4)+Coefficienti!$B$10)*(1-Parametri!$B$4))*(1+Parametri!$B$5)+FerrGriglia!H3+Coefficienti!$B$11*Parametri!$B$6,2)*(1+Parametri!$B$7),2) | I4: =ROUND(ROUND((((Coefficienti!$B$1+Coefficienti!$B$2*I$2+Coefficienti!$B$3*$A4)*Parametri!$B$1+(Coefficienti!$B$4+Coefficienti!$B$5*I$2+Coefficienti!$B$6*$A4)*Parametri!$B$2)*(1-Parametri!$B$3)+((Coefficienti!$B$7+Coefficienti!$B$8*I$2+Coefficienti!$B$9*$A4)+Coefficienti!$B$10)*(1-Parametri!$B$4))*(1+Parametri!$B$5)+FerrGriglia!I3+Coefficienti!$B$11*Parametri!$B$6,2)*(1+Parametri!$B$7),2) | ... AA4: =ROUND(ROUND((((Coefficienti!$B$1+Coefficienti!$B$2*AA$2+Coefficienti!$B$3*$A4)*Parametri!$B$1+(Coefficienti!$B$4+Coefficienti!$B$5*AA$2+Coefficienti!$B$6*$A4)*Parametri!$B$2)*(1-Parametri!$B$3)+((Coefficienti!$B$7+Coefficienti!$B$8*AA$2+Coefficienti!$B$9*$A4)+Coefficienti!$B$10)*(1-Parametri!$B$4))*(1+Parametri!$B$5)+FerrGriglia!AA3+Coefficienti!$B$11*Parametri!$B$6,2)*(1+Parametri!$B$7),2)
A5: 800 | B5: =ROUND(ROUND((((Coefficienti!$B$1+Coefficienti!$B$2*B$2+Coefficienti!$B$3*$A5)*Parametri!$B$1+(Coefficienti!$B$4+Coefficienti!$B$5*B$2+Coefficienti!$B$6*$A5)*Parametri!$B$2)*(1-Parametri!$B$3)+((Coefficienti!$B$7+Coefficienti!$B$8*B$2+Coefficienti!$B$9*$A5)+Coefficienti!$B$10)*(1-Parametri!$B$4))*(1+Parametri!$B$5)+FerrGriglia!B4+Coefficienti!$B$11*Parametri!$B$6,2)*(1+Parametri!$B$7),2) | C5: =ROUND(ROUND((((Coefficienti!$B$1+Coefficienti!$B$2*C$2+Coefficienti!$B$3*$A5)*Parametri!$B$1+(Coefficienti!$B$4+Coefficienti!$B$5*C$2+Coefficienti!$B$6*$A5)*Parametri!$B$2)*(1-Parametri!$B$3)+((Coefficienti!$B$7+Coefficienti!$B$8*C$2+Coefficienti!$B$9*$A5)+Coefficienti!$B$10)*(1-Parametri!$B$4))*(1+Parametri!$B$5)+FerrGriglia!C4+Coefficienti!$B$11*Parametri!$B$6,2)*(1+Parametri!$B$7),2) | D5: =ROUND(ROUND((((Coefficienti!$B$1+Coefficienti!$B$2*D$2+Coefficienti!$B$3*$A5)*Parametri!$B$1+(Coefficienti!$B$4+Coefficienti!$B$5*D$2+Coefficienti!$B$6*$A5)*Parametri!$B$2)*(1-Parametri!$B$3)+((Coefficienti!$B$7+Coefficienti!$B$8*D$2+Coefficienti!$B$9*$A5)+Coefficienti!$B$10)*(1-Parametri!$B$4))*(1+Parametri!$B$5)+FerrGriglia!D4+Coefficienti!$B$11*Parametri!$B$6,2)*(1+Parametri!$B$7),2) | E5: =ROUND(ROUND((((Coefficienti!$B$1+Coefficienti!$B$2*E$2+Coefficienti!$B$3*$A5)*Parametri!$B$1+(Coefficienti!$B$4+Coefficienti!$B$5*E$2+Coefficienti!$B$6*$A5)*Parametri!$B$2)*(1-Parametri!$B$3)+((Coefficienti!$B$7+Coefficienti!$B$8*E$2+Coefficienti!$B$9*$A5)+Coefficienti!$B$10)*(1-Parametri!$B$4))*(1+Parametri!$B$5)+FerrGriglia!E4+Coefficienti!$B$11*Parametri!$B$6,2)*(1+Parametri!$B$7),2) | F5: =ROUND(ROUND((((Coefficienti!$B$1+Coefficienti!$B$2*F$2+Coefficienti!$B$3*$A5)*Parametri!$B$1+(Coefficienti!$B$4+Coefficienti!$B$5*F$2+Coefficienti!$B$6*$A5)*Parametri!$B$2)*(1-Parametri!$B$3)+((Coefficienti!$B$7+Coefficienti!$B$8*F$2+Coefficienti!$B$9*$A5)+Coefficienti!$B$10)*(1-Parametri!$B$4))*(1+Parametri!$B$5)+FerrGriglia!F4+Coefficienti!$B$11*Parametri!$B$6,2)*(1+Parametri!$B$7),2) | G5: =ROUND(ROUND((((Coefficienti!$B$1+Coefficienti!$B$2*G$2+Coefficienti!$B$3*$A5)*Parametri!$B$1+(Coefficienti!$B$4+Coefficienti!$B$5*G$2+Coefficienti!$B$6*$A5)*Parametri!$B$2)*(1-Parametri!$B$3)+((Coefficienti!$B$7+Coefficienti!$B$8*G$2+Coefficienti!$B$9*$A5)+Coefficienti!$B$10)*(1-Parametri!$B$4))*(1+Parametri!$B$5)+FerrGriglia!G4+Coefficienti!$B$11*Parametri!$B$6,2)*(1+Parametri!$B$7),2) | H5: =ROUND(ROUND((((Coefficienti!$B$1+Coefficienti!$B$2*H$2+Coefficienti!$B$3*$A5)*Parametri!$B$1+(Coefficienti!$B$4+Coefficienti!$B$5*H$2+Coefficienti!$B$6*$A5)*Parametri!$B$2)*(1-Parametri!$B$3)+((Coefficienti!$B$7+Coefficienti!$B$8*H$2+Coefficienti!$B$9*$A5)+Coefficienti!$B$10)*(1-Parametri!$B$4))*(1+Parametri!$B$5)+FerrGriglia!H4+Coefficienti!$B$11*Parametri!$B$6,2)*(1+Parametri!$B$7),2) | I5: =ROUND(ROUND((((Coefficienti!$B$1+Coefficienti!$B$2*I$2+Coefficienti!$B$3*$A5)*Parametri!$B$1+(Coefficienti!$B$4+Coefficienti!$B$5*I$2+Coefficienti!$B$6*$A5)*Parametri!$B$2)*(1-Parametri!$B$3)+((Coefficienti!$B$7+Coefficienti!$B$8*I$2+Coefficienti!$B$9*$A5)+Coefficienti!$B$10)*(1-Parametri!$B$4))*(1+Parametri!$B$5)+FerrGriglia!I4+Coefficienti!$B$11*Parametri!$B$6,2)*(1+Parametri!$B$7),2) | ... AA5: =ROUND(ROUND((((Coefficienti!$B$1+Coefficienti!$B$2*AA$2+Coefficienti!$B$3*$A5)*Parametri!$B$1+(Coefficienti!$B$4+Coefficienti!$B$5*AA$2+Coefficienti!$B$6*$A5)*Parametri!$B$2)*(1-Parametri!$B$3)+((Coefficienti!$B$7+Coefficienti!$B$8*AA$2+Coefficienti!$B$9*$A5)+Coefficienti!$B$10)*(1-Parametri!$B$4))*(1+Parametri!$B$5)+FerrGriglia!AA4+Coefficienti!$B$11*Parametri!$B$6,2)*(1+Parametri!$B$7),2)
A6: 900 | B6: =ROUND(ROUND((((Coefficienti!$B$1+Coefficienti!$B$2*B$2+Coefficienti!$B$3*$A6)*Parametri!$B$1+(Coefficienti!$B$4+Coefficienti!$B$5*B$2+Coefficienti!$B$6*$A6)*Parametri!$B$2)*(1-Parametri!$B$3)+((Coefficienti!$B$7+Coefficienti!$B$8*B$2+Coefficienti!$B$9*$A6)+Coefficienti!$B$10)*(1-Parametri!$B$4))*(1+Parametri!$B$5)+FerrGriglia!B5+Coefficienti!$B$11*Parametri!$B$6,2)*(1+Parametri!$B$7),2) | C6: =ROUND(ROUND((((Coefficienti!$B$1+Coefficienti!$B$2*C$2+Coefficienti!$B$3*$A6)*Parametri!$B$1+(Coefficienti!$B$4+Coefficienti!$B$5*C$2+Coefficienti!$B$6*$A6)*Parametri!$B$2)*(1-Parametri!$B$3)+((Coefficienti!$B$7+Coefficienti!$B$8*C$2+Coefficienti!$B$9*$A6)+Coefficienti!$B$10)*(1-Parametri!$B$4))*(1+Parametri!$B$5)+FerrGriglia!C5+Coefficienti!$B$11*Parametri!$B$6,2)*(1+Parametri!$B$7),2) | D6: =ROUND(ROUND((((Coefficienti!$B$1+Coefficienti!$B$2*D$2+Coefficienti!$B$3*$A6)*Parametri!$B$1+(Coefficienti!$B$4+Coefficienti!$B$5*D$2+Coefficienti!$B$6*$A6)*Parametri!$B$2)*(1-Parametri!$B$3)+((Coefficienti!$B$7+Coefficienti!$B$8*D$2+Coefficienti!$B$9*$A6)+Coefficienti!$B$10)*(1-Parametri!$B$4))*(1+Parametri!$B$5)+FerrGriglia!D5+Coefficienti!$B$11*Parametri!$B$6,2)*(1+Parametri!$B$7),2) | E6: =ROUND(ROUND((((Coefficienti!$B$1+Coefficienti!$B$2*E$2+Coefficienti!$B$3*$A6)*Parametri!$B$1+(Coefficienti!$B$4+Coefficienti!$B$5*E$2+Coefficienti!$B$6*$A6)*Parametri!$B$2)*(1-Parametri!$B$3)+((Coefficienti!$B$7+Coefficienti!$B$8*E$2+Coefficienti!$B$9*$A6)+Coefficienti!$B$10)*(1-Parametri!$B$4))*(1+Parametri!$B$5)+FerrGriglia!E5+Coefficienti!$B$11*Parametri!$B$6,2)*(1+Parametri!$B$7),2) | F6: =ROUND(ROUND((((Coefficienti!$B$1+Coefficienti!$B$2*F$2+Coefficienti!$B$3*$A6)*Parametri!$B$1+(Coefficienti!$B$4+Coefficienti!$B$5*F$2+Coefficienti!$B$6*$A6)*Parametri!$B$2)*(1-Parametri!$B$3)+((Coefficienti!$B$7+Coefficienti!$B$8*F$2+Coefficienti!$B$9*$A6)+Coefficienti!$B$10)*(1-Parametri!$B$4))*(1+Parametri!$B$5)+FerrGriglia!F5+Coefficienti!$B$11*Parametri!$B$6,2)*(1+Parametri!$B$7),2) | G6: =ROUND(ROUND((((Coefficienti!$B$1+Coefficienti!$B$2*G$2+Coefficienti!$B$3*$A6)*Parametri!$B$1+(Coefficienti!$B$4+Coefficienti!$B$5*G$2+Coefficienti!$B$6*$A6)*Parametri!$B$2)*(1-Parametri!$B$3)+((Coefficienti!$B$7+Coefficienti!$B$8*G$2+Coefficienti!$B$9*$A6)+Coefficienti!$B$10)*(1-Parametri!$B$4))*(1+Parametri!$B$5)+FerrGriglia!G5+Coefficienti!$B$11*Parametri!$B$6,2)*(1+Parametri!$B$7),2) | H6: =ROUND(ROUND((((Coefficienti!$B$1+Coefficienti!$B$2*H$2+Coefficienti!$B$3*$A6)*Parametri!$B$1+(Coefficienti!$B$4+Coefficienti!$B$5*H$2+Coefficienti!$B$6*$A6)*Parametri!$B$2)*(1-Parametri!$B$3)+((Coefficienti!$B$7+Coefficienti!$B$8*H$2+Coefficienti!$B$9*$A6)+Coefficienti!$B$10)*(1-Parametri!$B$4))*(1+Parametri!$B$5)+FerrGriglia!H5+Coefficienti!$B$11*Parametri!$B$6,2)*(1+Parametri!$B$7),2) | I6: =ROUND(ROUND((((Coefficienti!$B$1+Coefficienti!$B$2*I$2+Coefficienti!$B$3*$A6)*Parametri!$B$1+(Coefficienti!$B$4+Coefficienti!$B$5*I$2+Coefficienti!$B$6*$A6)*Parametri!$B$2)*(1-Parametri!$B$3)+((Coefficienti!$B$7+Coefficienti!$B$8*I$2+Coefficienti!$B$9*$A6)+Coefficienti!$B$10)*(1-Parametri!$B$4))*(1+Parametri!$B$5)+FerrGriglia!I5+Coefficienti!$B$11*Parametri!$B$6,2)*(1+Parametri!$B$7),2) | ... AA6: =ROUND(ROUND((((Coefficienti!$B$1+Coefficienti!$B$2*AA$2+Coefficienti!$B$3*$A6)*Parametri!$B$1+(Coefficienti!$B$4+Coefficienti!$B$5*AA$2+Coefficienti!$B$6*$A6)*Parametri!$B$2)*(1-Parametri!$B$3)+((Coefficienti!$B$7+Coefficienti!$B$8*AA$2+Coefficienti!$B$9*$A6)+Coefficienti!$B$10)*(1-Parametri!$B$4))*(1+Parametri!$B$5)+FerrGriglia!AA5+Coefficienti!$B$11*Parametri!$B$6,2)*(1+Parametri!$B$7),2)
A7: 1000 | B7: =ROUND(ROUND((((Coefficienti!$B$1+Coefficienti!$B$2*B$2+Coefficienti!$B$3*$A7)*Parametri!$B$1+(Coefficienti!$B$4+Coefficienti!$B$5*B$2+Coefficienti!$B$6*$A7)*Parametri!$B$2)*(1-Parametri!$B$3)+((Coefficienti!$B$7+Coefficienti!$B$8*B$2+Coefficienti!$B$9*$A7)+Coefficienti!$B$10)*(1-Parametri!$B$4))*(1+Parametri!$B$5)+FerrGriglia!B6+Coefficienti!$B$11*Parametri!$B$6,2)*(1+Parametri!$B$7),2) | C7: =ROUND(ROUND((((Coefficienti!$B$1+Coefficienti!$B$2*C$2+Coefficienti!$B$3*$A7)*Parametri!$B$1+(Coefficienti!$B$4+Coefficienti!$B$5*C$2+Coefficienti!$B$6*$A7)*Parametri!$B$2)*(1-Parametri!$B$3)+((Coefficienti!$B$7+Coefficienti!$B$8*C$2+Coefficienti!$B$9*$A7)+Coefficienti!$B$10)*(1-Parametri!$B$4))*(1+Parametri!$B$5)+FerrGriglia!C6+Coefficienti!$B$11*Parametri!$B$6,2)*(1+Parametri!$B$7),2) | D7: =ROUND(ROUND((((Coefficienti!$B$1+Coefficienti!$B$2*D$2+Coefficienti!$B$3*$A7)*Parametri!$B$1+(Coefficienti!$B$4+Coefficienti!$B$5*D$2+Coefficienti!$B$6*$A7)*Parametri!$B$2)*(1-Parametri!$B$3)+((Coefficienti!$B$7+Coefficienti!$B$8*D$2+Coefficienti!$B$9*$A7)+Coefficienti!$B$10)*(1-Parametri!$B$4))*(1+Parametri!$B$5)+FerrGriglia!D6+Coefficienti!$B$11*Parametri!$B$6,2)*(1+Parametri!$B$7),2) | E7: =ROUND(ROUND((((Coefficienti!$B$1+Coefficienti!$B$2*E$2+Coefficienti!$B$3*$A7)*Parametri!$B$1+(Coefficienti!$B$4+Coefficienti!$B$5*E$2+Coefficienti!$B$6*$A7)*Parametri!$B$2)*(1-Parametri!$B$3)+((Coefficienti!$B$7+Coefficienti!$B$8*E$2+Coefficienti!$B$9*$A7)+Coefficienti!$B$10)*(1-Parametri!$B$4))*(1+Parametri!$B$5)+FerrGriglia!E6+Coefficienti!$B$11*Parametri!$B$6,2)*(1+Parametri!$B$7),2) | F7: =ROUND(ROUND((((Coefficienti!$B$1+Coefficienti!$B$2*F$2+Coefficienti!$B$3*$A7)*Parametri!$B$1+(Coefficienti!$B$4+Coefficienti!$B$5*F$2+Coefficienti!$B$6*$A7)*Parametri!$B$2)*(1-Parametri!$B$3)+((Coefficienti!$B$7+Coefficienti!$B$8*F$2+Coefficienti!$B$9*$A7)+Coefficienti!$B$10)*(1-Parametri!$B$4))*(1+Parametri!$B$5)+FerrGriglia!F6+Coefficienti!$B$11*Parametri!$B$6,2)*(1+Parametri!$B$7),2) | G7: =ROUND(ROUND((((Coefficienti!$B$1+Coefficienti!$B$2*G$2+Coefficienti!$B$3*$A7)*Parametri!$B$1+(Coefficienti!$B$4+Coefficienti!$B$5*G$2+Coefficienti!$B$6*$A7)*Parametri!$B$2)*(1-Parametri!$B$3)+((Coefficienti!$B$7+Coefficienti!$B$8*G$2+Coefficienti!$B$9*$A7)+Coefficienti!$B$10)*(1-Parametri!$B$4))*(1+Parametri!$B$5)+FerrGriglia!G6+Coefficienti!$B$11*Parametri!$B$6,2)*(1+Parametri!$B$7),2) | H7: =ROUND(ROUND((((Coefficienti!$B$1+Coefficienti!$B$2*H$2+Coefficienti!$B$3*$A7)*Parametri!$B$1+(Coefficienti!$B$4+Coefficienti!$B$5*H$2+Coefficienti!$B$6*$A7)*Parametri!$B$2)*(1-Parametri!$B$3)+((Coefficienti!$B$7+Coefficienti!$B$8*H$2+Coefficienti!$B$9*$A7)+Coefficienti!$B$10)*(1-Parametri!$B$4))*(1+Parametri!$B$5)+FerrGriglia!H6+Coefficienti!$B$11*Parametri!$B$6,2)*(1+Parametri!$B$7),2) | I7: =ROUND(ROUND((((Coefficienti!$B$1+Coefficienti!$B$2*I$2+Coefficienti!$B$3*$A7)*Parametri!$B$1+(Coefficienti!$B$4+Coefficienti!$B$5*I$2+Coefficienti!$B$6*$A7)*Parametri!$B$2)*(1-Parametri!$B$3)+((Coefficienti!$B$7+Coefficienti!$B$8*I$2+Coefficienti!$B$9*$A7)+Coefficienti!$B$10)*(1-Parametri!$B$4))*(1+Parametri!$B$5)+FerrGriglia!I6+Coefficienti!$B$11*Parametri!$B$6,2)*(1+Parametri!$B$7),2) | ... AA7: =ROUND(ROUND((((Coefficienti!$B$1+Coefficienti!$B$2*AA$2+Coefficienti!$B$3*$A7)*Parametri!$B$1+(Coefficienti!$B$4+Coefficienti!$B$5*AA$2+Coefficienti!$B$6*$A7)*Parametri!$B$2)*(1-Parametri!$B$3)+((Coefficienti!$B$7+Coefficienti!$B$8*AA$2+Coefficienti!$B$9*$A7)+Coefficienti!$B$10)*(1-Parametri!$B$4))*(1+Parametri!$B$5)+FerrGriglia!AA6+Coefficienti!$B$11*Parametri!$B$6,2)*(1+Parametri!$B$7),2)
A8: 1100 | B8: =ROUND(ROUND((((Coefficienti!$B$1+Coefficienti!$B$2*B$2+Coefficienti!$B$3*$A8)*Parametri!$B$1+(Coefficienti!$B$4+Coefficienti!$B$5*B$2+Coefficienti!$B$6*$A8)*Parametri!$B$2)*(1-Parametri!$B$3)+((Coefficienti!$B$7+Coefficienti!$B$8*B$2+Coefficienti!$B$9*$A8)+Coefficienti!$B$10)*(1-Parametri!$B$4))*(1+Parametri!$B$5)+FerrGriglia!B7+Coefficienti!$B$11*Parametri!$B$6,2)*(1+Parametri!$B$7),2) | C8: =ROUND(ROUND((((Coefficienti!$B$1+Coefficienti!$B$2*C$2+Coefficienti!$B$3*$A8)*Parametri!$B$1+(Coefficienti!$B$4+Coefficienti!$B$5*C$2+Coefficienti!$B$6*$A8)*Parametri!$B$2)*(1-Parametri!$B$3)+((Coefficienti!$B$7+Coefficienti!$B$8*C$2+Coefficienti!$B$9*$A8)+Coefficienti!$B$10)*(1-Parametri!$B$4))*(1+Parametri!$B$5)+FerrGriglia!C7+Coefficienti!$B$11*Parametri!$B$6,2)*(1+Parametri!$B$7),2) | D8: =ROUND(ROUND((((Coefficienti!$B$1+Coefficienti!$B$2*D$2+Coefficienti!$B$3*$A8)*Parametri!$B$1+(Coefficienti!$B$4+Coefficienti!$B$5*D$2+Coefficienti!$B$6*$A8)*Parametri!$B$2)*(1-Parametri!$B$3)+((Coefficienti!$B$7+Coefficienti!$B$8*D$2+Coefficienti!$B$9*$A8)+Coefficienti!$B$10)*(1-Parametri!$B$4))*(1+Parametri!$B$5)+FerrGriglia!D7+Coefficienti!$B$11*Parametri!$B$6,2)*(1+Parametri!$B$7),2) | E8: =ROUND(ROUND((((Coefficienti!$B$1+Coefficienti!$B$2*E$2+Coefficienti!$B$3*$A8)*Parametri!$B$1+(Coefficienti!$B$4+Coefficienti!$B$5*E$2+Coefficienti!$B$6*$A8)*Parametri!$B$2)*(1-Parametri!$B$3)+((Coefficienti!$B$7+Coefficienti!$B$8*E$2+Coefficienti!$B$9*$A8)+Coefficienti!$B$10)*(1-Parametri!$B$4))*(1+Parametri!$B$5)+FerrGriglia!E7+Coefficienti!$B$11*Parametri!$B$6,2)*(1+Parametri!$B$7),2) | F8: =ROUND(ROUND((((Coefficienti!$B$1+Coefficienti!$B$2*F$2+Coefficienti!$B$3*$A8)*Parametri!$B$1+(Coefficienti!$B$4+Coefficienti!$B$5*F$2+Coefficienti!$B$6*$A8)*Parametri!$B$2)*(1-Parametri!$B$3)+((Coefficienti!$B$7+Coefficienti!$B$8*F$2+Coefficienti!$B$9*$A8)+Coefficienti!$B$10)*(1-Parametri!$B$4))*(1+Parametri!$B$5)+FerrGriglia!F7+Coefficienti!$B$11*Parametri!$B$6,2)*(1+Parametri!$B$7),2) | G8: =ROUND(ROUND((((Coefficienti!$B$1+Coefficienti!$B$2*G$2+Coefficienti!$B$3*$A8)*Parametri!$B$1+(Coefficienti!$B$4+Coefficienti!$B$5*G$2+Coefficienti!$B$6*$A8)*Parametri!$B$2)*(1-Parametri!$B$3)+((Coefficienti!$B$7+Coefficienti!$B$8*G$2+Coefficienti!$B$9*$A8)+Coefficienti!$B$10)*(1-Parametri!$B$4))*(1+Parametri!$B$5)+FerrGriglia!G7+Coefficienti!$B$11*Parametri!$B$6,2)*(1+Parametri!$B$7),2) | H8: =ROUND(ROUND((((Coefficienti!$B$1+Coefficienti!$B$2*H$2+Coefficienti!$B$3*$A8)*Parametri!$B$1+(Coefficienti!$B$4+Coefficienti!$B$5*H$2+Coefficienti!$B$6*$A8)*Parametri!$B$2)*(1-Parametri!$B$3)+((Coefficienti!$B$7+Coefficienti!$B$8*H$2+Coefficienti!$B$9*$A8)+Coefficienti!$B$10)*(1-Parametri!$B$4))*(1+Parametri!$B$5)+FerrGriglia!H7+Coefficienti!$B$11*Parametri!$B$6,2)*(1+Parametri!$B$7),2) | I8: =ROUND(ROUND((((Coefficienti!$B$1+Coefficienti!$B$2*I$2+Coefficienti!$B$3*$A8)*Parametri!$B$1+(Coefficienti!$B$4+Coefficienti!$B$5*I$2+Coefficienti!$B$6*$A8)*Parametri!$B$2)*(1-Parametri!$B$3)+((Coefficienti!$B$7+Coefficienti!$B$8*I$2+Coefficienti!$B$9*$A8)+Coefficienti!$B$10)*(1-Parametri!$B$4))*(1+Parametri!$B$5)+FerrGriglia!I7+Coefficienti!$B$11*Parametri!$B$6,2)*(1+Parametri!$B$7),2) | ... AA8: =ROUND(ROUND((((Coefficienti!$B$1+Coefficienti!$B$2*AA$2+Coefficienti!$B$3*$A8)*Parametri!$B$1+(Coefficienti!$B$4+Coefficienti!$B$5*AA$2+Coefficienti!$B$6*$A8)*Parametri!$B$2)*(1-Parametri!$B$3)+((Coefficienti!$B$7+Coefficienti!$B$8*AA$2+Coefficienti!$B$9*$A8)+Coefficienti!$B$10)*(1-Parametri!$B$4))*(1+Parametri!$B$5)+FerrGriglia!AA7+Coefficienti!$B$11*Parametri!$B$6,2)*(1+Parametri!$B$7),2)
A9: 1200 | B9: =ROUND(ROUND((((Coefficienti!$B$1+Coefficienti!$B$2*B$2+Coefficienti!$B$3*$A9)*Parametri!$B$1+(Coefficienti!$B$4+Coefficienti!$B$5*B$2+Coefficienti!$B$6*$A9)*Parametri!$B$2)*(1-Parametri!$B$3)+((Coefficienti!$B$7+Coefficienti!$B$8*B$2+Coefficienti!$B$9*$A9)+Coefficienti!$B$10)*(1-Parametri!$B$4))*(1+Parametri!$B$5)+FerrGriglia!B8+Coefficienti!$B$11*Parametri!$B$6,2)*(1+Parametri!$B$7),2) | C9: =ROUND(ROUND((((Coefficienti!$B$1+Coefficienti!$B$2*C$2+Coefficienti!$B$3*$A9)*Parametri!$B$1+(Coefficienti!$B$4+Coefficienti!$B$5*C$2+Coefficienti!$B$6*$A9)*Parametri!$B$2)*(1-Parametri!$B$3)+((Coefficienti!$B$7+Coefficienti!$B$8*C$2+Coefficienti!$B$9*$A9)+Coefficienti!$B$10)*(1-Parametri!$B$4))*(1+Parametri!$B$5)+FerrGriglia!C8+Coefficienti!$B$11*Parametri!$B$6,2)*(1+Parametri!$B$7),2) | D9: =ROUND(ROUND((((Coefficienti!$B$1+Coefficienti!$B$2*D$2+Coefficienti!$B$3*$A9)*Parametri!$B$1+(Coefficienti!$B$4+Coefficienti!$B$5*D$2+Coefficienti!$B$6*$A9)*Parametri!$B$2)*(1-Parametri!$B$3)+((Coefficienti!$B$7+Coefficienti!$B$8*D$2+Coefficienti!$B$9*$A9)+Coefficienti!$B$10)*(1-Parametri!$B$4))*(1+Parametri!$B$5)+FerrGriglia!D8+Coefficienti!$B$11*Parametri!$B$6,2)*(1+Parametri!$B$7),2) | E9: =ROUND(ROUND((((Coefficienti!$B$1+Coefficienti!$B$2*E$2+Coefficienti!$B$3*$A9)*Parametri!$B$1+(Coefficienti!$B$4+Coefficienti!$B$5*E$2+Coefficienti!$B$6*$A9)*Parametri!$B$2)*(1-Parametri!$B$3)+((Coefficienti!$B$7+Coefficienti!$B$8*E$2+Coefficienti!$B$9*$A9)+Coefficienti!$B$10)*(1-Parametri!$B$4))*(1+Parametri!$B$5)+FerrGriglia!E8+Coefficienti!$B$11*Parametri!$B$6,2)*(1+Parametri!$B$7),2) | F9: =ROUND(ROUND((((Coefficienti!$B$1+Coefficienti!$B$2*F$2+Coefficienti!$B$3*$A9)*Parametri!$B$1+(Coefficienti!$B$4+Coefficienti!$B$5*F$2+Coefficienti!$B$6*$A9)*Parametri!$B$2)*(1-Parametri!$B$3)+((Coefficienti!$B$7+Coefficienti!$B$8*F$2+Coefficienti!$B$9*$A9)+Coefficienti!$B$10)*(1-Parametri!$B$4))*(1+Parametri!$B$5)+FerrGriglia!F8+Coefficienti!$B$11*Parametri!$B$6,2)*(1+Parametri!$B$7),2) | G9: =ROUND(ROUND((((Coefficienti!$B$1+Coefficienti!$B$2*G$2+Coefficienti!$B$3*$A9)*Parametri!$B$1+(Coefficienti!$B$4+Coefficienti!$B$5*G$2+Coefficienti!$B$6*$A9)*Parametri!$B$2)*(1-Parametri!$B$3)+((Coefficienti!$B$7+Coefficienti!$B$8*G$2+Coefficienti!$B$9*$A9)+Coefficienti!$B$10)*(1-Parametri!$B$4))*(1+Parametri!$B$5)+FerrGriglia!G8+Coefficienti!$B$11*Parametri!$B$6,2)*(1+Parametri!$B$7),2) | H9: =ROUND(ROUND((((Coefficienti!$B$1+Coefficienti!$B$2*H$2+Coefficienti!$B$3*$A9)*Parametri!$B$1+(Coefficienti!$B$4+Coefficienti!$B$5*H$2+Coefficienti!$B$6*$A9)*Parametri!$B$2)*(1-Parametri!$B$3)+((Coefficienti!$B$7+Coefficienti!$B$8*H$2+Coefficienti!$B$9*$A9)+Coefficienti!$B$10)*(1-Parametri!$B$4))*(1+Parametri!$B$5)+FerrGriglia!H8+Coefficienti!$B$11*Parametri!$B$6,2)*(1+Parametri!$B$7),2) | I9: =ROUND(ROUND((((Coefficienti!$B$1+Coefficienti!$B$2*I$2+Coefficienti!$B$3*$A9)*Parametri!$B$1+(Coefficienti!$B$4+Coefficienti!$B$5*I$2+Coefficienti!$B$6*$A9)*Parametri!$B$2)*(1-Parametri!$B$3)+((Coefficienti!$B$7+Coefficienti!$B$8*I$2+Coefficienti!$B$9*$A9)+Coefficienti!$B$10)*(1-Parametri!$B$4))*(1+Parametri!$B$5)+FerrGriglia!I8+Coefficienti!$B$11*Parametri!$B$6,2)*(1+Parametri!$B$7),2) | ... AA9: =ROUND(ROUND((((Coefficienti!$B$1+Coefficienti!$B$2*AA$2+Coefficienti!$B$3*$A9)*Parametri!$B$1+(Coefficienti!$B$4+Coefficienti!$B$5*AA$2+Coefficienti!$B$6*$A9)*Parametri!$B$2)*(1-Parametri!$B$3)+((Coefficienti!$B$7+Coefficienti!$B$8*AA$2+Coefficienti!$B$9*$A9)+Coefficienti!$B$10)*(1-Parametri!$B$4))*(1+Parametri!$B$5)+FerrGriglia!AA8+Coefficienti!$B$11*Parametri!$B$6,2)*(1+Parametri!$B$7),2)
A10: 1300 | B10: =ROUND(ROUND((((Coefficienti!$B$1+Coefficienti!$B$2*B$2+Coefficienti!$B$3*$A10)*Parametri!$B$1+(Coefficienti!$B$4+Coefficienti!$B$5*B$2+Coefficienti!$B$6*$A10)*Parametri!$B$2)*(1-Parametri!$B$3)+((Coefficienti!$B$7+Coefficienti!$B$8*B$2+Coefficienti!$B$9*$A10)+Coefficienti!$B$10)*(1-Parametri!$B$4))*(1+Parametri!$B$5)+FerrGriglia!B9+Coefficienti!$B$11*Parametri!$B$6,2)*(1+Parametri!$B$7),2) | C10: =ROUND(ROUND((((Coefficienti!$B$1+Coefficienti!$B$2*C$2+Coefficienti!$B$3*$A10)*Parametri!$B$1+(Coefficienti!$B$4+Coefficienti!$B$5*C$2+Coefficienti!$B$6*$A10)*Parametri!$B$2)*(1-Parametri!$B$3)+((Coefficienti!$B$7+Coefficienti!$B$8*C$2+Coefficienti!$B$9*$A10)+Coefficienti!$B$10)*(1-Parametri!$B$4))*(1+Parametri!$B$5)+FerrGriglia!C9+Coefficienti!$B$11*Parametri!$B$6,2)*(1+Parametri!$B$7),2) | D10: =ROUND(ROUND((((Coefficienti!$B$1+Coefficienti!$B$2*D$2+Coefficienti!$B$3*$A10)*Parametri!$B$1+(Coefficienti!$B$4+Coefficienti!$B$5*D$2+Coefficienti!$B$6*$A10)*Parametri!$B$2)*(1-Parametri!$B$3)+((Coefficienti!$B$7+Coefficienti!$B$8*D$2+Coefficienti!$B$9*$A10)+Coefficienti!$B$10)*(1-Parametri!$B$4))*(1+Parametri!$B$5)+FerrGriglia!D9+Coefficienti!$B$11*Parametri!$B$6,2)*(1+Parametri!$B$7),2) | E10: =ROUND(ROUND((((Coefficienti!$B$1+Coefficienti!$B$2*E$2+Coefficienti!$B$3*$A10)*Parametri!$B$1+(Coefficienti!$B$4+Coefficienti!$B$5*E$2+Coefficienti!$B$6*$A10)*Parametri!$B$2)*(1-Parametri!$B$3)+((Coefficienti!$B$7+Coefficienti!$B$8*E$2+Coefficienti!$B$9*$A10)+Coefficienti!$B$10)*(1-Parametri!$B$4))*(1+Parametri!$B$5)+FerrGriglia!E9+Coefficienti!$B$11*Parametri!$B$6,2)*(1+Parametri!$B$7),2) | F10: =ROUND(ROUND((((Coefficienti!$B$1+Coefficienti!$B$2*F$2+Coefficienti!$B$3*$A10)*Parametri!$B$1+(Coefficienti!$B$4+Coefficienti!$B$5*F$2+Coefficienti!$B$6*$A10)*Parametri!$B$2)*(1-Parametri!$B$3)+((Coefficienti!$B$7+Coefficienti!$B$8*F$2+Coefficienti!$B$9*$A10)+Coefficienti!$B$10)*(1-Parametri!$B$4))*(1+Parametri!$B$5)+FerrGriglia!F9+Coefficienti!$B$11*Parametri!$B$6,2)*(1+Parametri!$B$7),2) | G10: =ROUND(ROUND((((Coefficienti!$B$1+Coefficienti!$B$2*G$2+Coefficienti!$B$3*$A10)*Parametri!$B$1+(Coefficienti!$B$4+Coefficienti!$B$5*G$2+Coefficienti!$B$6*$A10)*Parametri!$B$2)*(1-Parametri!$B$3)+((Coefficienti!$B$7+Coefficienti!$B$8*G$2+Coefficienti!$B$9*$A10)+Coefficienti!$B$10)*(1-Parametri!$B$4))*(1+Parametri!$B$5)+FerrGriglia!G9+Coefficienti!$B$11*Parametri!$B$6,2)*(1+Parametri!$B$7),2) | H10: =ROUND(ROUND((((Coefficienti!$B$1+Coefficienti!$B$2*H$2+Coefficienti!$B$3*$A10)*Parametri!$B$1+(Coefficienti!$B$4+Coefficienti!$B$5*H$2+Coefficienti!$B$6*$A10)*Parametri!$B$2)*(1-Parametri!$B$3)+((Coefficienti!$B$7+Coefficienti!$B$8*H$2+Coefficienti!$B$9*$A10)+Coefficienti!$B$10)*(1-Parametri!$B$4))*(1+Parametri!$B$5)+FerrGriglia!H9+Coefficienti!$B$11*Parametri!$B$6,2)*(1+Parametri!$B$7),2) | I10: =ROUND(ROUND((((Coefficienti!$B$1+Coefficienti!$B$2*I$2+Coefficienti!$B$3*$A10)*Parametri!$B$1+(Coefficienti!$B$4+Coefficienti!$B$5*I$2+Coefficienti!$B$6*$A10)*Parametri!$B$2)*(1-Parametri!$B$3)+((Coefficienti!$B$7+Coefficienti!$B$8*I$2+Coefficienti!$B$9*$A10)+Coefficienti!$B$10)*(1-Parametri!$B$4))*(1+Parametri!$B$5)+FerrGriglia!I9+Coefficienti!$B$11*Parametri!$B$6,2)*(1+Parametri!$B$7),2) | ... AA10: =ROUND(ROUND((((Coefficienti!$B$1+Coefficienti!$B$2*AA$2+Coefficienti!$B$3*$A10)*Parametri!$B$1+(Coefficienti!$B$4+Coefficienti!$B$5*AA$2+Coefficienti!$B$6*$A10)*Parametri!$B$2)*(1-Parametri!$B$3)+((Coefficienti!$B$7+Coefficienti!$B$8*AA$2+Coefficienti!$B$9*$A10)+Coefficienti!$B$10)*(1-Parametri!$B$4))*(1+Parametri!$B$5)+FerrGriglia!AA9+Coefficienti!$B$11*Parametri!$B$6,2)*(1+Parametri!$B$7),2)
A11: 1400 | B11: =ROUND(ROUND((((Coefficienti!$B$1+Coefficienti!$B$2*B$2+Coefficienti!$B$3*$A11)*Parametri!$B$1+(Coefficienti!$B$4+Coefficienti!$B$5*B$2+Coefficienti!$B$6*$A11)*Parametri!$B$2)*(1-Parametri!$B$3)+((Coefficienti!$B$7+Coefficienti!$B$8*B$2+Coefficienti!$B$9*$A11)+Coefficienti!$B$10)*(1-Parametri!$B$4))*(1+Parametri!$B$5)+FerrGriglia!B10+Coefficienti!$B$11*Parametri!$B$6,2)*(1+Parametri!$B$7),2) | C11: =ROUND(ROUND((((Coefficienti!$B$1+Coefficienti!$B$2*C$2+Coefficienti!$B$3*$A11)*Parametri!$B$1+(Coefficienti!$B$4+Coefficienti!$B$5*C$2+Coefficienti!$B$6*$A11)*Parametri!$B$2)*(1-Parametri!$B$3)+((Coefficienti!$B$7+Coefficienti!$B$8*C$2+Coefficienti!$B$9*$A11)+Coefficienti!$B$10)*(1-Parametri!$B$4))*(1+Parametri!$B$5)+FerrGriglia!C10+Coefficienti!$B$11*Parametri!$B$6,2)*(1+Parametri!$B$7),2) | D11: =ROUND(ROUND((((Coefficienti!$B$1+Coefficienti!$B$2*D$2+Coefficienti!$B$3*$A11)*Parametri!$B$1+(Coefficienti!$B$4+Coefficienti!$B$5*D$2+Coefficienti!$B$6*$A11)*Parametri!$B$2)*(1-Parametri!$B$3)+((Coefficienti!$B$7+Coefficienti!$B$8*D$2+Coefficienti!$B$9*$A11)+Coefficienti!$B$10)*(1-Parametri!$B$4))*(1+Parametri!$B$5)+FerrGriglia!D10+Coefficienti!$B$11*Parametri!$B$6,2)*(1+Parametri!$B$7),2) | E11: =ROUND(ROUND((((Coefficienti!$B$1+Coefficienti!$B$2*E$2+Coefficienti!$B$3*$A11)*Parametri!$B$1+(Coefficienti!$B$4+Coefficienti!$B$5*E$2+Coefficienti!$B$6*$A11)*Parametri!$B$2)*(1-Parametri!$B$3)+((Coefficienti!$B$7+Coefficienti!$B$8*E$2+Coefficienti!$B$9*$A11)+Coefficienti!$B$10)*(1-Parametri!$B$4))*(1+Parametri!$B$5)+FerrGriglia!E10+Coefficienti!$B$11*Parametri!$B$6,2)*(1+Parametri!$B$7),2) | F11: =ROUND(ROUND((((Coefficienti!$B$1+Coefficienti!$B$2*F$2+Coefficienti!$B$3*$A11)*Parametri!$B$1+(Coefficienti!$B$4+Coefficienti!$B$5*F$2+Coefficienti!$B$6*$A11)*Parametri!$B$2)*(1-Parametri!$B$3)+((Coefficienti!$B$7+Coefficienti!$B$8*F$2+Coefficienti!$B$9*$A11)+Coefficienti!$B$10)*(1-Parametri!$B$4))*(1+Parametri!$B$5)+FerrGriglia!F10+Coefficienti!$B$11*Parametri!$B$6,2)*(1+Parametri!$B$7),2) | G11: =ROUND(ROUND((((Coefficienti!$B$1+Coefficienti!$B$2*G$2+Coefficienti!$B$3*$A11)*Parametri!$B$1+(Coefficienti!$B$4+Coefficienti!$B$5*G$2+Coefficienti!$B$6*$A11)*Parametri!$B$2)*(1-Parametri!$B$3)+((Coefficienti!$B$7+Coefficienti!$B$8*G$2+Coefficienti!$B$9*$A11)+Coefficienti!$B$10)*(1-Parametri!$B$4))*(1+Parametri!$B$5)+FerrGriglia!G10+Coefficienti!$B$11*Parametri!$B$6,2)*(1+Parametri!$B$7),2) | H11: =ROUND(ROUND((((Coefficienti!$B$1+Coefficienti!$B$2*H$2+Coefficienti!$B$3*$A11)*Parametri!$B$1+(Coefficienti!$B$4+Coefficienti!$B$5*H$2+Coefficienti!$B$6*$A11)*Parametri!$B$2)*(1-Parametri!$B$3)+((Coefficienti!$B$7+Coefficienti!$B$8*H$2+Coefficienti!$B$9*$A11)+Coefficienti!$B$10)*(1-Parametri!$B$4))*(1+Parametri!$B$5)+FerrGriglia!H10+Coefficienti!$B$11*Parametri!$B$6,2)*(1+Parametri!$B$7),2) | I11: =ROUND(ROUND((((Coefficienti!$B$1+Coefficienti!$B$2*I$2+Coefficienti!$B$3*$A11)*Parametri!$B$1+(Coefficienti!$B$4+Coefficienti!$B$5*I$2+Coefficienti!$B$6*$A11)*Parametri!$B$2)*(1-Parametri!$B$3)+((Coefficienti!$B$7+Coefficienti!$B$8*I$2+Coefficienti!$B$9*$A11)+Coefficienti!$B$10)*(1-Parametri!$B$4))*(1+Parametri!$B$5)+FerrGriglia!I10+Coefficienti!$B$11*Parametri!$B$6,2)*(1+Parametri!$B$7),2) | ... AA11: =ROUND(ROUND((((Coefficienti!$B$1+Coefficienti!$B$2*AA$2+Coefficienti!$B$3*$A11)*Parametri!$B$1+(Coefficienti!$B$4+Coefficienti!$B$5*AA$2+Coefficienti!$B$6*$A11)*Parametri!$B$2)*(1-Parametri!$B$3)+((Coefficienti!$B$7+Coefficienti!$B$8*AA$2+Coefficienti!$B$9*$A11)+Coefficienti!$B$10)*(1-Parametri!$B$4))*(1+Parametri!$B$5)+FerrGriglia!AA10+Coefficienti!$B$11*Parametri!$B$6,2)*(1+Parametri!$B$7),2)
A12: 1500 | B12: =ROUND(ROUND((((Coefficienti!$B$1+Coefficienti!$B$2*B$2+Coefficienti!$B$3*$A12)*Parametri!$B$1+(Coefficienti!$B$4+Coefficienti!$B$5*B$2+Coefficienti!$B$6*$A12)*Parametri!$B$2)*(1-Parametri!$B$3)+((Coefficienti!$B$7+Coefficienti!$B$8*B$2+Coefficienti!$B$9*$A12)+Coefficienti!$B$10)*(1-Parametri!$B$4))*(1+Parametri!$B$5)+FerrGriglia!B11+Coefficienti!$B$11*Parametri!$B$6,2)*(1+Parametri!$B$7),2) | C12: =ROUND(ROUND((((Coefficienti!$B$1+Coefficienti!$B$2*C$2+Coefficienti!$B$3*$A12)*Parametri!$B$1+(Coefficienti!$B$4+Coefficienti!$B$5*C$2+Coefficienti!$B$6*$A12)*Parametri!$B$2)*(1-Parametri!$B$3)+((Coefficienti!$B$7+Coefficienti!$B$8*C$2+Coefficienti!$B$9*$A12)+Coefficienti!$B$10)*(1-Parametri!$B$4))*(1+Parametri!$B$5)+FerrGriglia!C11+Coefficienti!$B$11*Parametri!$B$6,2)*(1+Parametri!$B$7),2) | D12: =ROUND(ROUND((((Coefficienti!$B$1+Coefficienti!$B$2*D$2+Coefficienti!$B$3*$A12)*Parametri!$B$1+(Coefficienti!$B$4+Coefficienti!$B$5*D$2+Coefficienti!$B$6*$A12)*Parametri!$B$2)*(1-Parametri!$B$3)+((Coefficienti!$B$7+Coefficienti!$B$8*D$2+Coefficienti!$B$9*$A12)+Coefficienti!$B$10)*(1-Parametri!$B$4))*(1+Parametri!$B$5)+FerrGriglia!D11+Coefficienti!$B$11*Parametri!$B$6,2)*(1+Parametri!$B$7),2) | E12: =ROUND(ROUND((((Coefficienti!$B$1+Coefficienti!$B$2*E$2+Coefficienti!$B$3*$A12)*Parametri!$B$1+(Coefficienti!$B$4+Coefficienti!$B$5*E$2+Coefficienti!$B$6*$A12)*Parametri!$B$2)*(1-Parametri!$B$3)+((Coefficienti!$B$7+Coefficienti!$B$8*E$2+Coefficienti!$B$9*$A12)+Coefficienti!$B$10)*(1-Parametri!$B$4))*(1+Parametri!$B$5)+FerrGriglia!E11+Coefficienti!$B$11*Parametri!$B$6,2)*(1+Parametri!$B$7),2) | F12: =ROUND(ROUND((((Coefficienti!$B$1+Coefficienti!$B$2*F$2+Coefficienti!$B$3*$A12)*Parametri!$B$1+(Coefficienti!$B$4+Coefficienti!$B$5*F$2+Coefficienti!$B$6*$A12)*Parametri!$B$2)*(1-Parametri!$B$3)+((Coefficienti!$B$7+Coefficienti!$B$8*F$2+Coefficienti!$B$9*$A12)+Coefficienti!$B$10)*(1-Parametri!$B$4))*(1+Parametri!$B$5)+FerrGriglia!F11+Coefficienti!$B$11*Parametri!$B$6,2)*(1+Parametri!$B$7),2) | G12: =ROUND(ROUND((((Coefficienti!$B$1+Coefficienti!$B$2*G$2+Coefficienti!$B$3*$A12)*Parametri!$B$1+(Coefficienti!$B$4+Coefficienti!$B$5*G$2+Coefficienti!$B$6*$A12)*Parametri!$B$2)*(1-Parametri!$B$3)+((Coefficienti!$B$7+Coefficienti!$B$8*G$2+Coefficienti!$B$9*$A12)+Coefficienti!$B$10)*(1-Parametri!$B$4))*(1+Parametri!$B$5)+FerrGriglia!G11+Coefficienti!$B$11*Parametri!$B$6,2)*(1+Parametri!$B$7),2) | H12: =ROUND(ROUND((((Coefficienti!$B$1+Coefficienti!$B$2*H$2+Coefficienti!$B$3*$A12)*Parametri!$B$1+(Coefficienti!$B$4+Coefficienti!$B$5*H$2+Coefficienti!$B$6*$A12)*Parametri!$B$2)*(1-Parametri!$B$3)+((Coefficienti!$B$7+Coefficienti!$B$8*H$2+Coefficienti!$B$9*$A12)+Coefficienti!$B$10)*(1-Parametri!$B$4))*(1+Parametri!$B$5)+FerrGriglia!H11+Coefficienti!$B$11*Parametri!$B$6,2)*(1+Parametri!$B$7),2) | I12: =ROUND(ROUND((((Coefficienti!$B$1+Coefficienti!$B$2*I$2+Coefficienti!$B$3*$A12)*Parametri!$B$1+(Coefficienti!$B$4+Coefficienti!$B$5*I$2+Coefficienti!$B$6*$A12)*Parametri!$B$2)*(1-Parametri!$B$3)+((Coefficienti!$B$7+Coefficienti!$B$8*I$2+Coefficienti!$B$9*$A12)+Coefficienti!$B$10)*(1-Parametri!$B$4))*(1+Parametri!$B$5)+FerrGriglia!I11+Coefficienti!$B$11*Parametri!$B$6,2)*(1+Parametri!$B$7),2) | ... AA12: =ROUND(ROUND((((Coefficienti!$B$1+Coefficienti!$B$2*AA$2+Coefficienti!$B$3*$A12)*Parametri!$B$1+(Coefficienti!$B$4+Coefficienti!$B$5*AA$2+Coefficienti!$B$6*$A12)*Parametri!$B$2)*(1-Parametri!$B$3)+((Coefficienti!$B$7+Coefficienti!$B$8*AA$2+Coefficienti!$B$9*$A12)+Coefficienti!$B$10)*(1-Parametri!$B$4))*(1+Parametri!$B$5)+FerrGriglia!AA11+Coefficienti!$B$11*Parametri!$B$6,2)*(1+Parametri!$B$7),2)
A13: 1600 | B13: =ROUND(ROUND((((Coefficienti!$B$1+Coefficienti!$B$2*B$2+Coefficienti!$B$3*$A13)*Parametri!$B$1+(Coefficienti!$B$4+Coefficienti!$B$5*B$2+Coefficienti!$B$6*$A13)*Parametri!$B$2)*(1-Parametri!$B$3)+((Coefficienti!$B$7+Coefficienti!$B$8*B$2+Coefficienti!$B$9*$A13)+Coefficienti!$B$10)*(1-Parametri!$B$4))*(1+Parametri!$B$5)+FerrGriglia!B12+Coefficienti!$B$11*Parametri!$B$6,2)*(1+Parametri!$B$7),2) | C13: =ROUND(ROUND((((Coefficienti!$B$1+Coefficienti!$B$2*C$2+Coefficienti!$B$3*$A13)*Parametri!$B$1+(Coefficienti!$B$4+Coefficienti!$B$5*C$2+Coefficienti!$B$6*$A13)*Parametri!$B$2)*(1-Parametri!$B$3)+((Coefficienti!$B$7+Coefficienti!$B$8*C$2+Coefficienti!$B$9*$A13)+Coefficienti!$B$10)*(1-Parametri!$B$4))*(1+Parametri!$B$5)+FerrGriglia!C12+Coefficienti!$B$11*Parametri!$B$6,2)*(1+Parametri!$B$7),2) | D13: =ROUND(ROUND((((Coefficienti!$B$1+Coefficienti!$B$2*D$2+Coefficienti!$B$3*$A13)*Parametri!$B$1+(Coefficienti!$B$4+Coefficienti!$B$5*D$2+Coefficienti!$B$6*$A13)*Parametri!$B$2)*(1-Parametri!$B$3)+((Coefficienti!$B$7+Coefficienti!$B$8*D$2+Coefficienti!$B$9*$A13)+Coefficienti!$B$10)*(1-Parametri!$B$4))*(1+Parametri!$B$5)+FerrGriglia!D12+Coefficienti!$B$11*Parametri!$B$6,2)*(1+Parametri!$B$7),2) | E13: =ROUND(ROUND((((Coefficienti!$B$1+Coefficienti!$B$2*E$2+Coefficienti!$B$3*$A13)*Parametri!$B$1+(Coefficienti!$B$4+Coefficienti!$B$5*E$2+Coefficienti!$B$6*$A13)*Parametri!$B$2)*(1-Parametri!$B$3)+((Coefficienti!$B$7+Coefficienti!$B$8*E$2+Coefficienti!$B$9*$A13)+Coefficienti!$B$10)*(1-Parametri!$B$4))*(1+Parametri!$B$5)+FerrGriglia!E12+Coefficienti!$B$11*Parametri!$B$6,2)*(1+Parametri!$B$7),2) | F13: =ROUND(ROUND((((Coefficienti!$B$1+Coefficienti!$B$2*F$2+Coefficienti!$B$3*$A13)*Parametri!$B$1+(Coefficienti!$B$4+Coefficienti!$B$5*F$2+Coefficienti!$B$6*$A13)*Parametri!$B$2)*(1-Parametri!$B$3)+((Coefficienti!$B$7+Coefficienti!$B$8*F$2+Coefficienti!$B$9*$A13)+Coefficienti!$B$10)*(1-Parametri!$B$4))*(1+Parametri!$B$5)+FerrGriglia!F12+Coefficienti!$B$11*Parametri!$B$6,2)*(1+Parametri!$B$7),2) | G13: =ROUND(ROUND((((Coefficienti!$B$1+Coefficienti!$B$2*G$2+Coefficienti!$B$3*$A13)*Parametri!$B$1+(Coefficienti!$B$4+Coefficienti!$B$5*G$2+Coefficienti!$B$6*$A13)*Parametri!$B$2)*(1-Parametri!$B$3)+((Coefficienti!$B$7+Coefficienti!$B$8*G$2+Coefficienti!$B$9*$A13)+Coefficienti!$B$10)*(1-Parametri!$B$4))*(1+Parametri!$B$5)+FerrGriglia!G12+Coefficienti!$B$11*Parametri!$B$6,2)*(1+Parametri!$B$7),2) | H13: =ROUND(ROUND((((Coefficienti!$B$1+Coefficienti!$B$2*H$2+Coefficienti!$B$3*$A13)*Parametri!$B$1+(Coefficienti!$B$4+Coefficienti!$B$5*H$2+Coefficienti!$B$6*$A13)*Parametri!$B$2)*(1-Parametri!$B$3)+((Coefficienti!$B$7+Coefficienti!$B$8*H$2+Coefficienti!$B$9*$A13)+Coefficienti!$B$10)*(1-Parametri!$B$4))*(1+Parametri!$B$5)+FerrGriglia!H12+Coefficienti!$B$11*Parametri!$B$6,2)*(1+Parametri!$B$7),2) | I13: =ROUND(ROUND((((Coefficienti!$B$1+Coefficienti!$B$2*I$2+Coefficienti!$B$3*$A13)*Parametri!$B$1+(Coefficienti!$B$4+Coefficienti!$B$5*I$2+Coefficienti!$B$6*$A13)*Parametri!$B$2)*(1-Parametri!$B$3)+((Coefficienti!$B$7+Coefficienti!$B$8*I$2+Coefficienti!$B$9*$A13)+Coefficienti!$B$10)*(1-Parametri!$B$4))*(1+Parametri!$B$5)+FerrGriglia!I12+Coefficienti!$B$11*Parametri!$B$6,2)*(1+Parametri!$B$7),2) | ... AA13: =ROUND(ROUND((((Coefficienti!$B$1+Coefficienti!$B$2*AA$2+Coefficienti!$B$3*$A13)*Parametri!$B$1+(Coefficienti!$B$4+Coefficienti!$B$5*AA$2+Coefficienti!$B$6*$A13)*Parametri!$B$2)*(1-Parametri!$B$3)+((Coefficienti!$B$7+Coefficienti!$B$8*AA$2+Coefficienti!$B$9*$A13)+Coefficienti!$B$10)*(1-Parametri!$B$4))*(1+Parametri!$B$5)+FerrGriglia!AA12+Coefficienti!$B$11*Parametri!$B$6,2)*(1+Parametri!$B$7),2)
A14: 1700 | B14: =ROUND(ROUND((((Coefficienti!$B$1+Coefficienti!$B$2*B$2+Coefficienti!$B$3*$A14)*Parametri!$B$1+(Coefficienti!$B$4+Coefficienti!$B$5*B$2+Coefficienti!$B$6*$A14)*Parametri!$B$2)*(1-Parametri!$B$3)+((Coefficienti!$B$7+Coefficienti!$B$8*B$2+Coefficienti!$B$9*$A14)+Coefficienti!$B$10)*(1-Parametri!$B$4))*(1+Parametri!$B$5)+FerrGriglia!B13+Coefficienti!$B$11*Parametri!$B$6,2)*(1+Parametri!$B$7),2) | C14: =ROUND(ROUND((((Coefficienti!$B$1+Coefficienti!$B$2*C$2+Coefficienti!$B$3*$A14)*Parametri!$B$1+(Coefficienti!$B$4+Coefficienti!$B$5*C$2+Coefficienti!$B$6*$A14)*Parametri!$B$2)*(1-Parametri!$B$3)+((Coefficienti!$B$7+Coefficienti!$B$8*C$2+Coefficienti!$B$9*$A14)+Coefficienti!$B$10)*(1-Parametri!$B$4))*(1+Parametri!$B$5)+FerrGriglia!C13+Coefficienti!$B$11*Parametri!$B$6,2)*(1+Parametri!$B$7),2) | D14: =ROUND(ROUND((((Coefficienti!$B$1+Coefficienti!$B$2*D$2+Coefficienti!$B$3*$A14)*Parametri!$B$1+(Coefficienti!$B$4+Coefficienti!$B$5*D$2+Coefficienti!$B$6*$A14)*Parametri!$B$2)*(1-Parametri!$B$3)+((Coefficienti!$B$7+Coefficienti!$B$8*D$2+Coefficienti!$B$9*$A14)+Coefficienti!$B$10)*(1-Parametri!$B$4))*(1+Parametri!$B$5)+FerrGriglia!D13+Coefficienti!$B$11*Parametri!$B$6,2)*(1+Parametri!$B$7),2) | E14: =ROUND(ROUND((((Coefficienti!$B$1+Coefficienti!$B$2*E$2+Coefficienti!$B$3*$A14)*Parametri!$B$1+(Coefficienti!$B$4+Coefficienti!$B$5*E$2+Coefficienti!$B$6*$A14)*Parametri!$B$2)*(1-Parametri!$B$3)+((Coefficienti!$B$7+Coefficienti!$B$8*E$2+Coefficienti!$B$9*$A14)+Coefficienti!$B$10)*(1-Parametri!$B$4))*(1+Parametri!$B$5)+FerrGriglia!E13+Coefficienti!$B$11*Parametri!$B$6,2)*(1+Parametri!$B$7),2) | F14: =ROUND(ROUND((((Coefficienti!$B$1+Coefficienti!$B$2*F$2+Coefficienti!$B$3*$A14)*Parametri!$B$1+(Coefficienti!$B$4+Coefficienti!$B$5*F$2+Coefficienti!$B$6*$A14)*Parametri!$B$2)*(1-Parametri!$B$3)+((Coefficienti!$B$7+Coefficienti!$B$8*F$2+Coefficienti!$B$9*$A14)+Coefficienti!$B$10)*(1-Parametri!$B$4))*(1+Parametri!$B$5)+FerrGriglia!F13+Coefficienti!$B$11*Parametri!$B$6,2)*(1+Parametri!$B$7),2) | G14: =ROUND(ROUND((((Coefficienti!$B$1+Coefficienti!$B$2*G$2+Coefficienti!$B$3*$A14)*Parametri!$B$1+(Coefficienti!$B$4+Coefficienti!$B$5*G$2+Coefficienti!$B$6*$A14)*Parametri!$B$2)*(1-Parametri!$B$3)+((Coefficienti!$B$7+Coefficienti!$B$8*G$2+Coefficienti!$B$9*$A14)+Coefficienti!$B$10)*(1-Parametri!$B$4))*(1+Parametri!$B$5)+FerrGriglia!G13+Coefficienti!$B$11*Parametri!$B$6,2)*(1+Parametri!$B$7),2) | H14: =ROUND(ROUND((((Coefficienti!$B$1+Coefficienti!$B$2*H$2+Coefficienti!$B$3*$A14)*Parametri!$B$1+(Coefficienti!$B$4+Coefficienti!$B$5*H$2+Coefficienti!$B$6*$A14)*Parametri!$B$2)*(1-Parametri!$B$3)+((Coefficienti!$B$7+Coefficienti!$B$8*H$2+Coefficienti!$B$9*$A14)+Coefficienti!$B$10)*(1-Parametri!$B$4))*(1+Parametri!$B$5)+FerrGriglia!H13+Coefficienti!$B$11*Parametri!$B$6,2)*(1+Parametri!$B$7),2) | I14: =ROUND(ROUND((((Coefficienti!$B$1+Coefficienti!$B$2*I$2+Coefficienti!$B$3*$A14)*Parametri!$B$1+(Coefficienti!$B$4+Coefficienti!$B$5*I$2+Coefficienti!$B$6*$A14)*Parametri!$B$2)*(1-Parametri!$B$3)+((Coefficienti!$B$7+Coefficienti!$B$8*I$2+Coefficienti!$B$9*$A14)+Coefficienti!$B$10)*(1-Parametri!$B$4))*(1+Parametri!$B$5)+FerrGriglia!I13+Coefficienti!$B$11*Parametri!$B$6,2)*(1+Parametri!$B$7),2) | ... AA14: =ROUND(ROUND((((Coefficienti!$B$1+Coefficienti!$B$2*AA$2+Coefficienti!$B$3*$A14)*Parametri!$B$1+(Coefficienti!$B$4+Coefficienti!$B$5*AA$2+Coefficienti!$B$6*$A14)*Parametri!$B$2)*(1-Parametri!$B$3)+((Coefficienti!$B$7+Coefficienti!$B$8*AA$2+Coefficienti!$B$9*$A14)+Coefficienti!$B$10)*(1-Parametri!$B$4))*(1+Parametri!$B$5)+FerrGriglia!AA13+Coefficienti!$B$11*Parametri!$B$6,2)*(1+Parametri!$B$7),2)
... A24: 2700 | B24: =ROUND(ROUND((((Coefficienti!$B$1+Coefficienti!$B$2*B$2+Coefficienti!$B$3*$A24)*Parametri!$B$1+(Coefficienti!$B$4+Coefficienti!$B$5*B$2+Coefficienti!$B$6*$A24)*Parametri!$B$2)*(1-Parametri!$B$3)+((Coefficienti!$B$7+Coefficienti!$B$8*B$2+Coefficienti!$B$9*$A24)+Coefficienti!$B$10)*(1-Parametri!$B$4))*(1+Parametri!$B$5)+FerrGriglia!B23+Coefficienti!$B$11*Parametri!$B$6,2)*(1+Parametri!$B$7),2) | C24: =ROUND(ROUND((((Coefficienti!$B$1+Coefficienti!$B$2*C$2+Coefficienti!$B$3*$A24)*Parametri!$B$1+(Coefficienti!$B$4+Coefficienti!$B$5*C$2+Coefficienti!$B$6*$A24)*Parametri!$B$2)*(1-Parametri!$B$3)+((Coefficienti!$B$7+Coefficienti!$B$8*C$2+Coefficienti!$B$9*$A24)+Coefficienti!$B$10)*(1-Parametri!$B$4))*(1+Parametri!$B$5)+FerrGriglia!C23+Coefficienti!$B$11*Parametri!$B$6,2)*(1+Parametri!$B$7),2) | D24: =ROUND(ROUND((((Coefficienti!$B$1+Coefficienti!$B$2*D$2+Coefficienti!$B$3*$A24)*Parametri!$B$1+(Coefficienti!$B$4+Coefficienti!$B$5*D$2+Coefficienti!$B$6*$A24)*Parametri!$B$2)*(1-Parametri!$B$3)+((Coefficienti!$B$7+Coefficienti!$B$8*D$2+Coefficienti!$B$9*$A24)+Coefficienti!$B$10)*(1-Parametri!$B$4))*(1+Parametri!$B$5)+FerrGriglia!D23+Coefficienti!$B$11*Parametri!$B$6,2)*(1+Parametri!$B$7),2) | E24: =ROUND(ROUND((((Coefficienti!$B$1+Coefficienti!$B$2*E$2+Coefficienti!$B$3*$A24)*Parametri!$B$1+(Coefficienti!$B$4+Coefficienti!$B$5*E$2+Coefficienti!$B$6*$A24)*Parametri!$B$2)*(1-Parametri!$B$3)+((Coefficienti!$B$7+Coefficienti!$B$8*E$2+Coefficienti!$B$9*$A24)+Coefficienti!$B$10)*(1-Parametri!$B$4))*(1+Parametri!$B$5)+FerrGriglia!E23+Coefficienti!$B$11*Parametri!$B$6,2)*(1+Parametri!$B$7),2) | F24: =ROUND(ROUND((((Coefficienti!$B$1+Coefficienti!$B$2*F$2+Coefficienti!$B$3*$A24)*Parametri!$B$1+(Coefficienti!$B$4+Coefficienti!$B$5*F$2+Coefficienti!$B$6*$A24)*Parametri!$B$2)*(1-Parametri!$B$3)+((Coefficienti!$B$7+Coefficienti!$B$8*F$2+Coefficienti!$B$9*$A24)+Coefficienti!$B$10)*(1-Parametri!$B$4))*(1+Parametri!$B$5)+FerrGriglia!F23+Coefficienti!$B$11*Parametri!$B$6,2)*(1+Parametri!$B$7),2) | G24: =ROUND(ROUND((((Coefficienti!$B$1+Coefficienti!$B$2*G$2+Coefficienti!$B$3*$A24)*Parametri!$B$1+(Coefficienti!$B$4+Coefficienti!$B$5*G$2+Coefficienti!$B$6*$A24)*Parametri!$B$2)*(1-Parametri!$B$3)+((Coefficienti!$B$7+Coefficienti!$B$8*G$2+Coefficienti!$B$9*$A24)+Coefficienti!$B$10)*(1-Parametri!$B$4))*(1+Parametri!$B$5)+FerrGriglia!G23+Coefficienti!$B$11*Parametri!$B$6,2)*(1+Parametri!$B$7),2) | H24: =ROUND(ROUND((((Coefficienti!$B$1+Coefficienti!$B$2*H$2+Coefficienti!$B$3*$A24)*Parametri!$B$1+(Coefficienti!$B$4+Coefficienti!$B$5*H$2+Coefficienti!$B$6*$A24)*Parametri!$B$2)*(1-Parametri!$B$3)+((Coefficienti!$B$7+Coefficienti!$B$8*H$2+Coefficienti!$B$9*$A24)+Coefficienti!$B$10)*(1-Parametri!$B$4))*(1+Parametri!$B$5)+FerrGriglia!H23+Coefficienti!$B$11*Parametri!$B$6,2)*(1+Parametri!$B$7),2) | I24: =ROUND(ROUND((((Coefficienti!$B$1+Coefficienti!$B$2*I$2+Coefficienti!$B$3*$A24)*Parametri!$B$1+(Coefficienti!$B$4+Coefficienti!$B$5*I$2+Coefficienti!$B$6*$A24)*Parametri!$B$2)*(1-Parametri!$B$3)+((Coefficienti!$B$7+Coefficienti!$B$8*I$2+Coefficienti!$B$9*$A24)+Coefficienti!$B$10)*(1-Parametri!$B$4))*(1+Parametri!$B$5)+FerrGriglia!I23+Coefficienti!$B$11*Parametri!$B$6,2)*(1+Parametri!$B$7),2) | ... AA24: =ROUND(ROUND((((Coefficienti!$B$1+Coefficienti!$B$2*AA$2+Coefficienti!$B$3*$A24)*Parametri!$B$1+(Coefficienti!$B$4+Coefficienti!$B$5*AA$2+Coefficienti!$B$6*$A24)*Parametri!$B$2)*(1-Parametri!$B$3)+((Coefficienti!$B$7+Coefficienti!$B$8*AA$2+Coefficienti!$B$9*$A24)+Coefficienti!$B$10)*(1-Parametri!$B$4))*(1+Parametri!$B$5)+FerrGriglia!AA23+Coefficienti!$B$11*Parametri!$B$6,2)*(1+Parametri!$B$7),2)
A27: COSTO SERRAMENTO (materiale scontato + sfrido + manodopera)
A28: H/L | B28: 500 | C28: 600 | D28: 700 | E28: 800 | F28: 900 | G28: 1000 | H28: 1100 | I28: 1200 | J28: 1300 | K28: 1400 | L28: 1500 | M28: 1600 | N28: 1700 | O28: 1800 | P28: 1900 | Q28: 2000 | R28: 2100 | S28: 2200 | T28: 2300 | U28: 2400 | V28: 2500 | W28: 2600 | X28: 2700 | Y28: 2800 | Z28: 2900 | AA28: 3000
A29: 600 | B29: =ROUND((((Coefficienti!$B$1+Coefficienti!$B$2*B$28+Coefficienti!$B$3*$A29)*Parametri!$B$1+(Coefficienti!$B$4+Coefficienti!$B$5*B$28+Coefficienti!$B$6*$A29)*Parametri!$B$2)*(1-Parametri!$B$3)+((Coefficienti!$B$7+Coefficienti!$B$8*B$28+Coefficienti!$B$9*$A29)+Coefficienti!$B$10)*(1-Parametri!$B$4))*(1+Parametri!$B$5)+FerrGriglia!B2+Coefficienti!$B$11*Parametri!$B$6,2) | C29: =ROUND((((Coefficienti!$B$1+Coefficienti!$B$2*C$28+Coefficienti!$B$3*$A29)*Parametri!$B$1+(Coefficienti!$B$4+Coefficienti!$B$5*C$28+Coefficienti!$B$6*$A29)*Parametri!$B$2)*(1-Parametri!$B$3)+((Coefficienti!$B$7+Coefficienti!$B$8*C$28+Coefficienti!$B$9*$A29)+Coefficienti!$B$10)*(1-Parametri!$B$4))*(1+Parametri!$B$5)+FerrGriglia!C2+Coefficienti!$B$11*Parametri!$B$6,2) | D29: =ROUND((((Coefficienti!$B$1+Coefficienti!$B$2*D$28+Coefficienti!$B$3*$A29)*Parametri!$B$1+(Coefficienti!$B$4+Coefficienti!$B$5*D$28+Coefficienti!$B$6*$A29)*Parametri!$B$2)*(1-Parametri!$B$3)+((Coefficienti!$B$7+Coefficienti!$B$8*D$28+Coefficienti!$B$9*$A29)+Coefficienti!$B$10)*(1-Parametri!$B$4))*(1+Parametri!$B$5)+FerrGriglia!D2+Coefficienti!$B$11*Parametri!$B$6,2) | E29: =ROUND((((Coefficienti!$B$1+Coefficienti!$B$2*E$28+Coefficienti!$B$3*$A29)*Parametri!$B$1+(Coefficienti!$B$4+Coefficienti!$B$5*E$28+Coefficienti!$B$6*$A29)*Parametri!$B$2)*(1-Parametri!$B$3)+((Coefficienti!$B$7+Coefficienti!$B$8*E$28+Coefficienti!$B$9*$A29)+Coefficienti!$B$10)*(1-Parametri!$B$4))*(1+Parametri!$B$5)+FerrGriglia!E2+Coefficienti!$B$11*Parametri!$B$6,2) | F29: =ROUND((((Coefficienti!$B$1+Coefficienti!$B$2*F$28+Coefficienti!$B$3*$A29)*Parametri!$B$1+(Coefficienti!$B$4+Coefficienti!$B$5*F$28+Coefficienti!$B$6*$A29)*Parametri!$B$2)*(1-Parametri!$B$3)+((Coefficienti!$B$7+Coefficienti!$B$8*F$28+Coefficienti!$B$9*$A29)+Coefficienti!$B$10)*(1-Parametri!$B$4))*(1+Parametri!$B$5)+FerrGriglia!F2+Coefficienti!$B$11*Parametri!$B$6,2) | G29: =ROUND((((Coefficienti!$B$1+Coefficienti!$B$2*G$28+Coefficienti!$B$3*$A29)*Parametri!$B$1+(Coefficienti!$B$4+Coefficienti!$B$5*G$28+Coefficienti!$B$6*$A29)*Parametri!$B$2)*(1-Parametri!$B$3)+((Coefficienti!$B$7+Coefficienti!$B$8*G$28+Coefficienti!$B$9*$A29)+Coefficienti!$B$10)*(1-Parametri!$B$4))*(1+Parametri!$B$5)+FerrGriglia!G2+Coefficienti!$B$11*Parametri!$B$6,2) | H29: =ROUND((((Coefficienti!$B$1+Coefficienti!$B$2*H$28+Coefficienti!$B$3*$A29)*Parametri!$B$1+(Coefficienti!$B$4+Coefficienti!$B$5*H$28+Coefficienti!$B$6*$A29)*Parametri!$B$2)*(1-Parametri!$B$3)+((Coefficienti!$B$7+Coefficienti!$B$8*H$28+Coefficienti!$B$9*$A29)+Coefficienti!$B$10)*(1-Parametri!$B$4))*(1+Parametri!$B$5)+FerrGriglia!H2+Coefficienti!$B$11*Parametri!$B$6,2) | I29: =ROUND((((Coefficienti!$B$1+Coefficienti!$B$2*I$28+Coefficienti!$B$3*$A29)*Parametri!$B$1+(Coefficienti!$B$4+Coefficienti!$B$5*I$28+Coefficienti!$B$6*$A29)*Parametri!$B$2)*(1-Parametri!$B$3)+((Coefficienti!$B$7+Coefficienti!$B$8*I$28+Coefficienti!$B$9*$A29)+Coefficienti!$B$10)*(1-Parametri!$B$4))*(1+Parametri!$B$5)+FerrGriglia!I2+Coefficienti!$B$11*Parametri!$B$6,2) | ... AA29: =ROUND((((Coefficienti!$B$1+Coefficienti!$B$2*AA$28+Coefficienti!$B$3*$A29)*Parametri!$B$1+(Coefficienti!$B$4+Coefficienti!$B$5*AA$28+Coefficienti!$B$6*$A29)*Parametri!$B$2)*(1-Parametri!$B$3)+((Coefficienti!$B$7+Coefficienti!$B$8*AA$28+Coefficienti!$B$9*$A29)+Coefficienti!$B$10)*(1-Parametri!$B$4))*(1+Parametri!$B$5)+FerrGriglia!AA2+Coefficienti!$B$11*Parametri!$B$6,2)
A30: 700 | B30: =ROUND((((Coefficienti!$B$1+Coefficienti!$B$2*B$28+Coefficienti!$B$3*$A30)*Parametri!$B$1+(Coefficienti!$B$4+Coefficienti!$B$5*B$28+Coefficienti!$B$6*$A30)*Parametri!$B$2)*(1-Parametri!$B$3)+((Coefficienti!$B$7+Coefficienti!$B$8*B$28+Coefficienti!$B$9*$A30)+Coefficienti!$B$10)*(1-Parametri!$B$4))*(1+Parametri!$B$5)+FerrGriglia!B3+Coefficienti!$B$11*Parametri!$B$6,2) | C30: =ROUND((((Coefficienti!$B$1+Coefficienti!$B$2*C$28+Coefficienti!$B$3*$A30)*Parametri!$B$1+(Coefficienti!$B$4+Coefficienti!$B$5*C$28+Coefficienti!$B$6*$A30)*Parametri!$B$2)*(1-Parametri!$B$3)+((Coefficienti!$B$7+Coefficienti!$B$8*C$28+Coefficienti!$B$9*$A30)+Coefficienti!$B$10)*(1-Parametri!$B$4))*(1+Parametri!$B$5)+FerrGriglia!C3+Coefficienti!$B$11*Parametri!$B$6,2) | D30: =ROUND((((Coefficienti!$B$1+Coefficienti!$B$2*D$28+Coefficienti!$B$3*$A30)*Parametri!$B$1+(Coefficienti!$B$4+Coefficienti!$B$5*D$28+Coefficienti!$B$6*$A30)*Parametri!$B$2)*(1-Parametri!$B$3)+((Coefficienti!$B$7+Coefficienti!$B$8*D$28+Coefficienti!$B$9*$A30)+Coefficienti!$B$10)*(1-Parametri!$B$4))*(1+Parametri!$B$5)+FerrGriglia!D3+Coefficienti!$B$11*Parametri!$B$6,2) | E30: =ROUND((((Coefficienti!$B$1+Coefficienti!$B$2*E$28+Coefficienti!$B$3*$A30)*Parametri!$B$1+(Coefficienti!$B$4+Coefficienti!$B$5*E$28+Coefficienti!$B$6*$A30)*Parametri!$B$2)*(1-Parametri!$B$3)+((Coefficienti!$B$7+Coefficienti!$B$8*E$28+Coefficienti!$B$9*$A30)+Coefficienti!$B$10)*(1-Parametri!$B$4))*(1+Parametri!$B$5)+FerrGriglia!E3+Coefficienti!$B$11*Parametri!$B$6,2) | F30: =ROUND((((Coefficienti!$B$1+Coefficienti!$B$2*F$28+Coefficienti!$B$3*$A30)*Parametri!$B$1+(Coefficienti!$B$4+Coefficienti!$B$5*F$28+Coefficienti!$B$6*$A30)*Parametri!$B$2)*(1-Parametri!$B$3)+((Coefficienti!$B$7+Coefficienti!$B$8*F$28+Coefficienti!$B$9*$A30)+Coefficienti!$B$10)*(1-Parametri!$B$4))*(1+Parametri!$B$5)+FerrGriglia!F3+Coefficienti!$B$11*Parametri!$B$6,2) | G30: =ROUND((((Coefficienti!$B$1+Coefficienti!$B$2*G$28+Coefficienti!$B$3*$A30)*Parametri!$B$1+(Coefficienti!$B$4+Coefficienti!$B$5*G$28+Coefficienti!$B$6*$A30)*Parametri!$B$2)*(1-Parametri!$B$3)+((Coefficienti!$B$7+Coefficienti!$B$8*G$28+Coefficienti!$B$9*$A30)+Coefficienti!$B$10)*(1-Parametri!$B$4))*(1+Parametri!$B$5)+FerrGriglia!G3+Coefficienti!$B$11*Parametri!$B$6,2) | H30: =ROUND((((Coefficienti!$B$1+Coefficienti!$B$2*H$28+Coefficienti!$B$3*$A30)*Parametri!$B$1+(Coefficienti!$B$4+Coefficienti!$B$5*H$28+Coefficienti!$B$6*$A30)*Parametri!$B$2)*(1-Parametri!$B$3)+((Coefficienti!$B$7+Coefficienti!$B$8*H$28+Coefficienti!$B$9*$A30)+Coefficienti!$B$10)*(1-Parametri!$B$4))*(1+Parametri!$B$5)+FerrGriglia!H3+Coefficienti!$B$11*Parametri!$B$6,2) | I30: =ROUND((((Coefficienti!$B$1+Coefficienti!$B$2*I$28+Coefficienti!$B$3*$A30)*Parametri!$B$1+(Coefficienti!$B$4+Coefficienti!$B$5*I$28+Coefficienti!$B$6*$A30)*Parametri!$B$2)*(1-Parametri!$B$3)+((Coefficienti!$B$7+Coefficienti!$B$8*I$28+Coefficienti!$B$9*$A30)+Coefficienti!$B$10)*(1-Parametri!$B$4))*(1+Parametri!$B$5)+FerrGriglia!I3+Coefficienti!$B$11*Parametri!$B$6,2) | ... AA30: =ROUND((((Coefficienti!$B$1+Coefficienti!$B$2*AA$28+Coefficienti!$B$3*$A30)*Parametri!$B$1+(Coefficienti!$B$4+Coefficienti!$B$5*AA$28+Coefficienti!$B$6*$A30)*Parametri!$B$2)*(1-Parametri!$B$3)+((Coefficienti!$B$7+Coefficienti!$B$8*AA$28+Coefficienti!$B$9*$A30)+Coefficienti!$B$10)*(1-Parametri!$B$4))*(1+Parametri!$B$5)+FerrGriglia!AA3+Coefficienti!$B$11*Parametri!$B$6,2)
A31: 800 | B31: =ROUND((((Coefficienti!$B$1+Coefficienti!$B$2*B$28+Coefficienti!$B$3*$A31)*Parametri!$B$1+(Coefficienti!$B$4+Coefficienti!$B$5*B$28+Coefficienti!$B$6*$A31)*Parametri!$B$2)*(1-Parametri!$B$3)+((Coefficienti!$B$7+Coefficienti!$B$8*B$28+Coefficienti!$B$9*$A31)+Coefficienti!$B$10)*(1-Parametri!$B$4))*(1+Parametri!$B$5)+FerrGriglia!B4+Coefficienti!$B$11*Parametri!$B$6,2) | C31: =ROUND((((Coefficienti!$B$1+Coefficienti!$B$2*C$28+Coefficienti!$B$3*$A31)*Parametri!$B$1+(Coefficienti!$B$4+Coefficienti!$B$5*C$28+Coefficienti!$B$6*$A31)*Parametri!$B$2)*(1-Parametri!$B$3)+((Coefficienti!$B$7+Coefficienti!$B$8*C$28+Coefficienti!$B$9*$A31)+Coefficienti!$B$10)*(1-Parametri!$B$4))*(1+Parametri!$B$5)+FerrGriglia!C4+Coefficienti!$B$11*Parametri!$B$6,2) | D31: =ROUND((((Coefficienti!$B$1+Coefficienti!$B$2*D$28+Coefficienti!$B$3*$A31)*Parametri!$B$1+(Coefficienti!$B$4+Coefficienti!$B$5*D$28+Coefficienti!$B$6*$A31)*Parametri!$B$2)*(1-Parametri!$B$3)+((Coefficienti!$B$7+Coefficienti!$B$8*D$28+Coefficienti!$B$9*$A31)+Coefficienti!$B$10)*(1-Parametri!$B$4))*(1+Parametri!$B$5)+FerrGriglia!D4+Coefficienti!$B$11*Parametri!$B$6,2) | E31: =ROUND((((Coefficienti!$B$1+Coefficienti!$B$2*E$28+Coefficienti!$B$3*$A31)*Parametri!$B$1+(Coefficienti!$B$4+Coefficienti!$B$5*E$28+Coefficienti!$B$6*$A31)*Parametri!$B$2)*(1-Parametri!$B$3)+((Coefficienti!$B$7+Coefficienti!$B$8*E$28+Coefficienti!$B$9*$A31)+Coefficienti!$B$10)*(1-Parametri!$B$4))*(1+Parametri!$B$5)+FerrGriglia!E4+Coefficienti!$B$11*Parametri!$B$6,2) | F31: =ROUND((((Coefficienti!$B$1+Coefficienti!$B$2*F$28+Coefficienti!$B$3*$A31)*Parametri!$B$1+(Coefficienti!$B$4+Coefficienti!$B$5*F$28+Coefficienti!$B$6*$A31)*Parametri!$B$2)*(1-Parametri!$B$3)+((Coefficienti!$B$7+Coefficienti!$B$8*F$28+Coefficienti!$B$9*$A31)+Coefficienti!$B$10)*(1-Parametri!$B$4))*(1+Parametri!$B$5)+FerrGriglia!F4+Coefficienti!$B$11*Parametri!$B$6,2) | G31: =ROUND((((Coefficienti!$B$1+Coefficienti!$B$2*G$28+Coefficienti!$B$3*$A31)*Parametri!$B$1+(Coefficienti!$B$4+Coefficienti!$B$5*G$28+Coefficienti!$B$6*$A31)*Parametri!$B$2)*(1-Parametri!$B$3)+((Coefficienti!$B$7+Coefficienti!$B$8*G$28+Coefficienti!$B$9*$A31)+Coefficienti!$B$10)*(1-Parametri!$B$4))*(1+Parametri!$B$5)+FerrGriglia!G4+Coefficienti!$B$11*Parametri!$B$6,2) | H31: =ROUND((((Coefficienti!$B$1+Coefficienti!$B$2*H$28+Coefficienti!$B$3*$A31)*Parametri!$B$1+(Coefficienti!$B$4+Coefficienti!$B$5*H$28+Coefficienti!$B$6*$A31)*Parametri!$B$2)*(1-Parametri!$B$3)+((Coefficienti!$B$7+Coefficienti!$B$8*H$28+Coefficienti!$B$9*$A31)+Coefficienti!$B$10)*(1-Parametri!$B$4))*(1+Parametri!$B$5)+FerrGriglia!H4+Coefficienti!$B$11*Parametri!$B$6,2) | I31: =ROUND((((Coefficienti!$B$1+Coefficienti!$B$2*I$28+Coefficienti!$B$3*$A31)*Parametri!$B$1+(Coefficienti!$B$4+Coefficienti!$B$5*I$28+Coefficienti!$B$6*$A31)*Parametri!$B$2)*(1-Parametri!$B$3)+((Coefficienti!$B$7+Coefficienti!$B$8*I$28+Coefficienti!$B$9*$A31)+Coefficienti!$B$10)*(1-Parametri!$B$4))*(1+Parametri!$B$5)+FerrGriglia!I4+Coefficienti!$B$11*Parametri!$B$6,2) | ... AA31: =ROUND((((Coefficienti!$B$1+Coefficienti!$B$2*AA$28+Coefficienti!$B$3*$A31)*Parametri!$B$1+(Coefficienti!$B$4+Coefficienti!$B$5*AA$28+Coefficienti!$B$6*$A31)*Parametri!$B$2)*(1-Parametri!$B$3)+((Coefficienti!$B$7+Coefficienti!$B$8*AA$28+Coefficienti!$B$9*$A31)+Coefficienti!$B$10)*(1-Parametri!$B$4))*(1+Parametri!$B$5)+FerrGriglia!AA4+Coefficienti!$B$11*Parametri!$B$6,2)
