Workbook

Sheet Prezzo
A1: LISTINO — FINESTRA 2 ANTE (2A75) — C75S SENZA VETRO — RAL 7016 (costo +213%)
A2: H/L | B2: 800 | C2: 900 | D2: 1000 | E2: 1100 | F2: 1200 | G2: 1300 | H2: 1400 | I2: 1500 | J2: 1600 | K2: 1700 | L2: 1800 | M2: 1900 | N2: 2000
A3: 500 | B3: =ROUND(ROUND((((Coefficienti!$B$1+Coefficienti!$B$2*B$2+Coefficienti!$B$3*$A3)*Parametri!$B$1+(Coefficienti!$B$4+Coefficienti!$B$5*B$2+Coefficienti!$B$6*$A3)*Parametri!$B$2)*(1-Parametri!$B$3)+((Coefficienti!$B$7+Coefficienti!$B$8*B$2+Coefficienti!$B$9*$A3)+Coefficienti!$B$10)*(1-Parametri!$B$4))*(1+Parametri!$B$5)+FerrGriglia!B2+Coefficienti!$B$11*Parametri!$B$6,2)*(1+Parametri!$B$7),2) | C3: =ROUND(ROUND((((Coefficienti!$B$1+Coefficienti!$B$2*C$2+Coefficienti!$B$3*$A3)*Parametri!$B$1+(Coefficienti!$B$4+Coefficienti!$B$5*C$2+Coefficienti!$B$6*$A3)*Parametri!$B$2)*(1-Parametri!$B$3)+((Coefficienti!$B$7+Coefficienti!$B$8*C$2+Coefficienti!$B$9*$A3)+Coefficienti!$B$10)*(1-Parametri!$B$4))*(1+Parametri!$B$5)+FerrGriglia!C2+Coefficienti!$B$11*Parametri!$B$6,2)*(1+Parametri!$B$7),2) | D3: =ROUND(ROUND((((Coefficienti!$B$1+Coefficienti!$B$2*D$2+Coefficienti!$B$3*$A3)*Parametri!$B$1+(Coefficienti!$B$4+Coefficienti!$B$5*D$2+Coefficienti!$B$6*$A3)*Parametri!$B$2)*(1-Parametri!$B$3)+((Coefficienti!$B$7+Coefficienti!$B$8*D$2+Coefficienti!$B$9*$A3)+Coefficienti!$B$10)*(1-Parametri!$B$4))*(1+Parametri!$B$5)+FerrGriglia!D2+Coefficienti!$B$11*Parametri!$B$6,2)*(1+Parametri!$B$7),2) | E3: =ROUND(ROUND((((Coefficienti!$B$1+Coefficienti!$B$2*E$2+Coefficienti!$B$3*$A3)*Parametri!$B$1+(Coefficienti!$B$4+Coefficienti!$B$5*E$2+Coefficienti!$B$6*$A3)*Parametri!$B$2)*(1-Parametri!$B$3)+((Coefficienti!$B$7+Coefficienti!$B$8*E$2+Coefficienti!$B$9*$A3)+Coefficienti!$B$10)*(1-Parametri!$B$4))*(1+Parametri!$B$5)+FerrGriglia!E2+Coefficienti!$B$11*Parametri!$B$6,2)*(1+Parametri!$B$7),2) | F3: =ROUND(ROUND((((Coefficienti!$B$1+Coefficienti!$B$2*F$2+Coefficienti!$B$3*$A3)*Parametri!$B$1+(Coefficienti!$B$4+Coefficienti!$B$5*F$2+Coefficienti!$B$6*$A3)*Parametri!$B$2)*(1-Parametri!$B$3)+((Coefficienti!$B$7+Coefficienti!$B$8*F$2+Coefficienti!$B$9*$A3)+Coefficienti!$B$10)*(1-Parametri!$B$4))*(1+Parametri!$B$5)+FerrGriglia!F2+Coefficienti!$B$11*Parametri!$B$6,2)*(1+Parametri!$B$7),2) | G3: =ROUND(ROUND((((Coefficienti!$B$1+Coefficienti!$B$2*G$2+Coefficienti!$B$3*$A3)*Parametri!$B$1+(Coefficienti!$B$4+Coefficienti!$B$5*G$2+Coefficienti!$B$6*$A3)*Parametri!$B$2)*(1-Parametri!$B$3)+((Coefficienti!$B$7+Coefficienti!$B$8*G$2+Coefficienti!$B$9*$A3)+Coefficienti!$B$10)*(1-Parametri!$B$4))*(1+Parametri!$B$5)+FerrGriglia!G2+Coefficienti!$B$11*Parametri!$B$6,2)*(1+Parametri!$B$7),2) | H3: =ROUND(ROUND((((Coefficienti!$B$1+Coefficienti!$B$2*H$2+Coefficienti!$B$3*$A3)*Parametri!$B$1+(Coefficienti!$B$4+Coefficienti!$B$5*H$2+Coefficienti!$B$6*$A3)*Parametri!$B$2)*(1-Parametri!$B$3)+((Coefficienti!$B$7+Coefficienti!$B$8*H$2+Coefficienti!$B$9*$A3)+Coefficienti!$B$10)*(1-Parametri!$B$4))*(1+Parametri!$B$5)+FerrGriglia!H2+Coefficienti!$B$11*Parametri!$B$6,2)*(1+Parametri!$B$7),2) | I3: =ROUND(ROUND((((Coefficienti!$B$1+Coefficienti!$B$2*I$2+Coefficienti!$B$3*$A3)*Parametri!$B$1+(Coefficienti!$B$4+Coefficienti!$B$5*I$2+Coefficienti!$B$6*$A3)*Parametri!$B$2)*(1-Parametri!$B$3)+((Coefficienti!$B$7+Coefficienti!$B$8*I$2+Coefficienti!$B$9*$A3)+Coefficienti!$B$10)*(1-Parametri!$B$4))*(1+Parametri!$B$5)+FerrGriglia!I2+Coefficienti!$B$11*Parametri!$B$6,2)*(1+Parametri!$B$7),2) | ... N3: =ROUND(ROUND((((Coefficienti!$B$1+Coefficienti!$B$2*N$2+Coefficienti!$B$3*$A3)*Parametri!$B$1+(Coefficienti!$B$4+Coefficienti!$B$5*N$2+Coefficienti!$B$6*$A3)*Parametri!$B$2)*(1-Parametri!$B$3)+((Coefficienti!$B$7+Coefficienti!$B$8*N$2+Coefficienti!$B$9*$A3)+Coefficienti!$B$10)*(1-Parametri!$B$4))*(1+Parametri!$B$5)+FerrGriglia!N2+Coefficienti!$B$11*Parametri!$B$6,2)*(1+Parametri!$B$7),2)
A4: 600 | B4: =ROUND(ROUND((((Coefficienti!$B$1+Coefficienti!$B$2*B$2+Coefficienti!$B$3*$A4)*Parametri!$B$1+(Coefficienti!$B$4+Coefficienti!$B$5*B$2+Coefficienti!$B$6*$A4)*Parametri!$B$2)*(1-Parametri!$B$3)+((Coefficienti!$B$7+Coefficienti!$B$8*B$2+Coefficienti!$B$9*$A4)+Coefficienti!$B$10)*(1-Parametri!$B$4))*(1+Parametri!$B$5)+FerrGriglia!B3+Coefficienti!$B$11*Parametri!$B$6,2)*(1+Parametri!$B$7),2) | C4: =ROUND(ROUND((((Coefficienti!$B$1+Coefficienti!$B$2*C$2+Coefficienti!$B$3*$A4)*Parametri!$B$1+(Coefficienti!$B$4+Coefficienti!$B$5*C$2+Coefficienti!$B$6*$A4)*Parametri!$B$2)*(1-Parametri!$B$3)+((Coefficienti!$B$7+Coefficienti!$B$8*C$2+Coefficienti!$B$9*$A4)+Coefficienti!$B$10)*(1-Parametri!$B$4))*(1+Parametri!$B$5)+FerrGriglia!C3+Coefficienti!$B$11*Parametri!$B$6,2)*(1+Parametri!$B$7),2) | D4: =ROUND(ROUND((((Coefficienti!$B$1+Coefficienti!$B$2*D$2+Coefficienti!$B$3*$A4)*Parametri!$B$1+(Coefficienti!$B$4+Coefficienti!$B$5*D$2+Coefficienti!$B$6*$A4)*Parametri!$B$2)*(1-Parametri!$B$3)+((Coefficienti!$B$7+Coefficienti!$B$8*D$2+Coefficienti!$B$9*$A4)+Coefficienti!$B$10)*(1-Parametri!$B$4))*(1+Parametri!$B$5)+FerrGriglia!D3+Coefficienti!$B$11*Parametri!$B$6,2)*(1+Parametri!$B$7),2) | E4: =ROUND(ROUND((((Coefficienti!$B$1+Coefficienti!$B$2*E$2+Coefficienti!$B$3*$A4)*Parametri!$B$1+(Coefficienti!$B$4+Coefficienti!$B$5*E$2+Coefficienti!$B$6*$A4)*Parametri!$B$2)*(1-Parametri!$B$3)+((Coefficienti!$B$7+Coefficienti!$B$8*E$2+Coefficienti!$B$9*$A4)+Coefficienti!$B$10)*(1-Parametri!$B$4))*(1+Parametri!$B$5)+FerrGriglia!E3+Coefficienti!$B$11*Parametri!$B$6,2)*(1+Parametri!$B$7),2) | F4: =ROUND(ROUND((((Coefficienti!$B$1+Coefficienti!$B$2*F$2+Coefficienti!$B$3*$A4)*Parametri!$B$1+(Coefficienti!$B$4+Coefficienti!$B$5*F$2+Coefficienti!$B$6*$A4)*Parametri!$B$2)*(1-Parametri!$B$3)+((Coefficienti!$B$7+Coefficienti!$B$8*F$2+Coefficienti!$B$9*$A4)+Coefficienti!$B$10)*(1-Parametri!$B$4))*(1+Parametri!$B$5)+FerrGriglia!F3+Coefficienti!$B$11*Parametri!$B$6,2)*(1+Parametri!$B$7),2) | G4: =ROUND(ROUND((((Coefficienti!$B$1+Coefficienti!$B$2*G$2+Coefficienti!$B$3*$A4)*Parametri!$B$1+(Coefficienti!$B$4+Coefficienti!$B$5*G$2+Coefficienti!$B$6*$A4)*Parametri!$B$2)*(1-Parametri!$B$3)+((Coefficienti!$B$7+Coefficienti!$B$8*G$2+Coefficienti!$B$9*$A4)+Coefficienti!$B$10)*(1-Parametri!$B$4))*(1+Parametri!$B$5)+FerrGriglia!G3+Coefficienti!$B$11*Parametri!$B$6,2)*(1+Parametri!$B$7),2) | H4: =ROUND(ROUND((((Coefficienti!$B$1+Coefficienti!$B$2*H$2+Coefficienti!$B$3*$A4)*Parametri!$B$1+(Coefficienti!$B$4+Coefficienti!$B$5*H$2+Coefficienti!$B$6*$A4)*Parametri!$B$2)*(1-Parametri!$B$3)+((Coefficienti!$B$7+Coefficienti!$B$8*H$2+Coefficienti!$B$9*$A4)+Coefficienti!$B$10)*(1-Parametri!$B$4))*(1+Parametri!$B$5)+FerrGriglia!H3+Coefficienti!$B$11*Parametri!$B$6,2)*(1+Parametri!$B$7),2) | I4: =ROUND(ROUND((((Coefficienti!$B$1+Coefficienti!$B$2*I$2+Coefficienti!$B$3*$A4)*Parametri!$B$1+(Coefficienti!$B$4+Coefficienti!$B$5*I$2+Coefficienti!$B$6*$A4)*Parametri!$B$2)*(1-Parametri!$B$3)+((Coefficienti!$B$7+Coefficienti!$B$8*I$2+Coefficienti!$B$9*$A4)+Coefficienti!$B$10)*(1-Parametri!$B$4))*(1+Parametri!$B$5)+FerrGriglia!I3+Coefficienti!$B$11*Parametri!$B$6,2)*(1+Parametri!$B$7),2) | ... N4: =ROUND(ROUND((((Coefficienti!$B$1+Coefficienti!$B$2*N$2+Coefficienti!$B$3*$A4)*Parametri!$B$1+(Coefficienti!$B$4+Coefficienti!$B$5*N$2+Coefficienti!$B$6*$A4)*Parametri!$B$2)*(1-Parametri!$B$3)+((Coefficienti!$B$7+Coefficienti!$B$8*N$2+Coefficienti!$B$9*$A4)+Coefficienti!$B$10)*(1-Parametri!$B$4))*(1+Parametri!$B$5)+FerrGriglia!N3+Coefficienti!$B$11*Parametri!$B$6,2)*(1+Parametri!$B$7),2)
A5: 700 | B5: =ROUND(ROUND((((Coefficienti!$B$1+Coefficienti!$B$2*B$2+Coefficienti!$B$3*$A5)*Parametri!$B$1+(Coefficienti!$B$4+Coefficienti!$B$5*B$2+Coefficienti!$B$6*$A5)*Parametri!$B$2)*(1-Parametri!$B$3)+((Coefficienti!$B$7+Coefficienti!$B$8*B$2+Coefficienti!$B$9*$A5)+Coefficienti!$B$10)*(1-Parametri!$B$4))*(1+Parametri!$B$5)+FerrGriglia!B4+Coefficienti!$B$11*Parametri!$B$6,2)*(1+Parametri!$B$7),2) | C5: =ROUND(ROUND((((Coefficienti!$B$1+Coefficienti!$B$2*C$2+Coefficienti!$B$3*$A5)*Parametri!$B$1+(Coefficienti!$B$4+Coefficienti!$B$5*C$2+Coefficienti!$B$6*$A5)*Parametri!$B$2)*(1-Parametri!$B$3)+((Coefficienti!$B$7+Coefficienti!$B$8*C$2+Coefficienti!$B$9*$A5)+Coefficienti!$B$10)*(1-Parametri!$B$4))*(1+Parametri!$B$5)+FerrGriglia!C4+Coefficienti!$B$11*Parametri!$B$6,2)*(1+Parametri!$B$7),2) | D5: =ROUND(ROUND((((Coefficienti!$B$1+Coefficienti!$B$2*D$2+Coefficienti!$B$3*$A5)*Parametri!$B$1+(Coefficienti!$B$4+Coefficienti!$B$5*D$2+Coefficienti!$B$6*$A5)*Parametri!$B$2)*(1-Parametri!$B$3)+((Coefficienti!$B$7+Coefficienti!$B$8*D$2+Coefficienti!$B$9*$A5)+Coefficienti!$B$10)*(1-Parametri!$B$4))*(1+Parametri!$B$5)+FerrGriglia!D4+Coefficienti!$B$11*Parametri!$B$6,2)*(1+Parametri!$B$7),2) | E5: =ROUND(ROUND((((Coefficienti!$B$1+Coefficienti!$B$2*E$2+Coefficienti!$B$3*$A5)*Parametri!$B$1+(Coefficienti!$B$4+Coefficienti!$B$5*E$2+Coefficienti!$B$6*$A5)*Parametri!$B$2)*(1-Parametri!$B$3)+((Coefficienti!$B$7+Coefficienti!$B$8*E$2+Coefficienti!$B$9*$A5)+Coefficienti!$B$10)*(1-Parametri!$B$4))*(1+Parametri!$B$5)+FerrGriglia!E4+Coefficienti!$B$11*Parametri!$B$6,2)*(1+Parametri!$B$7),2) | F5: =ROUND(ROUND((((Coefficienti!$B$1+Coefficienti!$B$2*F$2+Coefficienti!$B$3*$A5)*Parametri!$B$1+(Coefficienti!$B$4+Coefficienti!$B$5*F$2+Coefficienti!$B$6*$A5)*Parametri!$B$2)*(1-Parametri!$B$3)+((Coefficienti!$B$7+Coefficienti!$B$8*F$2+Coefficienti!$B$9*$A5)+Coefficienti!$B$10)*(1-Parametri!$B$4))*(1+Parametri!$B$5)+FerrGriglia!F4+Coefficienti!$B$11*Parametri!$B$6,2)*(1+Parametri!$B$7),2) | G5: =ROUND(ROUND((((Coefficienti!$B$1+Coefficienti!$B$2*G$2+Coefficienti!$B$3*$A5)*Parametri!$B$1+(Coefficienti!$B$4+Coefficienti!$B$5*G$2+Coefficienti!$B$6*$A5)*Parametri!$B$2)*(1-Parametri!$B$3)+((Coefficienti!$B$7+Coefficienti!$B$8*G$2+Coefficienti!$B$9*$A5)+Coefficienti!$B$10)*(1-Parametri!$B$4))*(1+Parametri!$B$5)+FerrGriglia!G4+Coefficienti!$B$11*Parametri!$B$6,2)*(1+Parametri!$B$7),2) | H5: =ROUND(ROUND((((Coefficienti!$B$1+Coefficienti!$B$2*H$2+Coefficienti!$B$3*$A5)*Parametri!$B$1+(Coefficienti!$B$4+Coefficienti!$B$5*H$2+Coefficienti!$B$6*$A5)*Parametri!$B$2)*(1-Parametri!$B$3)+((Coefficienti!$B$7+Coefficienti!$B$8*H$2+Coefficienti!$B$9*$A5)+Coefficienti!$B$10)*(1-Parametri!$B$4))*(1+Parametri!$B$5)+FerrGriglia!H4+Coefficienti!$B$11*Parametri!$B$6,2)*(1+Parametri!$B$7),2) | I5: =ROUND(ROUND((((Coefficienti!$B$1+Coefficienti!$B$2*I$2+Coefficienti!$B$3*$A5)*Parametri!$B$1+(Coefficienti!$B$4+Coefficienti!$B$5*I$2+Coefficienti!$B$6*$A5)*Parametri!$B$2)*(1-Parametri!$B$3)+((Coefficienti!$B$7+Coefficienti!$B$8*I$2+Coefficienti!$B$9*$A5)+Coefficienti!$B$10)*(1-Parametri!$B$4))*(1+Parametri!$B$5)+FerrGriglia!I4+Coefficienti!$B$11*Parametri!$B$6,2)*(1+Parametri!$B$7),2) | ... N5: =ROUND(ROUND((((Coefficienti!$B$1+Coefficienti!$B$2*N$2+Coefficienti!$B$3*$A5)*Parametri!$B$1+(Coefficienti!$B$4+Coefficienti!$B$5*N$2+Coefficienti!$B$6*$A5)*Parametri!$B$2)*(1-Parametri!$B$3)+((Coefficienti!$B$7+Coefficienti!$B$8*N$2+Coefficienti!$B$9*$A5)+Coefficienti!$B$10)*(1-Parametri!$B$4))*(1+Parametri!$B$5)+FerrGriglia!N4+Coefficienti!$B$11*Parametri!$B$6,2)*(1+Parametri!$B$7),2)
A6: 800 | B6: =ROUND(ROUND((((Coefficienti!$B$1+Coefficienti!$B$2*B$2+Coefficienti!$B$3*$A6)*Parametri!$B$1+(Coefficienti!$B$4+Coefficienti!$B$5*B$2+Coefficienti!$B$6*$A6)*Parametri!$B$2)*(1-Parametri!$B$3)+((Coefficienti!$B$7+Coefficienti!$B$8*B$2+Coefficienti!$B$9*$A6)+Coefficienti!$B$10)*(1-Parametri!$B$4))*(1+Parametri!$B$5)+FerrGriglia!B5+Coefficienti!$B$11*Parametri!$B$6,2)*(1+Parametri!$B$7),2) | C6: =ROUND(ROUND((((Coefficienti!$B$1+Coefficienti!$B$2*C$2+Coefficienti!$B$3*$A6)*Parametri!$B$1+(Coefficienti!$B$4+Coefficienti!$B$5*C$2+Coefficienti!$B$6*$A6)*Parametri!$B$2)*(1-Parametri!$B$3)+((Coefficienti!$B$7+Coefficienti!$B$8*C$2+Coefficienti!$B$9*$A6)+Coefficienti!$B$10)*(1-Parametri!$B$4))*(1+Parametri!$B$5)+FerrGriglia!C5+Coefficienti!$B$11*Parametri!$B$6,2)*(1+Parametri!$B$7),2) | D6: =ROUND(ROUND((((Coefficienti!$B$1+Coefficienti!$B$2*D$2+Coefficienti!$B$3*$A6)*Parametri!$B$1+(Coefficienti!$B$4+Coefficienti!$B$5*D$2+Coefficienti!$B$6*$A6)*Parametri!$B$2)*(1-Parametri!$B$3)+((Coefficienti!$B$7+Coefficienti!$B$8*D$2+Coefficienti!$B$9*$A6)+Coefficienti!$B$10)*(1-Parametri!$B$4))*(1+Parametri!$B$5)+FerrGriglia!D5+Coefficienti!$B$11*Parametri!$B$6,2)*(1+Parametri!$B$7),2) | E6: =ROUND(ROUND((((Coefficienti!$B$1+Coefficienti!$B$2*E$2+Coefficienti!$B$3*$A6)*Parametri!$B$1+(Coefficienti!$B$4+Coefficienti!$B$5*E$2+Coefficienti!$B$6*$A6)*Parametri!$B$2)*(1-Parametri!$B$3)+((Coefficienti!$B$7+Coefficienti!$B$8*E$2+Coefficienti!$B$9*$A6)+Coefficienti!$B$10)*(1-Parametri!$B$4))*(1+Parametri!$B$5)+FerrGriglia!E5+Coefficienti!$B$11*Parametri!$B$6,2)*(1+Parametri!$B$7),2) | F6: =ROUND(ROUND((((Coefficienti!$B$1+Coefficienti!$B$2*F$2+Coefficienti!$B$3*$A6)*Parametri!$B$1+(Coefficienti!$B$4+Coefficienti!$B$5*F$2+Coefficienti!$B$6*$A6)*Parametri!$B$2)*(1-Parametri!$B$3)+((Coefficienti!$B$7+Coefficienti!$B$8*F$2+Coefficienti!$B$9*$A6)+Coefficienti!$B$10)*(1-Parametri!$B$4))*(1+Parametri!$B$5)+FerrGriglia!F5+Coefficienti!$B$11*Parametri!$B$6,2)*(1+Parametri!$B$7),2) | G6: =ROUND(ROUND((((Coefficienti!$B$1+Coefficienti!$B$2*G$2+Coefficienti!$B$3*$A6)*Parametri!$B$1+(Coefficienti!$B$4+Coefficienti!$B$5*G$2+Coefficienti!$B$6*$A6)*Parametri!$B$2)*(1-Parametri!$B$3)+((Coefficienti!$B$7+Coefficienti!$B$8*G$2+Coefficienti!$B$9*$A6)+Coefficienti!$B$10)*(1-Parametri!$B$4))*(1+Parametri!$B$5)+FerrGriglia!G5+Coefficienti!$B$11*Parametri!$B$6,2)*(1+Parametri!$B$7),2) | H6: =ROUND(ROUND((((Coefficienti!$B$1+Coefficienti!$B$2*H$2+Coefficienti!$B$3*$A6)*Parametri!$B$1+(Coefficienti!$B$4+Coefficienti!$B$5*H$2+Coefficienti!$B$6*$A6)*Parametri!$B$2)*(1-Parametri!$B$3)+((Coefficienti!$B$7+Coefficienti!$B$8*H$2+Coefficienti!$B$9*$A6)+Coefficienti!$B$10)*(1-Parametri!$B$4))*(1+Parametri!$B$5)+FerrGriglia!H5+Coefficienti!$B$11*Parametri!$B$6,2)*(1+Parametri!$B$7),2) | I6: =ROUND(ROUND((((Coefficienti!$B$1+Coefficienti!$B$2*I$2+Coefficienti!$B$3*$A6)*Parametri!$B$1+(Coefficienti!$B$4+Coefficienti!$B$5*I$2+Coefficienti!$B$6*$A6)*Parametri!$B$2)*(1-Parametri!$B$3)+((Coefficienti!$B$7+Coefficienti!$B$8*I$2+Coefficienti!$B$9*$A6)+Coefficienti!$B$10)*(1-Parametri!$B$4))*(1+Parametri!$B$5)+FerrGriglia!I5+Coefficienti!$B$11*Parametri!$B$6,2)*(1+Parametri!$B$7),2) | ... N6: =ROUND(ROUND((((Coefficienti!$B$1+Coefficienti!$B$2*N$2+Coefficienti!$B$3*$A6)*Parametri!$B$1+(Coefficienti!$B$4+Coefficienti!$B$5*N$2+Coefficienti!$B$6*$A6)*Parametri!$B$2)*(1-Parametri!$B$3)+((Coefficienti!$B$7+Coefficienti!$B$8*N$2+Coefficienti!$B$9*$A6)+Coefficienti!$B$10)*(1-Parametri!$B$4))*(1+Parametri!$B$5)+FerrGriglia!N5+Coefficienti!$B$11*Parametri!$B$6,2)*(1+Parametri!$B$7),2)
A7: 900 | B7: =ROUND(ROUND((((Coefficienti!$B$1+Coefficienti!$B$2*B$2+Coefficienti!$B$3*$A7)*Parametri!$B$1+(Coefficienti!$B$4+Coefficienti!$B$5*B$2+Coefficienti!$B$6*$A7)*Parametri!$B$2)*(1-Parametri!$B$3)+((Coefficienti!$B$7+Coefficienti!$B$8*B$2+Coefficienti!$B$9*$A7)+Coefficienti!$B$10)*(1-Parametri!$B$4))*(1+Parametri!$B$5)+FerrGriglia!B6+Coefficienti!$B$11*Parametri!$B$6,2)*(1+Parametri!$B$7),2) | C7: =ROUND(ROUND((((Coefficienti!$B$1+Coefficienti!$B$2*C$2+Coefficienti!$B$3*$A7)*Parametri!$B$1+(Coefficienti!$B$4+Coefficienti!$B$5*C$2+Coefficienti!$B$6*$A7)*Parametri!$B$2)*(1-Parametri!$B$3)+((Coefficienti!$B$7+Coefficienti!$B$8*C$2+Coefficienti!$B$9*$A7)+Coefficienti!$B$10)*(1-Parametri!$B$4))*(1+Parametri!$B$5)+FerrGriglia!C6+Coefficienti!$B$11*Parametri!$B$6,2)*(1+Parametri!$B$7),2) | D7: =ROUND(ROUND((((Coefficienti!$B$1+Coefficienti!$B$2*D$2+Coefficienti!$B$3*$A7)*Parametri!$B$1+(Coefficienti!$B$4+Coefficienti!$B$5*D$2+Coefficienti!$B$6*$A7)*Parametri!$B$2)*(1-Parametri!$B$3)+((Coefficienti!$B$7+Coefficienti!$B$8*D$2+Coefficienti!$B$9*$A7)+Coefficienti!$B$10)*(1-Parametri!$B$4))*(1+Parametri!$B$5)+FerrGriglia!D6+Coefficienti!$B$11*Parametri!$B$6,2)*(1+Parametri!$B$7),2) | E7: =ROUND(ROUND((((Coefficienti!$B$1+Coefficienti!$B$2*E$2+Coefficienti!$B$3*$A7)*Parametri!$B$1+(Coefficienti!$B$4+Coefficienti!$B$5*E$2+Coefficienti!$B$6*$A7)*Parametri!$B$2)*(1-Parametri!$B$3)+((Coefficienti!$B$7+Coefficienti!$B$8*E$2+Coefficienti!$B$9*$A7)+Coefficienti!$B$10)*(1-Parametri!$B$4))*(1+Parametri!$B$5)+FerrGriglia!E6+Coefficienti!$B$11*Parametri!$B$6,2)*(1+Parametri!$B$7),2) | F7: =ROUND(ROUND((((Coefficienti!$B$1+Coefficienti!$B$2*F$2+Coefficienti!$B$3*$A7)*Parametri!$B$1+(Coefficienti!$B$4+Coefficienti!$B$5*F$2+Coefficienti!$B$6*$A7)*Parametri!$B$2)*(1-Parametri!$B$3)+((Coefficienti!$B$7+Coefficienti!$B$8*F$2+Coefficienti!$B$9*$A7)+Coefficienti!$B$10)*(1-Parametri!$B$4))*(1+Parametri!$B$5)+FerrGriglia!F6+Coefficienti!$B$11*Parametri!$B$6,2)*(1+Parametri!$B$7),2) | G7: =ROUND(ROUND((((Coefficienti!$B$1+Coefficienti!$B$2*G$2+Coefficienti!$B$3*$A7)*Parametri!$B$1+(Coefficienti!$B$4+Coefficienti!$B$5*G$2+Coefficienti!$B$6*$A7)*Parametri!$B$2)*(1-Parametri!$B$3)+((Coefficienti!$B$7+Coefficienti!$B$8*G$2+Coefficienti!$B$9*$A7)+Coefficienti!$B$10)*(1-Parametri!$B$4))*(1+Parametri!$B$5)+FerrGriglia!G6+Coefficienti!$B$11*Parametri!$B$6,2)*(1+Parametri!$B$7),2) | H7: =ROUND(ROUND((((Coefficienti!$B$1+Coefficienti!$B$2*H$2+Coefficienti!$B$3*$A7)*Parametri!$B$1+(Coefficienti!$B$4+Coefficienti!$B$5*H$2+Coefficienti!$B$6*$A7)*Parametri!$B$2)*(1-Parametri!$B$3)+((Coefficienti!$B$7+Coefficienti!$B$8*H$2+Coefficienti!$B$9*$A7)+Coefficienti!$B$10)*(1-Parametri!$B$4))*(1+Parametri!$B$5)+FerrGriglia!H6+Coefficienti!$B$11*Parametri!$B$6,2)*(1+Parametri!$B$7),2) | I7: =ROUND(ROUND((((Coefficienti!$B$1+Coefficienti!$B$2*I$2+Coefficienti!$B$3*$A7)*Parametri!$B$1+(Coefficienti!$B$4+Coefficienti!$B$5*I$2+Coefficienti!$B$6*$A7)*Parametri!$B$2)*(1-Parametri!$B$3)+((Coefficienti!$B$7+Coefficienti!$B$8*I$2+Coefficienti!$B$9*$A7)+Coefficienti!$B$10)*(1-Parametri!$B$4))*(1+Parametri!$B$5)+FerrGriglia!I6+Coefficienti!$B$11*Parametri!$B$6,2)*(1+Parametri!$B$7),2) | ... N7: =ROUND(ROUND((((Coefficienti!$B$1+Coefficienti!$B$2*N$2+Coefficienti!$B$3*$A7)*Parametri!$B$1+(Coefficienti!$B$4+Coefficienti!$B$5*N$2+Coefficienti!$B$6*$A7)*Parametri!$B$2)*(1-Parametri!$B$3)+((Coefficienti!$B$7+Coefficienti!$B$8*N$2+Coefficienti!$B$9*$A7)+Coefficienti!$B$10)*(1-Parametri!$B$4))*(1+Parametri!$B$5)+FerrGriglia!N6+Coefficienti!$B$11*Parametri!$B$6,2)*(1+Parametri!$B$7),2)
A8: 1000 | B8: =ROUND(ROUND((((Coefficienti!$B$1+Coefficienti!$B$2*B$2+Coefficienti!$B$3*$A8)*Parametri!$B$1+(Coefficienti!$B$4+Coefficienti!$B$5*B$2+Coefficienti!$B$6*$A8)*Parametri!$B$2)*(1-Parametri!$B$3)+((Coefficienti!$B$7+Coefficienti!$B$8*B$2+Coefficienti!$B$9*$A8)+Coefficienti!$B$10)*(1-Parametri!$B$4))*(1+Parametri!$B$5)+FerrGriglia!B7+Coefficienti!$B$11*Parametri!$B$6,2)*(1+Parametri!$B$7),2) | C8: =ROUND(ROUND((((Coefficienti!$B$1+Coefficienti!$B$2*C$2+Coefficienti!$B$3*$A8)*Parametri!$B$1+(Coefficienti!$B$4+Coefficienti!$B$5*C$2+Coefficienti!$B$6*$A8)*Parametri!$B$2)*(1-Parametri!$B$3)+((Coefficienti!$B$7+Coefficienti!$B$8*C$2+Coefficienti!$B$9*$A8)+Coefficienti!$B$10)*(1-Parametri!$B$4))*(1+Parametri!$B$5)+FerrGriglia!C7+Coefficienti!$B$11*Parametri!$B$6,2)*(1+Parametri!$B$7),2) | D8: =ROUND(ROUND((((Coefficienti!$B$1+Coefficienti!$B$2*D$2+Coefficienti!$B$3*$A8)*Parametri!$B$1+(Coefficienti!$B$4+Coefficienti!$B$5*D$2+Coefficienti!$B$6*$A8)*Parametri!$B$2)*(1-Parametri!$B$3)+((Coefficienti!$B$7+Coefficienti!$B$8*D$2+Coefficienti!$B$9*$A8)+Coefficienti!$B$10)*(1-Parametri!$B$4))*(1+Parametri!$B$5)+FerrGriglia!D7+Coefficienti!$B$11*Parametri!$B$6,2)*(1+Parametri!$B$7),2) | E8: =ROUND(ROUND((((Coefficienti!$B$1+Coefficienti!$B$2*E$2+Coefficienti!$B$3*$A8)*Parametri!$B$1+(Coefficienti!$B$4+Coefficienti!$B$5*E$2+Coefficienti!$B$6*$A8)*Parametri!$B$2)*(1-Parametri!$B$3)+((Coefficienti!$B$7+Coefficienti!$B$8*E$2+Coefficienti!$B$9*$A8)+Coefficienti!$B$10)*(1-Parametri!$B$4))*(1+Parametri!$B$5)+FerrGriglia!E7+Coefficienti!$B$11*Parametri!$B$6,2)*(1+Parametri!$B$7),2) | F8: =ROUND(ROUND((((Coefficienti!$B$1+Coefficienti!$B$2*F$2+Coefficienti!$B$3*$A8)*Parametri!$B$1+(Coefficienti!$B$4+Coefficienti!$B$5*F$2+Coefficienti!$B$6*$A8)*Parametri!$B$2)*(1-Parametri!$B$3)+((Coefficienti!$B$7+Coefficienti!$B$8*F$2+Coefficienti!$B$9*$A8)+Coefficienti!$B$10)*(1-Parametri!$B$4))*(1+Parametri!$B$5)+FerrGriglia!F7+Coefficienti!$B$11*Parametri!$B$6,2)*(1+Parametri!$B$7),2) | G8: =ROUND(ROUND((((Coefficienti!$B$1+Coefficienti!$B$2*G$2+Coefficienti!$B$3*$A8)*Parametri!$B$1+(Coefficienti!$B$4+Coefficienti!$B$5*G$2+Coefficienti!$B$6*$A8)*Parametri!$B$2)*(1-Parametri!$B$3)+((Coefficienti!$B$7+Coefficienti!$B$8*G$2+Coefficienti!$B$9*$A8)+Coefficienti!$B$10)*(1-Parametri!$B$4))*(1+Parametri!$B$5)+FerrGriglia!G7+Coefficienti!$B$11*Parametri!$B$6,2)*(1+Parametri!$B$7),2) | H8: =ROUND(ROUND((((Coefficienti!$B$1+Coefficienti!$B$2*H$2+Coefficienti!$B$3*$A8)*Parametri!$B$1+(Coefficienti!$B$4+Coefficienti!$B$5*H$2+Coefficienti!$B$6*$A8)*Parametri!$B$2)*(1-Parametri!$B$3)+((Coefficienti!$B$7+Coefficienti!$B$8*H$2+Coefficienti!$B$9*$A8)+Coefficienti!$B$10)*(1-Parametri!$B$4))*(1+Parametri!$B$5)+FerrGriglia!H7+Coefficienti!$B$11*Parametri!$B$6,2)*(1+Parametri!$B$7),2) | I8: =ROUND(ROUND((((Coefficienti!$B$1+Coefficienti!$B$2*I$2+Coefficienti!$B$3*$A8)*Parametri!$B$1+(Coefficienti!$B$4+Coefficienti!$B$5*I$2+Coefficienti!$B$6*$A8)*Parametri!$B$2)*(1-Parametri!$B$3)+((Coefficienti!$B$7+Coefficienti!$B$8*I$2+Coefficienti!$B$9*$A8)+Coefficienti!$B$10)*(1-Parametri!$B$4))*(1+Parametri!$B$5)+FerrGriglia!I7+Coefficienti!$B$11*Parametri!$B$6,2)*(1+Parametri!$B$7),2) | ... N8: =ROUND(ROUND((((Coefficienti!$B$1+Coefficienti!$B$2*N$2+Coefficienti!$B$3*$A8)*Parametri!$B$1+(Coefficienti!$B$4+Coefficienti!$B$5*N$2+Coefficienti!$B$6*$A8)*Parametri!$B$2)*(1-Parametri!$B$3)+((Coefficienti!$B$7+Coefficienti!$B$8*N$2+Coefficienti!$B$9*$A8)+Coefficienti!$B$10)*(1-Parametri!$B$4))*(1+Parametri!$B$5)+FerrGriglia!N7+Coefficienti!$B$11*Parametri!$B$6,2)*(1+Parametri!$B$7),2)
A9: 1100 | B9: =ROUND(ROUND((((Coefficienti!$B$1+Coefficienti!$B$2*B$2+Coefficienti!$B$3*$A9)*Parametri!$B$1+(Coefficienti!$B$4+Coefficienti!$B$5*B$2+Coefficienti!$B$6*$A9)*Parametri!$B$2)*(1-Parametri!$B$3)+((Coefficienti!$B$7+Coefficienti!$B$8*B$2+Coefficienti!$B$9*$A9)+Coefficienti!$B$10)*(1-Parametri!$B$4))*(1+Parametri!$B$5)+FerrGriglia!B8+Coefficienti!$B$11*Parametri!$B$6,2)*(1+Parametri!$B$7),2) | C9: =ROUND(ROUND((((Coefficienti!$B$1+Coefficienti!$B$2*C$2+Coefficienti!$B$3*$A9)*Parametri!$B$1+(Coefficienti!$B$4+Coefficienti!$B$5*C$2+Coefficienti!$B$6*$A9)*Parametri!$B$2)*(1-Parametri!$B$3)+((Coefficienti!$B$7+Coefficienti!$B$8*C$2+Coefficienti!$B$9*$A9)+Coefficienti!$B$10)*(1-Parametri!$B$4))*(1+Parametri!$B$5)+FerrGriglia!C8+Coefficienti!$B$11*Parametri!$B$6,2)*(1+Parametri!$B$7),2) | D9: =ROUND(ROUND((((Coefficienti!$B$1+Coefficienti!$B$2*D$2+Coefficienti!$B$3*$A9)*Parametri!$B$1+(Coefficienti!$B$4+Coefficienti!$B$5*D$2+Coefficienti!$B$6*$A9)*Parametri!$B$2)*(1-Parametri!$B$3)+((Coefficienti!$B$7+Coefficienti!$B$8*D$2+Coefficienti!$B$9*$A9)+Coefficienti!$B$10)*(1-Parametri!$B$4))*(1+Parametri!$B$5)+FerrGriglia!D8+Coefficienti!$B$11*Parametri!$B$6,2)*(1+Parametri!$B$7),2) | E9: =ROUND(ROUND((((Coefficienti!$B$1+Coefficienti!$B$2*E$2+Coefficienti!$B$3*$A9)*Parametri!$B$1+(Coefficienti!$B$4+Coefficienti!$B$5*E$2+Coefficienti!$B$6*$A9)*Parametri!$B$2)*(1-Parametri!$B$3)+((Coefficienti!$B$7+Coefficienti!$B$8*E$2+Coefficienti!$B$9*$A9)+Coefficienti!$B$10)*(1-Parametri!$B$4))*(1+Parametri!$B$5)+FerrGriglia!E8+Coefficienti!$B$11*Parametri!$B$6,2)*(1+Parametri!$B$7),2) | F9: =ROUND(ROUND((((Coefficienti!$B$1+Coefficienti!$B$2*F$2+Coefficienti!$B$3*$A9)*Parametri!$B$1+(Coefficienti!$B$4+Coefficienti!$B$5*F$2+Coefficienti!$B$6*$A9)*Parametri!$B$2)*(1-Parametri!$B$3)+((Coefficienti!$B$7+Coefficienti!$B$8*F$2+Coefficienti!$B$9*$A9)+Coefficienti!$B$10)*(1-Parametri!$B$4))*(1+Parametri!$B$5)+FerrGriglia!F8+Coefficienti!$B$11*Parametri!$B$6,2)*(1+Parametri!$B$7),2) | G9: =ROUND(ROUND((((Coefficienti!$B$1+Coefficienti!$B$2*G$2+Coefficienti!$B$3*$A9)*Parametri!$B$1+(Coefficienti!$B$4+Coefficienti!$B$5*G$2+Coefficienti!$B$6*$A9)*Parametri!$B$2)*(1-Parametri!$B$3)+((Coefficienti!$B$7+Coefficienti!$B$8*G$2+Coefficienti!$B$9*$A9)+Coefficienti!$B$10)*(1-Parametri!$B$4))*(1+Parametri!$B$5)+FerrGriglia!G8+Coefficienti!$B$11*Parametri!$B$6,2)*(1+Parametri!$B$7),2) | H9: =ROUND(ROUND((((Coefficienti!$B$1+Coefficienti!$B$2*H$2+Coefficienti!$B$3*$A9)*Parametri!$B$1+(Coefficienti!$B$4+Coefficienti!$B$5*H$2+Coefficienti!$B$6*$A9)*Parametri!$B$2)*(1-Parametri!$B$3)+((Coefficienti!$B$7+Coefficienti!$B$8*H$2+Coefficienti!$B$9*$A9)+Coefficienti!$B$10)*(1-Parametri!$B$4))*(1+Parametri!$B$5)+FerrGriglia!H8+Coefficienti!$B$11*Parametri!$B$6,2)*(1+Parametri!$B$7),2) | I9: =ROUND(ROUND((((Coefficienti!$B$1+Coefficienti!$B$2*I$2+Coefficienti!$B$3*$A9)*Parametri!$B$1+(Coefficienti!$B$4+Coefficienti!$B$5*I$2+Coefficienti!$B$6*$A9)*Parametri!$B$2)*(1-Parametri!$B$3)+((Coefficienti!$B$7+Coefficienti!$B$8*I$2+Coefficienti!$B$9*$A9)+Coefficienti!$B$10)*(1-Parametri!$B$4))*(1+Parametri!$B$5)+FerrGriglia!I8+Coefficienti!$B$11*Parametri!$B$6,2)*(1+Parametri!$B$7),2) | ... N9: =ROUND(ROUND((((Coefficienti!$B$1+Coefficienti!$B$2*N$2+Coefficienti!$B$3*$A9)*Parametri!$B$1+(Coefficienti!$B$4+Coefficienti!$B$5*N$2+Coefficienti!$B$6*$A9)*Parametri!$B$2)*(1-Parametri!$B$3)+((Coefficienti!$B$7+Coefficienti!$B$8*N$2+Coefficienti!$B$9*$A9)+Coefficienti!$B$10)*(1-Parametri!$B$4))*(1+Parametri!$B$5)+FerrGriglia!N8+Coefficienti!$B$11*Parametri!$B$6,2)*(1+Parametri!$B$7),2)
A10: 1200 | B10: =ROUND(ROUND((((Coefficienti!$B$1+Coefficienti!$B$2*B$2+Coefficienti!$B$3*$A10)*Parametri!$B$1+(Coefficienti!$B$4+Coefficienti!$B$5*B$2+Coefficienti!$B$6*$A10)*Parametri!$B$2)*(1-Parametri!$B$3)+((Coefficienti!$B$7+Coefficienti!$B$8*B$2+Coefficienti!$B$9*$A10)+Coefficienti!$B$10)*(1-Parametri!$B$4))*(1+Parametri!$B$5)+FerrGriglia!B9+Coefficienti!$B$11*Parametri!$B$6,2)*(1+Parametri!$B$7),2) | C10: =ROUND(ROUND((((Coefficienti!$B$1+Coefficienti!$B$2*C$2+Coefficienti!$B$3*$A10)*Parametri!$B$1+(Coefficienti!$B$4+Coefficienti!$B$5*C$2+Coefficienti!$B$6*$A10)*Parametri!$B$2)*(1-Parametri!$B$3)+((Coefficienti!$B$7+Coefficienti!$B$8*C$2+Coefficienti!$B$9*$A10)+Coefficienti!$B$10)*(1-Parametri!$B$4))*(1+Parametri!$B$5)+FerrGriglia!C9+Coefficienti!$B$11*Parametri!$B$6,2)*(1+Parametri!$B$7),2) | D10: =ROUND(ROUND((((Coefficienti!$B$1+Coefficienti!$B$2*D$2+Coefficienti!$B$3*$A10)*Parametri!$B$1+(Coefficienti!$B$4+Coefficienti!$B$5*D$2+Coefficienti!$B$6*$A10)*Parametri!$B$2)*(1-Parametri!$B$3)+((Coefficienti!$B$7+Coefficienti!$B$8*D$2+Coefficienti!$B$9*$A10)+Coefficienti!$B$10)*(1-Parametri!$B$4))*(1+Parametri!$B$5)+FerrGriglia!D9+Coefficienti!$B$11*Parametri!$B$6,2)*(1+Parametri!$B$7),2) | E10: =ROUND(ROUND((((Coefficienti!$B$1+Coefficienti!$B$2*E$2+Coefficienti!$B$3*$A10)*Parametri!$B$1+(Coefficienti!$B$4+Coefficienti!$B$5*E$2+Coefficienti!$B$6*$A10)*Parametri!$B$2)*(1-Parametri!$B$3)+((Coefficienti!$B$7+Coefficienti!$B$8*E$2+Coefficienti!$B$9*$A10)+Coefficienti!$B$10)*(1-Parametri!$B$4))*(1+Parametri!$B$5)+FerrGriglia!E9+Coefficienti!$B$11*Parametri!$B$6,2)*(1+Parametri!$B$7),2) | F10: =ROUND(ROUND((((Coefficienti!$B$1+Coefficienti!$B$2*F$2+Coefficienti!$B$3*$A10)*Parametri!$B$1+(Coefficienti!$B$4+Coefficienti!$B$5*F$2+Coefficienti!$B$6*$A10)*Parametri!$B$2)*(1-Parametri!$B$3)+((Coefficienti!$B$7+Coefficienti!$B$8*F$2+Coefficienti!$B$9*$A10)+Coefficienti!$B$10)*(1-Parametri!$B$4))*(1+Parametri!$B$5)+FerrGriglia!F9+Coefficienti!$B$11*Parametri!$B$6,2)*(1+Parametri!$B$7),2) | G10: =ROUND(ROUND((((Coefficienti!$B$1+Coefficienti!$B$2*G$2+Coefficienti!$B$3*$A10)*Parametri!$B$1+(Coefficienti!$B$4+Coefficienti!$B$5*G$2+Coefficienti!$B$6*$A10)*Parametri!$B$2)*(1-Parametri!$B$3)+((Coefficienti!$B$7+Coefficienti!$B$8*G$2+Coefficienti!$B$9*$A10)+Coefficienti!$B$10)*(1-Parametri!$B$4))*(1+Parametri!$B$5)+FerrGriglia!G9+Coefficienti!$B$11*Parametri!$B$6,2)*(1+Parametri!$B$7),2) | H10: =ROUND(ROUND((((Coefficienti!$B$1+Coefficienti!$B$2*H$2+Coefficienti!$B$3*$A10)*Parametri!$B$1+(Coefficienti!$B$4+Coefficienti!$B$5*H$2+Coefficienti!$B$6*$A10)*Parametri!$B$2)*(1-Parametri!$B$3)+((Coefficienti!$B$7+Coefficienti!$B$8*H$2+Coefficienti!$B$9*$A10)+Coefficienti!$B$10)*(1-Parametri!$B$4))*(1+Parametri!$B$5)+FerrGriglia!H9+Coefficienti!$B$11*Parametri!$B$6,2)*(1+Parametri!$B$7),2) | I10: =ROUND(ROUND((((Coefficienti!$B$1+Coefficienti!$B$2*I$2+Coefficienti!$B$3*$A10)*Parametri!$B$1+(Coefficienti!$B$4+Coefficienti!$B$5*I$2+Coefficienti!$B$6*$A10)*Parametri!$B$2)*(1-Parametri!$B$3)+((Coefficienti!$B$7+Coefficienti!$B$8*I$2+Coefficienti!$B$9*$A10)+Coefficienti!$B$10)*(1-Parametri!$B$4))*(1+Parametri!$B$5)+FerrGriglia!I9+Coefficienti!$B$11*Parametri!$B$6,2)*(1+Parametri!$B$7),2) | ... N10: =ROUND(ROUND((((Coefficienti!$B$1+Coefficienti!$B$2*N$2+Coefficienti!$B$3*$A10)*Parametri!$B$1+(Coefficienti!$B$4+Coefficienti!$B$5*N$2+Coefficienti!$B$6*$A10)*Parametri!$B$2)*(1-Parametri!$B$3)+((Coefficienti!$B$7+Coefficienti!$B$8*N$2+Coefficienti!$B$9*$A10)+Coefficienti!$B$10)*(1-Parametri!$B$4))*(1+Parametri!$B$5)+FerrGriglia!N9+Coefficienti!$B$11*Parametri!$B$6,2)*(1+Parametri!$B$7),2)
A11: 1300 | B11: =ROUND(ROUND((((Coefficienti!$B$1+Coefficienti!$B$2*B$2+Coefficienti!$B$3*$A11)*Parametri!$B$1+(Coefficienti!$B$4+Coefficienti!$B$5*B$2+Coefficienti!$B$6*$A11)*Parametri!$B$2)*(1-Parametri!$B$3)+((Coefficienti!$B$7+Coefficienti!$B$8*B$2+Coefficienti!$B$9*$A11)+Coefficienti!$B$10)*(1-Parametri!$B$4))*(1+Parametri!$B$5)+FerrGriglia!B10+Coefficienti!$B$11*Parametri!$B$6,2)*(1+Parametri!$B$7),2) | C11: =ROUND(ROUND((((Coefficienti!$B$1+Coefficienti!$B$2*C$2+Coefficienti!$B$3*$A11)*Parametri!$B$1+(Coefficienti!$B$4+Coefficienti!$B$5*C$2+Coefficienti!$B$6*$A11)*Parametri!$B$2)*(1-Parametri!$B$3)+((Coefficienti!$B$7+Coefficienti!$B$8*C$2+Coefficienti!$B$9*$A11)+Coefficienti!$B$10)*(1-Parametri!$B$4))*(1+Parametri!$B$5)+FerrGriglia!C10+Coefficienti!$B$11*Parametri!$B$6,2)*(1+Parametri!$B$7),2) | D11: =ROUND(ROUND((((Coefficienti!$B$1+Coefficienti!$B$2*D$2+Coefficienti!$B$3*$A11)*Parametri!$B$1+(Coefficienti!$B$4+Coefficienti!$B$5*D$2+Coefficienti!$B$6*$A11)*Parametri!$B$2)*(1-Parametri!$B$3)+((Coefficienti!$B$7+Coefficienti!$B$8*D$2+Coefficienti!$B$9*$A11)+Coefficienti!$B$10)*(1-Parametri!$B$4))*(1+Parametri!$B$5)+FerrGriglia!D10+Coefficienti!$B$11*Parametri!$B$6,2)*(1+Parametri!$B$7),2) | E11: =ROUND(ROUND((((Coefficienti!$B$1+Coefficienti!$B$2*E$2+Coefficienti!$B$3*$A11)*Parametri!$B$1+(Coefficienti!$B$4+Coefficienti!$B$5*E$2+Coefficienti!$B$6*$A11)*Parametri!$B$2)*(1-Parametri!$B$3)+((Coefficienti!$B$7+Coefficienti!$B$8*E$2+Coefficienti!$B$9*$A11)+Coefficienti!$B$10)*(1-Parametri!$B$4))*(1+Parametri!$B$5)+FerrGriglia!E10+Coefficienti!$B$11*Parametri!$B$6,2)*(1+Parametri!$B$7),2) | F11: =ROUND(ROUND((((Coefficienti!$B$1+Coefficienti!$B$2*F$2+Coefficienti!$B$3*$A11)*Parametri!$B$1+(Coefficienti!$B$4+Coefficienti!$B$5*F$2+Coefficienti!$B$6*$A11)*Parametri!$B$2)*(1-Parametri!$B$3)+((Coefficienti!$B$7+Coefficienti!$B$8*F$2+Coefficienti!$B$9*$A11)+Coefficienti!$B$10)*(1-Parametri!$B$4))*(1+Parametri!$B$5)+FerrGriglia!F10+Coefficienti!$B$11*Parametri!$B$6,2)*(1+Parametri!$B$7),2) | G11: =ROUND(ROUND((((Coefficienti!$B$1+Coefficienti!$B$2*G$2+Coefficienti!$B$3*$A11)*Parametri!$B$1+(Coefficienti!$B$4+Coefficienti!$B$5*G$2+Coefficienti!$B$6*$A11)*Parametri!$B$2)*(1-Parametri!$B$3)+((Coefficienti!$B$7+Coefficienti!$B$8*G$2+Coefficienti!$B$9*$A11)+Coefficienti!$B$10)*(1-Parametri!$B$4))*(1+Parametri!$B$5)+FerrGriglia!G10+Coefficienti!$B$11*Parametri!$B$6,2)*(1+Parametri!$B$7),2) | H11: =ROUND(ROUND((((Coefficienti!$B$1+Coefficienti!$B$2*H$2+Coefficienti!$B$3*$A11)*Parametri!$B$1+(Coefficienti!$B$4+Coefficienti!$B$5*H$2+Coefficienti!$B$6*$A11)*Parametri!$B$2)*(1-Parametri!$B$3)+((Coefficienti!$B$7+Coefficienti!$B$8*H$2+Coefficienti!$B$9*$A11)+Coefficienti!$B$10)*(1-Parametri!$B$4))*(1+Parametri!$B$5)+FerrGriglia!H10+Coefficienti!$B$11*Parametri!$B$6,2)*(1+Parametri!$B$7),2) | I11: =ROUND(ROUND((((Coefficienti!$B$1+Coefficienti!$B$2*I$2+Coefficienti!$B$3*$A11)*Parametri!$B$1+(Coefficienti!$B$4+Coefficienti!$B$5*I$2+Coefficienti!$B$6*$A11)*Parametri!$B$2)*(1-Parametri!$B$3)+((Coefficienti!$B$7+Coefficienti!$B$8*I$2+Coefficienti!$B$9*$A11)+Coefficienti!$B$10)*(1-Parametri!$B$4))*(1+Parametri!$B$5)+FerrGriglia!I10+Coefficienti!$B$11*Parametri!$B$6,2)*(1+Parametri!$B$7),2) | ... N11: =ROUND(ROUND((((Coefficienti!$B$1+Coefficienti!$B$2*N$2+Coefficienti!$B$3*$A11)*Parametri!$B$1+(Coefficienti!$B$4+Coefficienti!$B$5*N$2+Coefficienti!$B$6*$A11)*Parametri!$B$2)*(1-Parametri!$B$3)+((Coefficienti!$B$7+Coefficienti!$B$8*N$2+Coefficienti!$B$9*$A11)+Coefficienti!$B$10)*(1-Parametri!$B$4))*(1+Parametri!$B$5)+FerrGriglia!N10+Coefficienti!$B$11*Parametri!$B$6,2)*(1+Parametri!$B$7),2)
A12: 1400 | B12: =ROUND(ROUND((((Coefficienti!$B$1+Coefficienti!$B$2*B$2+Coefficienti!$B$3*$A12)*Parametri!$B$1+(Coefficienti!$B$4+Coefficienti!$B$5*B$2+Coefficienti!$B$6*$A12)*Parametri!$B$2)*(1-Parametri!$B$3)+((Coefficienti!$B$7+Coefficienti!$B$8*B$2+Coefficienti!$B$9*$A12)+Coefficienti!$B$10)*(1-Parametri!$B$4))*(1+Parametri!$B$5)+FerrGriglia!B11+Coefficienti!$B$11*Parametri!$B$6,2)*(1+Parametri!$B$7),2) | C12: =ROUND(ROUND((((Coefficienti!$B$1+Coefficienti!$B$2*C$2+Coefficienti!$B$3*$A12)*Parametri!$B$1+(Coefficienti!$B$4+Coefficienti!$B$5*C$2+Coefficienti!$B$6*$A12)*Parametri!$B$2)*(1-Parametri!$B$3)+((Coefficienti!$B$7+Coefficienti!$B$8*C$2+Coefficienti!$B$9*$A12)+Coefficienti!$B$10)*(1-Parametri!$B$4))*(1+Parametri!$B$5)+FerrGriglia!C11+Coefficienti!$B$11*Parametri!$B$6,2)*(1+Parametri!$B$7),2) | D12: =ROUND(ROUND((((Coefficienti!$B$1+Coefficienti!$B$2*D$2+Coefficienti!$B$3*$A12)*Parametri!$B$1+(Coefficienti!$B$4+Coefficienti!$B$5*D$2+Coefficienti!$B$6*$A12)*Parametri!$B$2)*(1-Parametri!$B$3)+((Coefficienti!$B$7+Coefficienti!$B$8*D$2+Coefficienti!$B$9*$A12)+Coefficienti!$B$10)*(1-Parametri!$B$4))*(1+Parametri!$B$5)+FerrGriglia!D11+Coefficienti!$B$11*Parametri!$B$6,2)*(1+Parametri!$B$7),2) | E12: =ROUND(ROUND((((Coefficienti!$B$1+Coefficienti!$B$2*E$2+Coefficienti!$B$3*$A12)*Parametri!$B$1+(Coefficienti!$B$4+Coefficienti!$B$5*E$2+Coefficienti!$B$6*$A12)*Parametri!$B$2)*(1-Parametri!$B$3)+((Coefficienti!$B$7+Coefficienti!$B$8*E$2+Coefficienti!$B$9*$A12)+Coefficienti!$B$10)*(1-Parametri!$B$4))*(1+Parametri!$B$5)+FerrGriglia!E11+Coefficienti!$B$11*Parametri!$B$6,2)*(1+Parametri!$B$7),2) | F12: =ROUND(ROUND((((Coefficienti!$B$1+Coefficienti!$B$2*F$2+Coefficienti!$B$3*$A12)*Parametri!$B$1+(Coefficienti!$B$4+Coefficienti!$B$5*F$2+Coefficienti!$B$6*$A12)*Parametri!$B$2)*(1-Parametri!$B$3)+((Coefficienti!$B$7+Coefficienti!$B$8*F$2+Coefficienti!$B$9*$A12)+Coefficienti!$B$10)*(1-Parametri!$B$4))*(1+Parametri!$B$5)+FerrGriglia!F11+Coefficienti!$B$11*Parametri!$B$6,2)*(1+Parametri!$B$7),2) | G12: =ROUND(ROUND((((Coefficienti!$B$1+Coefficienti!$B$2*G$2+Coefficienti!$B$3*$A12)*Parametri!$B$1+(Coefficienti!$B$4+Coefficienti!$B$5*G$2+Coefficienti!$B$6*$A12)*Parametri!$B$2)*(1-Parametri!$B$3)+((Coefficienti!$B$7+Coefficienti!$B$8*G$2+Coefficienti!$B$9*$A12)+Coefficienti!$B$10)*(1-Parametri!$B$4))*(1+Parametri!$B$5)+FerrGriglia!G11+Coefficienti!$B$11*Parametri!$B$6,2)*(1+Parametri!$B$7),2) | H12: =ROUND(ROUND((((Coefficienti!$B$1+Coefficienti!$B$2*H$2+Coefficienti!$B$3*$A12)*Parametri!$B$1+(Coefficienti!$B$4+Coefficienti!$B$5*H$2+Coefficienti!$B$6*$A12)*Parametri!$B$2)*(1-Parametri!$B$3)+((Coefficienti!$B$7+Coefficienti!$B$8*H$2+Coefficienti!$B$9*$A12)+Coefficienti!$B$10)*(1-Parametri!$B$4))*(1+Parametri!$B$5)+FerrGriglia!H11+Coefficienti!$B$11*Parametri!$B$6,2)*(1+Parametri!$B$7),2) | I12: =ROUND(ROUND((((Coefficienti!$B$1+Coefficienti!$B$2*I$2+Coefficienti!$B$3*$A12)*Parametri!$B$1+(Coefficienti!$B$4+Coefficienti!$B$5*I$2+Coefficienti!$B$6*$A12)*Parametri!$B$2)*(1-Parametri!$B$3)+((Coefficienti!$B$7+Coefficienti!$B$8*I$2+Coefficienti!$B$9*$A12)+Coefficienti!$B$10)*(1-Parametri!$B$4))*(1+Parametri!$B$5)+FerrGriglia!I11+Coefficienti!$B$11*Parametri!$B$6,2)*(1+Parametri!$B$7),2) | ... N12: =ROUND(ROUND((((Coefficienti!$B$1+Coefficienti!$B$2*N$2+Coefficienti!$B$3*$A12)*Parametri!$B$1+(Coefficienti!$B$4+Coefficienti!$B$5*N$2+Coefficienti!$B$6*$A12)*Parametri!$B$2)*(1-Parametri!$B$3)+((Coefficienti!$B$7+Coefficienti!$B$8*N$2+Coefficienti!$B$9*$A12)+Coefficienti!$B$10)*(1-Parametri!$B$4))*(1+Parametri!$B$5)+FerrGriglia!N11+Coefficienti!$B$11*Parametri!$B$6,2)*(1+Parametri!$B$7),2)
A13: 1500 | B13: =ROUND(ROUND((((Coefficienti!$B$1+Coefficienti!$B$2*B$2+Coefficienti!$B$3*$A13)*Parametri!$B$1+(Coefficienti!$B$4+Coefficienti!$B$5*B$2+Coefficienti!$B$6*$A13)*Parametri!$B$2)*(1-Parametri!$B$3)+((Coefficienti!$B$7+Coefficienti!$B$8*B$2+Coefficienti!$B$9*$A13)+Coefficienti!$B$10)*(1-Parametri!$B$4))*(1+Parametri!$B$5)+FerrGriglia!B12+Coefficienti!$B$11*Parametri!$B$6,2)*(1+Parametri!$B$7),2) | C13: =ROUND(ROUND((((Coefficienti!$B$1+Coefficienti!$B$2*C$2+Coefficienti!$B$3*$A13)*Parametri!$B$1+(Coefficienti!$B$4+Coefficienti!$B$5*C$2+Coefficienti!$B$6*$A13)*Parametri!$B$2)*(1-Parametri!$B$3)+((Coefficienti!$B$7+Coefficienti!$B$8*C$2+Coefficienti!$B$9*$A13)+Coefficienti!$B$10)*(1-Parametri!$B$4))*(1+Parametri!$B$5)+FerrGriglia!C12+Coefficienti!$B$11*Parametri!$B$6,2)*(1+Parametri!$B$7),2) | D13: =ROUND(ROUND((((Coefficienti!$B$1+Coefficienti!$B$2*D$2+Coefficienti!$B$3*$A13)*Parametri!$B$1+(Coefficienti!$B$4+Coefficienti!$B$5*D$2+Coefficienti!$B$6*$A13)*Parametri!$B$2)*(1-Parametri!$B$3)+((Coefficienti!$B$7+Coefficienti!$B$8*D$2+Coefficienti!$B$9*$A13)+Coefficienti!$B$10)*(1-Parametri!$B$4))*(1+Parametri!$B$5)+FerrGriglia!D12+Coefficienti!$B$11*Parametri!$B$6,2)*(1+Parametri!$B$7),2) | E13: =ROUND(ROUND((((Coefficienti!$B$1+Coefficienti!$B$2*E$2+Coefficienti!$B$3*$A13)*Parametri!$B$1+(Coefficienti!$B$4+Coefficienti!$B$5*E$2+Coefficienti!$B$6*$A13)*Parametri!$B$2)*(1-Parametri!$B$3)+((Coefficienti!$B$7+Coefficienti!$B$8*E$2+Coefficienti!$B$9*$A13)+Coefficienti!$B$10)*(1-Parametri!$B$4))*(1+Parametri!$B$5)+FerrGriglia!E12+Coefficienti!$B$11*Parametri!$B$6,2)*(1+Parametri!$B$7),2) | F13: =ROUND(ROUND((((Coefficienti!$B$1+Coefficienti!$B$2*F$2+Coefficienti!$B$3*$A13)*Parametri!$B$1+(Coefficienti!$B$4+Coefficienti!$B$5*F$2+Coefficienti!$B$6*$A13)*Parametri!$B$2)*(1-Parametri!$B$3)+((Coefficienti!$B$7+Coefficienti!$B$8*F$2+Coefficienti!$B$9*$A13)+Coefficienti!$B$10)*(1-Parametri!$B$4))*(1+Parametri!$B$5)+FerrGriglia!F12+Coefficienti!$B$11*Parametri!$B$6,2)*(1+Parametri!$B$7),2) | G13: =ROUND(ROUND((((Coefficienti!$B$1+Coefficienti!$B$2*G$2+Coefficienti!$B$3*$A13)*Parametri!$B$1+(Coefficienti!$B$4+Coefficienti!$B$5*G$2+Coefficienti!$B$6*$A13)*Parametri!$B$2)*(1-Parametri!$B$3)+((Coefficienti!$B$7+Coefficienti!$B$8*G$2+Coefficienti!$B$9*$A13)+Coefficienti!$B$10)*(1-Parametri!$B$4))*(1+Parametri!$B$5)+FerrGriglia!G12+Coefficienti!$B$11*Parametri!$B$6,2)*(1+Parametri!$B$7),2) | H13: =ROUND(ROUND((((Coefficienti!$B$1+Coefficienti!$B$2*H$2+Coefficienti!$B$3*$A13)*Parametri!$B$1+(Coefficienti!$B$4+Coefficienti!$B$5*H$2+Coefficienti!$B$6*$A13)*Parametri!$B$2)*(1-Parametri!$B$3)+((Coefficienti!$B$7+Coefficienti!$B$8*H$2+Coefficienti!$B$9*$A13)+Coefficienti!$B$10)*(1-Parametri!$B$4))*(1+Parametri!$B$5)+FerrGriglia!H12+Coefficienti!$B$11*Parametri!$B$6,2)*(1+Parametri!$B$7),2) | I13: =ROUND(ROUND((((Coefficienti!$B$1+Coefficienti!$B$2*I$2+Coefficienti!$B$3*$A13)*Parametri!$B$1+(Coefficienti!$B$4+Coefficienti!$B$5*I$2+Coefficienti!$B$6*$A13)*Parametri!$B$2)*(1-Parametri!$B$3)+((Coefficienti!$B$7+Coefficienti!$B$8*I$2+Coefficienti!$B$9*$A13)+Coefficienti!$B$10)*(1-Parametri!$B$4))*(1+Parametri!$B$5)+FerrGriglia!I12+Coefficienti!$B$11*Parametri!$B$6,2)*(1+Parametri!$B$7),2) | ... N13: =ROUND(ROUND((((Coefficienti!$B$1+Coefficienti!$B$2*N$2+Coefficienti!$B$3*$A13)*Parametri!$B$1+(Coefficienti!$B$4+Coefficienti!$B$5*N$2+Coefficienti!$B$6*$A13)*Parametri!$B$2)*(1-Parametri!$B$3)+((Coefficienti!$B$7+Coefficienti!$B$8*N$2+Coefficienti!$B$9*$A13)+Coefficienti!$B$10)*(1-Parametri!$B$4))*(1+Parametri!$B$5)+FerrGriglia!N12+Coefficienti!$B$11*Parametri!$B$6,2)*(1+Parametri!$B$7),2)
A14: 1600 | B14: =ROUND(ROUND((((Coefficienti!$B$1+Coefficienti!$B$2*B$2+Coefficienti!$B$3*$A14)*Parametri!$B$1+(Coefficienti!$B$4+Coefficienti!$B$5*B$2+Coefficienti!$B$6*$A14)*Parametri!$B$2)*(1-Parametri!$B$3)+((Coefficienti!$B$7+Coefficienti!$B$8*B$2+Coefficienti!$B$9*$A14)+Coefficienti!$B$10)*(1-Parametri!$B$4))*(1+Parametri!$B$5)+FerrGriglia!B13+Coefficienti!$B$11*Parametri!$B$6,2)*(1+Parametri!$B$7),2) | C14: =ROUND(ROUND((((Coefficienti!$B$1+Coefficienti!$B$2*C$2+Coefficienti!$B$3*$A14)*Parametri!$B$1+(Coefficienti!$B$4+Coefficienti!$B$5*C$2+Coefficienti!$B$6*$A14)*Parametri!$B$2)*(1-Parametri!$B$3)+((Coefficienti!$B$7+Coefficienti!$B$8*C$2+Coefficienti!$B$9*$A14)+Coefficienti!$B$10)*(1-Parametri!$B$4))*(1+Parametri!$B$5)+FerrGriglia!C13+Coefficienti!$B$11*Parametri!$B$6,2)*(1+Parametri!$B$7),2) | D14: =ROUND(ROUND((((Coefficienti!$B$1+Coefficienti!$B$2*D$2+Coefficienti!$B$3*$A14)*Parametri!$B$1+(Coefficienti!$B$4+Coefficienti!$B$5*D$2+Coefficienti!$B$6*$A14)*Parametri!$B$2)*(1-Parametri!$B$3)+((Coefficienti!$B$7+Coefficienti!$B$8*D$2+Coefficienti!$B$9*$A14)+Coefficienti!$B$10)*(1-Parametri!$B$4))*(1+Parametri!$B$5)+FerrGriglia!D13+Coefficienti!$B$11*Parametri!$B$6,2)*(1+Parametri!$B$7),2) | E14: =ROUND(ROUND((((Coefficienti!$B$1+Coefficienti!$B$2*E$2+Coefficienti!$B$3*$A14)*Parametri!$B$1+(Coefficienti!$B$4+Coefficienti!$B$5*E$2+Coefficienti!$B$6*$A14)*Parametri!$B$2)*(1-Parametri!$B$3)+((Coefficienti!$B$7+Coefficienti!$B$8*E$2+Coefficienti!$B$9*$A14)+Coefficienti!$B$10)*(1-Parametri!$B$4))*(1+Parametri!$B$5)+FerrGriglia!E13+Coefficienti!$B$11*Parametri!$B$6,2)*(1+Parametri!$B$7),2) | F14: =ROUND(ROUND((((Coefficienti!$B$1+Coefficienti!$B$2*F$2+Coefficienti!$B$3*$A14)*Parametri!$B$1+(Coefficienti!$B$4+Coefficienti!$B$5*F$2+Coefficienti!$B$6*$A14)*Parametri!$B$2)*(1-Parametri!$B$3)+((Coefficienti!$B$7+Coefficienti!$B$8*F$2+Coefficienti!$B$9*$A14)+Coefficienti!$B$10)*(1-Parametri!$B$4))*(1+Parametri!$B$5)+FerrGriglia!F13+Coefficienti!$B$11*Parametri!$B$6,2)*(1+Parametri!$B$7),2) | G14: =ROUND(ROUND((((Coefficienti!$B$1+Coefficienti!$B$2*G$2+Coefficienti!$B$3*$A14)*Parametri!$B$1+(Coefficienti!$B$4+Coefficienti!$B$5*G$2+Coefficienti!$B$6*$A14)*Parametri!$B$2)*(1-Parametri!$B$3)+((Coefficienti!$B$7+Coefficienti!$B$8*G$2+Coefficienti!$B$9*$A14)+Coefficienti!$B$10)*(1-Parametri!$B$4))*(1+Parametri!$B$5)+FerrGriglia!G13+Coefficienti!$B$11*Parametri!$B$6,2)*(1+Parametri!$B$7),2) | H14: =ROUND(ROUND((((Coefficienti!$B$1+Coefficienti!$B$2*H$2+Coefficienti!$B$3*$A14)*Parametri!$B$1+(Coefficienti!$B$4+Coefficienti!$B$5*H$2+Coefficienti!$B$6*$A14)*Parametri!$B$2)*(1-Parametri!$B$3)+((Coefficienti!$B$7+Coefficienti!$B$8*H$2+Coefficienti!$B$9*$A14)+Coefficienti!$B$10)*(1-Parametri!$B$4))*(1+Parametri!$B$5)+FerrGriglia!H13+Coefficienti!$B$11*Parametri!$B$6,2)*(1+Parametri!$B$7),2) | I14: =ROUND(ROUND((((Coefficienti!$B$1+Coefficienti!$B$2*I$2+Coefficienti!$B$3*$A14)*Parametri!$B$1+(Coefficienti!$B$4+Coefficienti!$B$5*I$2+Coefficienti!$B$6*$A14)*Parametri!$B$2)*(1-Parametri!$B$3)+((Coefficienti!$B$7+Coefficienti!$B$8*I$2+Coefficienti!$B$9*$A14)+Coefficienti!$B$10)*(1-Parametri!$B$4))*(1+Parametri!$B$5)+FerrGriglia!I13+Coefficienti!$B$11*Parametri!$B$6,2)*(1+Parametri!$B$7),2) | ... N14: =ROUND(ROUND((((Coefficienti!$B$1+Coefficienti!$B$2*N$2+Coefficienti!$B$3*$A14)*Parametri!$B$1+(Coefficienti!$B$4+Coefficienti!$B$5*N$2+Coefficienti!$B$6*$A14)*Parametri!$B$2)*(1-Parametri!$B$3)+((Coefficienti!$B$7+Coefficienti!$B$8*N$2+Coefficienti!$B$9*$A14)+Coefficienti!$B$10)*(1-Parametri!$B$4))*(1+Parametri!$B$5)+FerrGriglia!N13+Coefficienti!$B$11*Parametri!$B$6,2)*(1+Parametri!$B$7),2)
... A18: 2000 | B18: =ROUND(ROUND((((Coefficienti!$B$1+Coefficienti!$B$2*B$2+Coefficienti!$B$3*$A18)*Parametri!$B$1+(Coefficienti!$B$4+Coefficienti!$B$5*B$2+Coefficienti!$B$6*$A18)*Parametri!$B$2)*(1-Parametri!$B$3)+((Coefficienti!$B$7+Coefficienti!$B$8*B$2+Coefficienti!$B$9*$A18)+Coefficienti!$B$10)*(1-Parametri!$B$4))*(1+Parametri!$B$5)+FerrGriglia!B17+Coefficienti!$B$11*Parametri!$B$6,2)*(1+Parametri!$B$7),2) | C18: =ROUND(ROUND((((Coefficienti!$B$1+Coefficienti!$B$2*C$2+Coefficienti!$B$3*$A18)*Parametri!$B$1+(Coefficienti!$B$4+Coefficienti!$B$5*C$2+Coefficienti!$B$6*$A18)*Parametri!$B$2)*(1-Parametri!$B$3)+((Coefficienti!$B$7+Coefficienti!$B$8*C$2+Coefficienti!$B$9*$A18)+Coefficienti!$B$10)*(1-Parametri!$B$4))*(1+Parametri!$B$5)+FerrGriglia!C17+Coefficienti!$B$11*Parametri!$B$6,2)*(1+Parametri!$B$7),2) | D18: =ROUND(ROUND((((Coefficienti!$B$1+Coefficienti!$B$2*D$2+Coefficienti!$B$3*$A18)*Parametri!$B$1+(Coefficienti!$B$4+Coefficienti!$B$5*D$2+Coefficienti!$B$6*$A18)*Parametri!$B$2)*(1-Parametri!$B$3)+((Coefficienti!$B$7+Coefficienti!$B$8*D$2+Coefficienti!$B$9*$A18)+Coefficienti!$B$10)*(1-Parametri!$B$4))*(1+Parametri!$B$5)+FerrGriglia!D17+Coefficienti!$B$11*Parametri!$B$6,2)*(1+Parametri!$B$7),2) | E18: =ROUND(ROUND((((Coefficienti!$B$1+Coefficienti!$B$2*E$2+Coefficienti!$B$3*$A18)*Parametri!$B$1+(Coefficienti!$B$4+Coefficienti!$B$5*E$2+Coefficienti!$B$6*$A18)*Parametri!$B$2)*(1-Parametri!$B$3)+((Coefficienti!$B$7+Coefficienti!$B$8*E$2+Coefficienti!$B$9*$A18)+Coefficienti!$B$10)*(1-Parametri!$B$4))*(1+Parametri!$B$5)+FerrGriglia!E17+Coefficienti!$B$11*Parametri!$B$6,2)*(1+Parametri!$B$7),2) | F18: =ROUND(ROUND((((Coefficienti!$B$1+Coefficienti!$B$2*F$2+Coefficienti!$B$3*$A18)*Parametri!$B$1+(Coefficienti!$B$4+Coefficienti!$B$5*F$2+Coefficienti!$B$6*$A18)*Parametri!$B$2)*(1-Parametri!$B$3)+((Coefficienti!$B$7+Coefficienti!$B$8*F$2+Coefficienti!$B$9*$A18)+Coefficienti!$B$10)*(1-Parametri!$B$4))*(1+Parametri!$B$5)+FerrGriglia!F17+Coefficienti!$B$11*Parametri!$B$6,2)*(1+Parametri!$B$7),2) | G18: =ROUND(ROUND((((Coefficienti!$B$1+Coefficienti!$B$2*G$2+Coefficienti!$B$3*$A18)*Parametri!$B$1+(Coefficienti!$B$4+Coefficienti!$B$5*G$2+Coefficienti!$B$6*$A18)*Parametri!$B$2)*(1-Parametri!$B$3)+((Coefficienti!$B$7+Coefficienti!$B$8*G$2+Coefficienti!$B$9*$A18)+Coefficienti!$B$10)*(1-Parametri!$B$4))*(1+Parametri!$B$5)+FerrGriglia!G17+Coefficienti!$B$11*Parametri!$B$6,2)*(1+Parametri!$B$7),2) | H18: =ROUND(ROUND((((Coefficienti!$B$1+Coefficienti!$B$2*H$2+Coefficienti!$B$3*$A18)*Parametri!$B$1+(Coefficienti!$B$4+Coefficienti!$B$5*H$2+Coefficienti!$B$6*$A18)*Parametri!$B$2)*(1-Parametri!$B$3)+((Coefficienti!$B$7+Coefficienti!$B$8*H$2+Coefficienti!$B$9*$A18)+Coefficienti!$B$10)*(1-Parametri!$B$4))*(1+Parametri!$B$5)+FerrGriglia!H17+Coefficienti!$B$11*Parametri!$B$6,2)*(1+Parametri!$B$7),2) | I18: =ROUND(ROUND((((Coefficienti!$B$1+Coefficienti!$B$2*I$2+Coefficienti!$B$3*$A18)*Parametri!$B$1+(Coefficienti!$B$4+Coefficienti!$B$5*I$2+Coefficienti!$B$6*$A18)*Parametri!$B$2)*(1-Parametri!$B$3)+((Coefficienti!$B$7+Coefficienti!$B$8*I$2+Coefficienti!$B$9*$A18)+Coefficienti!$B$10)*(1-Parametri!$B$4))*(1+Parametri!$B$5)+FerrGriglia!I17+Coefficienti!$B$11*Parametri!$B$6,2)*(1+Parametri!$B$7),2) | ... N18: =ROUND(ROUND((((Coefficienti!$B$1+Coefficienti!$B$2*N$2+Coefficienti!$B$3*$A18)*Parametri!$B$1+(Coefficienti!$B$4+Coefficienti!$B$5*N$2+Coefficienti!$B$6*$A18)*Parametri!$B$2)*(1-Parametri!$B$3)+((Coefficienti!$B$7+Coefficienti!$B$8*N$2+Coefficienti!$B$9*$A18)+Coefficienti!$B$10)*(1-Parametri!$B$4))*(1+Parametri!$B$5)+FerrGriglia!N17+Coefficienti!$B$11*Parametri!$B$6,2)*(1+Parametri!$B$7),2)
A21: COSTO SERRAMENTO (materiale scontato + sfrido + manodopera)
A22: H/L | B22: 800 | C22: 900 | D22: 1000 | E22: 1100 | F22: 1200 | G22: 1300 | H22: 1400 | I22: 1500 | J22: 1600 | K22: 1700 | L22: 1800 | M22: 1900 | N22: 2000
A23: 500 | B23: =ROUND((((Coefficienti!$B$1+Coefficienti!$B$2*B$22+Coefficienti!$B$3*$A23)*Parametri!$B$1+(Coefficienti!$B$4+Coefficienti!$B$5*B$22+Coefficienti!$B$6*$A23)*Parametri!$B$2)*(1-Parametri!$B$3)+((Coefficienti!$B$7+Coefficienti!$B$8*B$22+Coefficienti!$B$9*$A23)+Coefficienti!$B$10)*(1-Parametri!$B$4))*(1+Parametri!$B$5)+FerrGriglia!B2+Coefficienti!$B$11*Parametri!$B$6,2) | C23: =ROUND((((Coefficienti!$B$1+Coefficienti!$B$2*C$22+Coefficienti!$B$3*$A23)*Parametri!$B$1+(Coefficienti!$B$4+Coefficienti!$B$5*C$22+Coefficienti!$B$6*$A23)*Parametri!$B$2)*(1-Parametri!$B$3)+((Coefficienti!$B$7+Coefficienti!$B$8*C$22+Coefficienti!$B$9*$A23)+Coefficienti!$B$10)*(1-Parametri!$B$4))*(1+Parametri!$B$5)+FerrGriglia!C2+Coefficienti!$B$11*Parametri!$B$6,2) | D23: =ROUND((((Coefficienti!$B$1+Coefficienti!$B$2*D$22+Coefficienti!$B$3*$A23)*Parametri!$B$1+(Coefficienti!$B$4+Coefficienti!$B$5*D$22+Coefficienti!$B$6*$A23)*Parametri!$B$2)*(1-Parametri!$B$3)+((Coefficienti!$B$7+Coefficienti!$B$8*D$22+Coefficienti!$B$9*$A23)+Coefficienti!$B$10)*(1-Parametri!$B$4))*(1+Parametri!$B$5)+FerrGriglia!D2+Coefficienti!$B$11*Parametri!$B$6,2) | E23: =ROUND((((Coefficienti!$B$1+Coefficienti!$B$2*E$22+Coefficienti!$B$3*$A23)*Parametri!$B$1+(Coefficienti!$B$4+Coefficienti!$B$5*E$22+Coefficienti!$B$6*$A23)*Parametri!$B$2)*(1-Parametri!$B$3)+((Coefficienti!$B$7+Coefficienti!$B$8*E$22+Coefficienti!$B$9*$A23)+Coefficienti!$B$10)*(1-Parametri!$B$4))*(1+Parametri!$B$5)+FerrGriglia!E2+Coefficienti!$B$11*Parametri!$B$6,2) | F23: =ROUND((((Coefficienti!$B$1+Coefficienti!$B$2*F$22+Coefficienti!$B$3*$A23)*Parametri!$B$1+(Coefficienti!$B$4+Coefficienti!$B$5*F$22+Coefficienti!$B$6*$A23)*Parametri!$B$2)*(1-Parametri!$B$3)+((Coefficienti!$B$7+Coefficienti!$B$8*F$22+Coefficienti!$B$9*$A23)+Coefficienti!$B$10)*(1-Parametri!$B$4))*(1+Parametri!$B$5)+FerrGriglia!F2+Coefficienti!$B$11*Parametri!$B$6,2) | G23: =ROUND((((Coefficienti!$B$1+Coefficienti!$B$2*G$22+Coefficienti!$B$3*$A23)*Parametri!$B$1+(Coefficienti!$B$4+Coefficienti!$B$5*G$22+Coefficienti!$B$6*$A23)*Parametri!$B$2)*(1-Parametri!$B$3)+((Coefficienti!$B$7+Coefficienti!$B$8*G$22+Coefficienti!$B$9*$A23)+Coefficienti!$B$10)*(1-Parametri!$B$4))*(1+Parametri!$B$5)+FerrGriglia!G2+Coefficienti!$B$11*Parametri!$B$6,2) | H23: =ROUND((((Coefficienti!$B$1+Coefficienti!$B$2*H$22+Coefficienti!$B$3*$A23)*Parametri!$B$1+(Coefficienti!$B$4+Coefficienti!$B$5*H$22+Coefficienti!$B$6*$A23)*Parametri!$B$2)*(1-Parametri!$B$3)+((Coefficienti!$B$7+Coefficienti!$B$8*H$22+Coefficienti!$B$9*$A23)+Coefficienti!$B$10)*(1-Parametri!$B$4))*(1+Parametri!$B$5)+FerrGriglia!H2+Coefficienti!$B$11*Parametri!$B$6,2) | I23: =ROUND((((Coefficienti!$B$1+Coefficienti!$B$2*I$22+Coefficienti!$B$3*$A23)*Parametri!$B$1+(Coefficienti!$B$4+Coefficienti!$B$5*I$22+Coefficienti!$B$6*$A23)*Parametri!$B$2)*(1-Parametri!$B$3)+((Coefficienti!$B$7+Coefficienti!$B$8*I$22+Coefficienti!$B$9*$A23)+Coefficienti!$B$10)*(1-Parametri!$B$4))*(1+Parametri!$B$5)+FerrGriglia!I2+Coefficienti!$B$11*Parametri!$B$6,2) | ... N23: =ROUND((((Coefficienti!$B$1+Coefficienti!$B$2*N$22+Coefficienti!$B$3*$A23)*Parametri!$B$1+(Coefficienti!$B$4+Coefficienti!$B$5*N$22+Coefficienti!$B$6*$A23)*Parametri!$B$2)*(1-Parametri!$B$3)+((Coefficienti!$B$7+Coefficienti!$B$8*N$22+Coefficienti!$B$9*$A23)+Coefficienti!$B$10)*(1-Parametri!$B$4))*(1+Parametri!$B$5)+FerrGriglia!N2+Coefficienti!$B$11*Parametri!$B$6,2)
A24: 600 | B24: =ROUND((((Coefficienti!$B$1+Coefficienti!$B$2*B$22+Coefficienti!$B$3*$A24)*Parametri!$B$1+(Coefficienti!$B$4+Coefficienti!$B$5*B$22+Coefficienti!$B$6*$A24)*Parametri!$B$2)*(1-Parametri!$B$3)+((Coefficienti!$B$7+Coefficienti!$B$8*B$22+Coefficienti!$B$9*$A24)+Coefficienti!$B$10)*(1-Parametri!$B$4))*(1+Parametri!$B$5)+FerrGriglia!B3+Coefficienti!$B$11*Parametri!$B$6,2) | C24: =ROUND((((Coefficienti!$B$1+Coefficienti!$B$2*C$22+Coefficienti!$B$3*$A24)*Parametri!$B$1+(Coefficienti!$B$4+Coefficienti!$B$5*C$22+Coefficienti!$B$6*$A24)*Parametri!$B$2)*(1-Parametri!$B$3)+((Coefficienti!$B$7+Coefficienti!$B$8*C$22+Coefficienti!$B$9*$A24)+Coefficienti!$B$10)*(1-Parametri!$B$4))*(1+Parametri!$B$5)+FerrGriglia!C3+Coefficienti!$B$11*Parametri!$B$6,2) | D24: =ROUND((((Coefficienti!$B$1+Coefficienti!$B$2*D$22+Coefficienti!$B$3*$A24)*Parametri!$B$1+(Coefficienti!$B$4+Coefficienti!$B$5*D$22+Coefficienti!$B$6*$A24)*Parametri!$B$2)*(1-Parametri!$B$3)+((Coefficienti!$B$7+Coefficienti!$B$8*D$22+Coefficienti!$B$9*$A24)+Coefficienti!$B$10)*(1-Parametri!$B$4))*(1+Parametri!$B$5)+FerrGriglia!D3+Coefficienti!$B$11*Parametri!$B$6,2) | E24: =ROUND((((Coefficienti!$B$1+Coefficienti!$B$2*E$22+Coefficienti!$B$3*$A24)*Parametri!$B$1+(Coefficienti!$B$4+Coefficienti!$B$5*E$22+Coefficienti!$B$6*$A24)*Parametri!$B$2)*(1-Parametri!$B$3)+((Coefficienti!$B$7+Coefficienti!$B$8*E$22+Coefficienti!$B$9*$A24)+Coefficienti!$B$10)*(1-Parametri!$B$4))*(1+Parametri!$B$5)+FerrGriglia!E3+Coefficienti!$B$11*Parametri!$B$6,2) | F24: =ROUND((((Coefficienti!$B$1+Coefficienti!$B$2*F$22+Coefficienti!$B$3*$A24)*Parametri!$B$1+(Coefficienti!$B$4+Coefficienti!$B$5*F$22+Coefficienti!$B$6*$A24)*Parametri!$B$2)*(1-Parametri!$B$3)+((Coefficienti!$B$7+Coefficienti!$B$8*F$22+Coefficienti!$B$9*$A24)+Coefficienti!$B$10)*(1-Parametri!$B$4))*(1+Parametri!$B$5)+FerrGriglia!F3+Coefficienti!$B$11*Parametri!$B$6,2) | G24: =ROUND((((Coefficienti!$B$1+Coefficienti!$B$2*G$22+Coefficienti!$B$3*$A24)*Parametri!$B$1+(Coefficienti!$B$4+Coefficienti!$B$5*G$22+Coefficienti!$B$6*$A24)*Parametri!$B$2)*(1-Parametri!$B$3)+((Coefficienti!$B$7+Coefficienti!$B$8*G$22+Coefficienti!$B$9*$A24)+Coefficienti!$B$10)*(1-Parametri!$B$4))*(1+Parametri!$B$5)+FerrGriglia!G3+Coefficienti!$B$11*Parametri!$B$6,2) | H24: =ROUND((((Coefficienti!$B$1+Coefficienti!$B$2*H$22+Coefficienti!$B$3*$A24)*Parametri!$B$1+(Coefficienti!$B$4+Coefficienti!$B$5*H$22+Coefficienti!$B$6*$A24)*Parametri!$B$2)*(1-Parametri!$B$3)+((Coefficienti!$B$7+Coefficienti!$B$8*H$22+Coefficienti!$B$9*$A24)+Coefficienti!$B$10)*(1-Parametri!$B$4))*(1+Parametri!$B$5)+FerrGriglia!H3+Coefficienti!$B$11*Parametri!$B$6,2) | I24: =ROUND((((Coefficienti!$B$1+Coefficienti!$B$2*I$22+Coefficienti!$B$3*$A24)*Parametri!$B$1+(Coefficienti!$B$4+Coefficienti!$B$5*I$22+Coefficienti!$B$6*$A24)*Parametri!$B$2)*(1-Parametri!$B$3)+((Coefficienti!$B$7+Coefficienti!$B$8*I$22+Coefficienti!$B$9*$A24)+Coefficienti!$B$10)*(1-Parametri!$B$4))*(1+Parametri!$B$5)+FerrGriglia!I3+Coefficienti!$B$11*Parametri!$B$6,2) | ... N24: =ROUND((((Coefficienti!$B$1+Coefficienti!$B$2*N$22+Coefficienti!$B$3*$A24)*Parametri!$B$1+(Coefficienti!$B$4+Coefficienti!$B$5*N$22+Coefficienti!$B$6*$A24)*Parametri!$B$2)*(1-Parametri!$B$3)+((Coefficienti!$B$7+Coefficienti!$B$8*N$22+Coefficienti!$B$9*$A24)+Coefficienti!$B$10)*(1-Parametri!$B$4))*(1+Parametri!$B$5)+FerrGriglia!N3+Coefficienti!$B$11*Parametri!$B$6,2)
A25: 700 | B25: =ROUND((((Coefficienti!$B$1+Coefficienti!$B$2*B$22+Coefficienti!$B$3*$A25)*Parametri!$B$1+(Coefficienti!$B$4+Coefficienti!$B$5*B$22+Coefficienti!$B$6*$A25)*Parametri!$B$2)*(1-Parametri!$B$3)+((Coefficienti!$B$7+Coefficienti!$B$8*B$22+Coefficienti!$B$9*$A25)+Coefficienti!$B$10)*(1-Parametri!$B$4))*(1+Parametri!$B$5)+FerrGriglia!B4+Coefficienti!$B$11*Parametri!$B$6,2) | C25: =ROUND((((Coefficienti!$B$1+Coefficienti!$B$2*C$22+Coefficienti!$B$3*$A25)*Parametri!$B$1+(Coefficienti!$B$4+Coefficienti!$B$5*C$22+Coefficienti!$B$6*$A25)*Parametri!$B$2)*(1-Parametri!$B$3)+((Coefficienti!$B$7+Coefficienti!$B$8*C$22+Coefficienti!$B$9*$A25)+Coefficienti!$B$10)*(1-Parametri!$B$4))*(1+Parametri!$B$5)+FerrGriglia!C4+Coefficienti!$B$11*Parametri!$B$6,2) | D25: =ROUND((((Coefficienti!$B$1+Coefficienti!$B$2*D$22+Coefficienti!$B$3*$A25)*Parametri!$B$1+(Coefficienti!$B$4+Coefficienti!$B$5*D$22+Coefficienti!$B$6*$A25)*Parametri!$B$2)*(1-Parametri!$B$3)+((Coefficienti!$B$7+Coefficienti!$B$8*D$22+Coefficienti!$B$9*$A25)+Coefficienti!$B$10)*(1-Parametri!$B$4))*(1+Parametri!$B$5)+FerrGriglia!D4+Coefficienti!$B$11*Parametri!$B$6,2) | E25: =ROUND((((Coefficienti!$B$1+Coefficienti!$B$2*E$22+Coefficienti!$B$3*$A25)*Parametri!$B$1+(Coefficienti!$B$4+Coefficienti!$B$5*E$22+Coefficienti!$B$6*$A25)*Parametri!$B$2)*(1-Parametri!$B$3)+((Coefficienti!$B$7+Coefficienti!$B$8*E$22+Coefficienti!$B$9*$A25)+Coefficienti!$B$10)*(1-Parametri!$B$4))*(1+Parametri!$B$5)+FerrGriglia!E4+Coefficienti!$B$11*Parametri!$B$6,2) | F25: =ROUND((((Coefficienti!$B$1+Coefficienti!$B$2*F$22+Coefficienti!$B$3*$A25)*Parametri!$B$1+(Coefficienti!$B$4+Coefficienti!$B$5*F$22+Coefficienti!$B$6*$A25)*Parametri!$B$2)*(1-Parametri!$B$3)+((Coefficienti!$B$7+Coefficienti!$B$8*F$22+Coefficienti!$B$9*$A25)+Coefficienti!$B$10)*(1-Parametri!$B$4))*(1+Parametri!$B$5)+FerrGriglia!F4+Coefficienti!$B$11*Parametri!$B$6,2) | G25: =ROUND((((Coefficienti!$B$1+Coefficienti!$B$2*G$22+Coefficienti!$B$3*$A25)*Parametri!$B$1+(Coefficienti!$B$4+Coefficienti!$B$5*G$22+Coefficienti!$B$6*$A25)*Parametri!$B$2)*(1-Parametri!$B$3)+((Coefficienti!$B$7+Coefficienti!$B$8*G$22+Coefficienti!$B$9*$A25)+Coefficienti!$B$10)*(1-Parametri!$B$4))*(1+Parametri!$B$5)+FerrGriglia!G4+Coefficienti!$B$11*Parametri!$B$6,2) | H25: =ROUND((((Coefficienti!$B$1+Coefficienti!$B$2*H$22+Coefficienti!$B$3*$A25)*Parametri!$B$1+(Coefficienti!$B$4+Coefficienti!$B$5*H$22+Coefficienti!$B$6*$A25)*Parametri!$B$2)*(1-Parametri!$B$3)+((Coefficienti!$B$7+Coefficienti!$B$8*H$22+Coefficienti!$B$9*$A25)+Coefficienti!$B$10)*(1-Parametri!$B$4))*(1+Parametri!$B$5)+FerrGriglia!H4+Coefficienti!$B$11*Parametri!$B$6,2) | I25: =ROUND((((Coefficienti!$B$1+Coefficienti!$B$2*I$22+Coefficienti!$B$3*$A25)*Parametri!$B$1+(Coefficienti!$B$4+Coefficienti!$B$5*I$22+Coefficienti!$B$6*$A25)*Parametri!$B$2)*(1-Parametri!$B$3)+((Coefficienti!$B$7+Coefficienti!$B$8*I$22+Coefficienti!$B$9*$A25)+Coefficienti!$B$10)*(1-Parametri!$B$4))*(1+Parametri!$B$5)+FerrGriglia!I4+Coefficienti!$B$11*Parametri!$B$6,2) | ... N25: =ROUND((((Coefficienti!$B$1+Coefficienti!$B$2*N$22+Coefficienti!$B$3*$A25)*Parametri!$B$1+(Coefficienti!$B$4+Coefficienti!$B$5*N$22+Coefficienti!$B$6*$A25)*Parametri!$B$2)*(1-Parametri!$B$3)+((Coefficienti!$B$7+Coefficienti!$B$8*N$22+Coefficienti!$B$9*$A25)+Coefficienti!$B$10)*(1-Parametri!$B$4))*(1+Parametri!$B$5)+FerrGriglia!N4+Coefficienti!$B$11*Parametri!$B$6,2)
