Workbook

Sheet Prezzo
A1: LISTINO — PORTAFINESTRA 2 ANTE (PB275) — C75S SENZA VETRO — RAL 7016 (costo +213%)
A2: H/L | B2: 800 | C2: 900 | D2: 1000 | E2: 1100 | F2: 1200 | G2: 1300 | H2: 1400 | I2: 1500 | J2: 1600 | K2: 1700 | L2: 1800
A3: 1900 | B3: =ROUND(ROUND((((Coefficienti!$B$1+Coefficienti!$B$2*B$2+Coefficienti!$B$3*$A3)*Parametri!$B$1+(Coefficienti!$B$4+Coefficienti!$B$5*B$2+Coefficienti!$B$6*$A3)*Parametri!$B$2)*(1-Parametri!$B$3)+((Coefficienti!$B$7+Coefficienti!$B$8*B$2+Coefficienti!$B$9*$A3)+Coefficienti!$B$10)*(1-Parametri!$B$4))*(1+Parametri!$B$5)+FerrGriglia!B2+Coefficienti!$B$11*Parametri!$B$6,2)*(1+Parametri!$B$7),2) | C3: =ROUND(ROUND((((Coefficienti!$B$1+Coefficienti!$B$2*C$2+Coefficienti!$B$3*$A3)*Parametri!$B$1+(Coefficienti!$B$4+Coefficienti!$B$5*C$2+Coefficienti!$B$6*$A3)*Parametri!$B$2)*(1-Parametri!$B$3)+((Coefficienti!$B$7+Coefficienti!$B$8*C$2+Coefficienti!$B$9*$A3)+Coefficienti!$B$10)*(1-Parametri!$B$4))*(1+Parametri!$B$5)+FerrGriglia!C2+Coefficienti!$B$11*Parametri!$B$6,2)*(1+Parametri!$B$7),2) | D3: =ROUND(ROUND((((Coefficienti!$B$1+Coefficienti!$B$2*D$2+Coefficienti!$B$3*$A3)*Parametri!$B$1+(Coefficienti!$B$4+Coefficienti!$B$5*D$2+Coefficienti!$B$6*$A3)*Parametri!$B$2)*(1-Parametri!$B$3)+((Coefficienti!$B$7+Coefficienti!$B$8*D$2+Coefficienti!$B$9*$A3)+Coefficienti!$B$10)*(1-Parametri!$B$4))*(1+Parametri!$B$5)+FerrGriglia!D2+Coefficienti!$B$11*Parametri!$B$6,2)*(1+Parametri!$B$7),2) | E3: =ROUND(ROUND((((Coefficienti!$B$1+Coefficienti!$B$2*E$2+Coefficienti!$B$3*$A3)*Parametri!$B$1+(Coefficienti!$B$4+Coefficienti!$B$5*E$2+Coefficienti!$B$6*$A3)*Parametri!$B$2)*(1-Parametri!$B$3)+((Coefficienti!$B$7+Coefficienti!$B$8*E$2+Coefficienti!$B$9*$A3)+Coefficienti!$B$10)*(1-Parametri!$B$4))*(1+Parametri!$B$5)+FerrGriglia!E2+Coefficienti!$B$11*Parametri!$B$6,2)*(1+Parametri!$B$7),2) | F3: =ROUND(ROUND((((Coefficienti!$B$1+Coefficienti!$B$2*F$2+Coefficienti!$B$3*$A3)*Parametri!$B$1+(Coefficienti!$B$4+Coefficienti!$B$5*F$2+Coefficienti!$B$6*$A3)*Parametri!$B$2)*(1-Parametri!$B$3)+((Coefficienti!$B$7+Coefficienti!$B$8*F$2+Coefficienti!$B$9*$A3)+Coefficienti!$B$10)*(1-Parametri!$B$4))*(1+Parametri!$B$5)+FerrGriglia!F2+Coefficienti!$B$11*Parametri!$B$6,2)*(1+Parametri!$B$7),2) | G3: =ROUND(ROUND((((Coefficienti!$B$1+Coefficienti!$B$2*G$2+Coefficienti!$B$3*$A3)*Parametri!$B$1+(Coefficienti!$B$4+Coefficienti!$B$5*G$2+Coefficienti!$B$6*$A3)*Parametri!$B$2)*(1-Parametri!$B$3)+((Coefficienti!$B$7+Coefficienti!$B$8*G$2+Coefficienti!$B$9*$A3)+Coefficienti!$B$10)*(1-Parametri!$B$4))*(1+Parametri!$B$5)+FerrGriglia!G2+Coefficienti!$B$11*Parametri!$B$6,2)*(1+Parametri!$B$7),2) | H3: =ROUND(ROUND((((Coefficienti!$B$1+Coefficienti!$B$2*H$2+Coefficienti!$B$3*$A3)*Parametri!$B$1+(Coefficienti!$B$4+Coefficienti!$B$5*H$2+Coefficienti!$B$6*$A3)*Parametri!$B$2)*(1-Parametri!$B$3)+((Coefficienti!$B$7+Coefficienti!$B$8*H$2+Coefficienti!$B$9*$A3)+Coefficienti!$B$10)*(1-Parametri!$B$4))*(1+Parametri!$B$5)+FerrGriglia!H2+Coefficienti!$B$11*Parametri!$B$6,2)*(1+Parametri!$B$7),2) | I3: =ROUND(ROUND((((Coefficienti!$B$1+Coefficienti!$B$2*I$2+Coefficienti!$B$3*$A3)*Parametri!$B$1+(Coefficienti!$B$4+Coefficienti!$B$5*I$2+Coefficienti!$B$6*$A3)*Parametri!$B$2)*(1-Parametri!$B$3)+((Coefficienti!$B$7+Coefficienti!$B$8*I$2+Coefficienti!$B$9*$A3)+Coefficienti!$B$10)*(1-Parametri!$B$4))*(1+Parametri!$B$5)+FerrGriglia!I2+Coefficienti!$B$11*Parametri!$B$6,2)*(1+Parametri!$B$7),2) | ... L3: =ROUND(ROUND((((Coefficienti!$B$1+Coefficienti!$B$2*L$2+Coefficienti!$B$3*$A3)*Parametri!$B$1+(Coefficienti!$B$4+Coefficienti!$B$5*L$2+Coefficienti!$B$6*$A3)*Parametri!$B$2)*(1-Parametri!$B$3)+((Coefficienti!$B$7+Coefficienti!$B$8*L$2+Coefficienti!$B$9*$A3)+Coefficienti!$B$10)*(1-Parametri!$B$4))*(1+Parametri!$B$5)+FerrGriglia!L2+Coefficienti!$B$11*Parametri!$B$6,2)*(1+Parametri!$B$7),2)
A4: 2000 | B4: =ROUND(ROUND((((Coefficienti!$B$1+Coefficienti!$B$2*B$2+Coefficienti!$B$3*$A4)*Parametri!$B$1+(Coefficienti!$B$4+Coefficienti!$B$5*B$2+Coefficienti!$B$6*$A4)*Parametri!$B$2)*(1-Parametri!$B$3)+((Coefficienti!$B$7+Coefficienti!$B$8*B$2+Coefficienti!$B$9*$A4)+Coefficienti!$B$10)*(1-Parametri!$B$4))*(1+Parametri!$B$5)+FerrGriglia!B3+Coefficienti!$B$11*Parametri!$B$6,2)*(1+Parametri!$B$7),2) | C4: =ROUND(ROUND((((Coefficienti!$B$1+Coefficienti!$B$2*C$2+Coefficienti!$B$3*$A4)*Parametri!$B$1+(Coefficienti!$B$4+Coefficienti!$B$5*C$2+Coefficienti!$B$6*$A4)*Parametri!$B$2)*(1-Parametri!$B$3)+((Coefficienti!$B$7+Coefficienti!$B$8*C$2+Coefficienti!$B$9*$A4)+Coefficienti!$B$10)*(1-Parametri!$B$4))*(1+Parametri!$B$5)+FerrGriglia!C3+Coefficienti!$B$11*Parametri!$B$6,2)*(1+Parametri!$B$7),2) | D4: =ROUND(ROUND((((Coefficienti!$B$1+Coefficienti!$B$2*D$2+Coefficienti!$B$3*$A4)*Parametri!$B$1+(Coefficienti!$B$4+Coefficienti!$B$5*D$2+Coefficienti!$B$6*$A4)*Parametri!$B$2)*(1-Parametri!$B$3)+((Coefficienti!$B$7+Coefficienti!$B$8*D$2+Coefficienti!$B$9*$A4)+Coefficienti!$B$10)*(1-Parametri!$B$4))*(1+Parametri!$B$5)+FerrGriglia!D3+Coefficienti!$B$11*Parametri!$B$6,2)*(1+Parametri!$B$7),2) | E4: =ROUND(ROUND((((Coefficienti!$B$1+Coefficienti!$B$2*E$2+Coefficienti!$B$3*$A4)*Parametri!$B$1+(Coefficienti!$B$4+Coefficienti!$B$5*E$2+Coefficienti!$B$6*$A4)*Parametri!$B$2)*(1-Parametri!$B$3)+((Coefficienti!$B$7+Coefficienti!$B$8*E$2+Coefficienti!$B$9*$A4)+Coefficienti!$B$10)*(1-Parametri!$B$4))*(1+Parametri!$B$5)+FerrGriglia!E3+Coefficienti!$B$11*Parametri!$B$6,2)*(1+Parametri!$B$7),2) | F4: =ROUND(ROUND((((Coefficienti!$B$1+Coefficienti!$B$2*F$2+Coefficienti!$B$3*$A4)*Parametri!$B$1+(Coefficienti!$B$4+Coefficienti!$B$5*F$2+Coefficienti!$B$6*$A4)*Parametri!$B$2)*(1-Parametri!$B$3)+((Coefficienti!$B$7+Coefficienti!$B$8*F$2+Coefficienti!$B$9*$A4)+Coefficienti!$B$10)*(1-Parametri!$B$4))*(1+Parametri!$B$5)+FerrGriglia!F3+Coefficienti!$B$11*Parametri!$B$6,2)*(1+Parametri!$B$7),2) | G4: =ROUND(ROUND((((Coefficienti!$B$1+Coefficienti!$B$2*G$2+Coefficienti!$B$3*$A4)*Parametri!$B$1+(Coefficienti!$B$4+Coefficienti!$B$5*G$2+Coefficienti!$B$6*$A4)*Parametri!$B$2)*(1-Parametri!$B$3)+((Coefficienti!$B$7+Coefficienti!$B$8*G$2+Coefficienti!$B$9*$A4)+Coefficienti!$B$10)*(1-Parametri!$B$4))*(1+Parametri!$B$5)+FerrGriglia!G3+Coefficienti!$B$11*Parametri!$B$6,2)*(1+Parametri!$B$7),2) | H4: =ROUND(ROUND((((Coefficienti!$B$1+Coefficienti!$B$2*H$2+Coefficienti!$B$3*$A4)*Parametri!$B$1+(Coefficienti!$B$4+Coefficienti!$B$5*H$2+Coefficienti!$B$6*$A4)*Parametri!$B$2)*(1-Parametri!$B$3)+((Coefficienti!$B$7+Coefficienti!$B$8*H$2+Coefficienti!$B$9*$A4)+Coefficienti!$B$10)*(1-Parametri!$B$4))*(1+Parametri!$B$5)+FerrGriglia!H3+Coefficienti!$B$11*Parametri!$B$6,2)*(1+Parametri!$B$7),2) | I4: =ROUND(ROUND((((Coefficienti!$B$1+Coefficienti!$B$2*I$2+Coefficienti!$B$3*$A4)*Parametri!$B$1+(Coefficienti!$B$4+Coefficienti!$B$5*I$2+Coefficienti!$B$6*$A4)*Parametri!$B$2)*(1-Parametri!$B$3)+((Coefficienti!$B$7+Coefficienti!$B$8*I$2+Coefficienti!$B$9*$A4)+Coefficienti!$B$10)*(1-Parametri!$B$4))*(1+Parametri!$B$5)+FerrGriglia!I3+Coefficienti!$B$11*Parametri!$B$6,2)*(1+Parametri!$B$7),2) | ... L4: =ROUND(ROUND((((Coefficienti!$B$1+Coefficienti!$B$2*L$2+Coefficienti!$B$3*$A4)*Parametri!$B$1+(Coefficienti!$B$4+Coefficienti!$B$5*L$2+Coefficienti!$B$6*$A4)*Parametri!$B$2)*(1-Parametri!$B$3)+((Coefficienti!$B$7+Coefficienti!$B$8*L$2+Coefficienti!$B$9*$A4)+Coefficienti!$B$10)*(1-Parametri!$B$4))*(1+Parametri!$B$5)+FerrGriglia!L3+Coefficienti!$B$11*Parametri!$B$6,2)*(1+Parametri!$B$7),2)
A5: 2100 | B5: =ROUND(ROUND((((Coefficienti!$B$1+Coefficienti!$B$2*B$2+Coefficienti!$B$3*$A5)*Parametri!$B$1+(Coefficienti!$B$4+Coefficienti!$B$5*B$2+Coefficienti!$B$6*$A5)*Parametri!$B$2)*(1-Parametri!$B$3)+((Coefficienti!$B$7+Coefficienti!$B$8*B$2+Coefficienti!$B$9*$A5)+Coefficienti!$B$10)*(1-Parametri!$B$4))*(1+Parametri!$B$5)+FerrGriglia!B4+Coefficienti!$B$11*Parametri!$B$6,2)*(1+Parametri!$B$7),2) | C5: =ROUND(ROUND((((Coefficienti!$B$1+Coefficienti!$B$2*C$2+Coefficienti!$B$3*$A5)*Parametri!$B$1+(Coefficienti!$B$4+Coefficienti!$B$5*C$2+Coefficienti!$B$6*$A5)*Parametri!$B$2)*(1-Parametri!$B$3)+((Coefficienti!$B$7+Coefficienti!$B$8*C$2+Coefficienti!$B$9*$A5)+Coefficienti!$B$10)*(1-Parametri!$B$4))*(1+Parametri!$B$5)+FerrGriglia!C4+Coefficienti!$B$11*Parametri!$B$6,2)*(1+Parametri!$B$7),2) | D5: =ROUND(ROUND((((Coefficienti!$B$1+Coefficienti!$B$2*D$2+Coefficienti!$B$3*$A5)*Parametri!$B$1+(Coefficienti!$B$4+Coefficienti!$B$5*D$2+Coefficienti!$B$6*$A5)*Parametri!$B$2)*(1-Parametri!$B$3)+((Coefficienti!$B$7+Coefficienti!$B$8*D$2+Coefficienti!$B$9*$A5)+Coefficienti!$B$10)*(1-Parametri!$B$4))*(1+Parametri!$B$5)+FerrGriglia!D4+Coefficienti!$B$11*Parametri!$B$6,2)*(1+Parametri!$B$7),2) | E5: =ROUND(ROUND((((Coefficienti!$B$1+Coefficienti!$B$2*E$2+Coefficienti!$B$3*$A5)*Parametri!$B$1+(Coefficienti!$B$4+Coefficienti!$B$5*E$2+Coefficienti!$B$6*$A5)*Parametri!$B$2)*(1-Parametri!$B$3)+((Coefficienti!$B$7+Coefficienti!$B$8*E$2+Coefficienti!$B$9*$A5)+Coefficienti!$B$10)*(1-Parametri!$B$4))*(1+Parametri!$B$5)+FerrGriglia!E4+Coefficienti!$B$11*Parametri!$B$6,2)*(1+Parametri!$B$7),2) | F5: =ROUND(ROUND((((Coefficienti!$B$1+Coefficienti!$B$2*F$2+Coefficienti!$B$3*$A5)*Parametri!$B$1+(Coefficienti!$B$4+Coefficienti!$B$5*F$2+Coefficienti!$B$6*$A5)*Parametri!$B$2)*(1-Parametri!$B$3)+((Coefficienti!$B$7+Coefficienti!$B$8*F$2+Coefficienti!$B$9*$A5)+Coefficienti!$B$10)*(1-Parametri!$B$4))*(1+Parametri!$B$5)+FerrGriglia!F4+Coefficienti!$B$11*Parametri!$B$6,2)*(1+Parametri!$B$7),2) | G5: =ROUND(ROUND((((Coefficienti!$B$1+Coefficienti!$B$2*G$2+Coefficienti!$B$3*$A5)*Parametri!$B$1+(Coefficienti!$B$4+Coefficienti!$B$5*G$2+Coefficienti!$B$6*$A5)*Parametri!$B$2)*(1-Parametri!$B$3)+((Coefficienti!$B$7+Coefficienti!$B$8*G$2+Coefficienti!$B$9*$A5)+Coefficienti!$B$10)*(1-Parametri!$B$4))*(1+Parametri!$B$5)+FerrGriglia!G4+Coefficienti!$B$11*Parametri!$B$6,2)*(1+Parametri!$B$7),2) | H5: =ROUND(ROUND((((Coefficienti!$B$1+Coefficienti!$B$2*H$2+Coefficienti!$B$3*$A5)*Parametri!$B$1+(Coefficienti!$B$4+Coefficienti!$B$5*H$2+Coefficienti!$B$6*$A5)*Parametri!$B$2)*(1-Parametri!$B$3)+((Coefficienti!$B$7+Coefficienti!$B$8*H$2+Coefficienti!$B$9*$A5)+Coefficienti!$B$10)*(1-Parametri!$B$4))*(1+Parametri!$B$5)+FerrGriglia!H4+Coefficienti!$B$11*Parametri!$B$6,2)*(1+Parametri!$B$7),2) | I5: =ROUND(ROUND((((Coefficienti!$B$1+Coefficienti!$B$2*I$2+Coefficienti!$B$3*$A5)*Parametri!$B$1+(Coefficienti!$B$4+Coefficienti!$B$5*I$2+Coefficienti!$B$6*$A5)*Parametri!$B$2)*(1-Parametri!$B$3)+((Coefficienti!$B$7+Coefficienti!$B$8*I$2+Coefficienti!$B$9*$A5)+Coefficienti!$B$10)*(1-Parametri!$B$4))*(1+Parametri!$B$5)+FerrGriglia!I4+Coefficienti!$B$11*Parametri!$B$6,2)*(1+Parametri!$B$7),2) | ... L5: =ROUND(ROUND((((Coefficienti!$B$1+Coefficienti!$B$2*L$2+Coefficienti!$B$3*$A5)*Parametri!$B$1+(Coefficienti!$B$4+Coefficienti!$B$5*L$2+Coefficienti!$B$6*$A5)*Parametri!$B$2)*(1-Parametri!$B$3)+((Coefficienti!$B$7+Coefficienti!$B$8*L$2+Coefficienti!$B$9*$A5)+Coefficienti!$B$10)*(1-Parametri!$B$4))*(1+Parametri!$B$5)+FerrGriglia!L4+Coefficienti!$B$11*Parametri!$B$6,2)*(1+Parametri!$B$7),2)
A6: 2200 | B6: =ROUND(ROUND((((Coefficienti!$B$1+Coefficienti!$B$2*B$2+Coefficienti!$B$3*$A6)*Parametri!$B$1+(Coefficienti!$B$4+Coefficienti!$B$5*B$2+Coefficienti!$B$6*$A6)*Parametri!$B$2)*(1-Parametri!$B$3)+((Coefficienti!$B$7+Coefficienti!$B$8*B$2+Coefficienti!$B$9*$A6)+Coefficienti!$B$10)*(1-Parametri!$B$4))*(1+Parametri!$B$5)+FerrGriglia!B5+Coefficienti!$B$11*Parametri!$B$6,2)*(1+Parametri!$B$7),2) | C6: =ROUND(ROUND((((Coefficienti!$B$1+Coefficienti!$B$2*C$2+Coefficienti!$B$3*$A6)*Parametri!$B$1+(Coefficienti!$B$4+Coefficienti!$B$5*C$2+Coefficienti!$B$6*$A6)*Parametri!$B$2)*(1-Parametri!$B$3)+((Coefficienti!$B$7+Coefficienti!$B$8*C$2+Coefficienti!$B$9*$A6)+Coefficienti!$B$10)*(1-Parametri!$B$4))*(1+Parametri!$B$5)+FerrGriglia!C5+Coefficienti!$B$11*Parametri!$B$6,2)*(1+Parametri!$B$7),2) | D6: =ROUND(ROUND((((Coefficienti!$B$1+Coefficienti!$B$2*D$2+Coefficienti!$B$3*$A6)*Parametri!$B$1+(Coefficienti!$B$4+Coefficienti!$B$5*D$2+Coefficienti!$B$6*$A6)*Parametri!$B$2)*(1-Parametri!$B$3)+((Coefficienti!$B$7+Coefficienti!$B$8*D$2+Coefficienti!$B$9*$A6)+Coefficienti!$B$10)*(1-Parametri!$B$4))*(1+Parametri!$B$5)+FerrGriglia!D5+Coefficienti!$B$11*Parametri!$B$6,2)*(1+Parametri!$B$7),2) | E6: =ROUND(ROUND((((Coefficienti!$B$1+Coefficienti!$B$2*E$2+Coefficienti!$B$3*$A6)*Parametri!$B$1+(Coefficienti!$B$4+Coefficienti!$B$5*E$2+Coefficienti!$B$6*$A6)*Parametri!$B$2)*(1-Parametri!$B$3)+((Coefficienti!$B$7+Coefficienti!$B$8*E$2+Coefficienti!$B$9*$A6)+Coefficienti!$B$10)*(1-Parametri!$B$4))*(1+Parametri!$B$5)+FerrGriglia!E5+Coefficienti!$B$11*Parametri!$B$6,2)*(1+Parametri!$B$7),2) | F6: =ROUND(ROUND((((Coefficienti!$B$1+Coefficienti!$B$2*F$2+Coefficienti!$B$3*$A6)*Parametri!$B$1+(Coefficienti!$B$4+Coefficienti!$B$5*F$2+Coefficienti!$B$6*$A6)*Parametri!$B$2)*(1-Parametri!$B$3)+((Coefficienti!$B$7+Coefficienti!$B$8*F$2+Coefficienti!$B$9*$A6)+Coefficienti!$B$10)*(1-Parametri!$B$4))*(1+Parametri!$B$5)+FerrGriglia!F5+Coefficienti!$B$11*Parametri!$B$6,2)*(1+Parametri!$B$7),2) | G6: =ROUND(ROUND((((Coefficienti!$B$1+Coefficienti!$B$2*G$2+Coefficienti!$B$3*$A6)*Parametri!$B$1+(Coefficienti!$B$4+Coefficienti!$B$5*G$2+Coefficienti!$B$6*$A6)*Parametri!$B$2)*(1-Parametri!$B$3)+((Coefficienti!$B$7+Coefficienti!$B$8*G$2+Coefficienti!$B$9*$A6)+Coefficienti!$B$10)*(1-Parametri!$B$4))*(1+Parametri!$B$5)+FerrGriglia!G5+Coefficienti!$B$11*Parametri!$B$6,2)*(1+Parametri!$B$7),2) | H6: =ROUND(ROUND((((Coefficienti!$B$1+Coefficienti!$B$2*H$2+Coefficienti!$B$3*$A6)*Parametri!$B$1+(Coefficienti!$B$4+Coefficienti!$B$5*H$2+Coefficienti!$B$6*$A6)*Parametri!$B$2)*(1-Parametri!$B$3)+((Coefficienti!$B$7+Coefficienti!$B$8*H$2+Coefficienti!$B$9*$A6)+Coefficienti!$B$10)*(1-Parametri!$B$4))*(1+Parametri!$B$5)+FerrGriglia!H5+Coefficienti!$B$11*Parametri!$B$6,2)*(1+Parametri!$B$7),2) | I6: =ROUND(ROUND((((Coefficienti!$B$1+Coefficienti!$B$2*I$2+Coefficienti!$B$3*$A6)*Parametri!$B$1+(Coefficienti!$B$4+Coefficienti!$B$5*I$2+Coefficienti!$B$6*$A6)*Parametri!$B$2)*(1-Parametri!$B$3)+((Coefficienti!$B$7+Coefficienti!$B$8*I$2+Coefficienti!$B$9*$A6)+Coefficienti!$B$10)*(1-Parametri!$B$4))*(1+Parametri!$B$5)+FerrGriglia!I5+Coefficienti!$B$11*Parametri!$B$6,2)*(1+Parametri!$B$7),2) | ... L6: =ROUND(ROUND((((Coefficienti!$B$1+Coefficienti!$B$2*L$2+Coefficienti!$B$3*$A6)*Parametri!$B$1+(Coefficienti!$B$4+Coefficienti!$B$5*L$2+Coefficienti!$B$6*$A6)*Parametri!$B$2)*(1-Parametri!$B$3)+((Coefficienti!$B$7+Coefficienti!$B$8*L$2+Coefficienti!$B$9*$A6)+Coefficienti!$B$10)*(1-Parametri!$B$4))*(1+Parametri!$B$5)+FerrGriglia!L5+Coefficienti!$B$11*Parametri!$B$6,2)*(1+Parametri!$B$7),2)
A7: 2300 | B7: =ROUND(ROUND((((Coefficienti!$B$1+Coefficienti!$B$2*B$2+Coefficienti!$B$3*$A7)*Parametri!$B$1+(Coefficienti!$B$4+Coefficienti!$B$5*B$2+Coefficienti!$B$6*$A7)*Parametri!$B$2)*(1-Parametri!$B$3)+((Coefficienti!$B$7+Coefficienti!$B$8*B$2+Coefficienti!$B$9*$A7)+Coefficienti!$B$10)*(1-Parametri!$B$4))*(1+Parametri!$B$5)+FerrGriglia!B6+Coefficienti!$B$11*Parametri!$B$6,2)*(1+Parametri!$B$7),2) | C7: =ROUND(ROUND((((Coefficienti!$B$1+Coefficienti!$B$2*C$2+Coefficienti!$B$3*$A7)*Parametri!$B$1+(Coefficienti!$B$4+Coefficienti!$B$5*C$2+Coefficienti!$B$6*$A7)*Parametri!$B$2)*(1-Parametri!$B$3)+((Coefficienti!$B$7+Coefficienti!$B$8*C$2+Coefficienti!$B$9*$A7)+Coefficienti!$B$10)*(1-Parametri!$B$4))*(1+Parametri!$B$5)+FerrGriglia!C6+Coefficienti!$B$11*Parametri!$B$6,2)*(1+Parametri!$B$7),2) | D7: =ROUND(ROUND((((Coefficienti!$B$1+Coefficienti!$B$2*D$2+Coefficienti!$B$3*$A7)*Parametri!$B$1+(Coefficienti!$B$4+Coefficienti!$B$5*D$2+Coefficienti!$B$6*$A7)*Parametri!$B$2)*(1-Parametri!$B$3)+((Coefficienti!$B$7+Coefficienti!$B$8*D$2+Coefficienti!$B$9*$A7)+Coefficienti!$B$10)*(1-Parametri!$B$4))*(1+Parametri!$B$5)+FerrGriglia!D6+Coefficienti!$B$11*Parametri!$B$6,2)*(1+Parametri!$B$7),2) | E7: =ROUND(ROUND((((Coefficienti!$B$1+Coefficienti!$B$2*E$2+Coefficienti!$B$3*$A7)*Parametri!$B$1+(Coefficienti!$B$4+Coefficienti!$B$5*E$2+Coefficienti!$B$6*$A7)*Parametri!$B$2)*(1-Parametri!$B$3)+((Coefficienti!$B$7+Coefficienti!$B$8*E$2+Coefficienti!$B$9*$A7)+Coefficienti!$B$10)*(1-Parametri!$B$4))*(1+Parametri!$B$5)+FerrGriglia!E6+Coefficienti!$B$11*Parametri!$B$6,2)*(1+Parametri!$B$7),2) | F7: =ROUND(ROUND((((Coefficienti!$B$1+Coefficienti!$B$2*F$2+Coefficienti!$B$3*$A7)*Parametri!$B$1+(Coefficienti!$B$4+Coefficienti!$B$5*F$2+Coefficienti!$B$6*$A7)*Parametri!$B$2)*(1-Parametri!$B$3)+((Coefficienti!$B$7+Coefficienti!$B$8*F$2+Coefficienti!$B$9*$A7)+Coefficienti!$B$10)*(1-Parametri!$B$4))*(1+Parametri!$B$5)+FerrGriglia!F6+Coefficienti!$B$11*Parametri!$B$6,2)*(1+Parametri!$B$7),2) | G7: =ROUND(ROUND((((Coefficienti!$B$1+Coefficienti!$B$2*G$2+Coefficienti!$B$3*$A7)*Parametri!$B$1+(Coefficienti!$B$4+Coefficienti!$B$5*G$2+Coefficienti!$B$6*$A7)*Parametri!$B$2)*(1-Parametri!$B$3)+((Coefficienti!$B$7+Coefficienti!$B$8*G$2+Coefficienti!$B$9*$A7)+Coefficienti!$B$10)*(1-Parametri!$B$4))*(1+Parametri!$B$5)+FerrGriglia!G6+Coefficienti!$B$11*Parametri!$B$6,2)*(1+Parametri!$B$7),2) | H7: =ROUND(ROUND((((Coefficienti!$B$1+Coefficienti!$B$2*H$2+Coefficienti!$B$3*$A7)*Parametri!$B$1+(Coefficienti!$B$4+Coefficienti!$B$5*H$2+Coefficienti!$B$6*$A7)*Parametri!$B$2)*(1-Parametri!$B$3)+((Coefficienti!$B$7+Coefficienti!$B$8*H$2+Coefficienti!$B$9*$A7)+Coefficienti!$B$10)*(1-Parametri!$B$4))*(1+Parametri!$B$5)+FerrGriglia!H6+Coefficienti!$B$11*Parametri!$B$6,2)*(1+Parametri!$B$7),2) | I7: =ROUND(ROUND((((Coefficienti!$B$1+Coefficienti!$B$2*I$2+Coefficienti!$B$3*$A7)*Parametri!$B$1+(Coefficienti!$B$4+Coefficienti!$B$5*I$2+Coefficienti!$B$6*$A7)*Parametri!$B$2)*(1-Parametri!$B$3)+((Coefficienti!$B$7+Coefficienti!$B$8*I$2+Coefficienti!$B$9*$A7)+Coefficienti!$B$10)*(1-Parametri!$B$4))*(1+Parametri!$B$5)+FerrGriglia!I6+Coefficienti!$B$11*Parametri!$B$6,2)*(1+Parametri!$B$7),2) | ... L7: =ROUND(ROUND((((Coefficienti!$B$1+Coefficienti!$B$2*L$2+Coefficienti!$B$3*$A7)*Parametri!$B$1+(Coefficienti!$B$4+Coefficienti!$B$5*L$2+Coefficienti!$B$6*$A7)*Parametri!$B$2)*(1-Parametri!$B$3)+((Coefficienti!$B$7+Coefficienti!$B$8*L$2+Coefficienti!$B$9*$A7)+Coefficienti!$B$10)*(1-Parametri!$B$4))*(1+Parametri!$B$5)+FerrGriglia!L6+Coefficienti!$B$11*Parametri!$B$6,2)*(1+Parametri!$B$7),2)
A8: 2400 | B8: =ROUND(ROUND((((Coefficienti!$B$1+Coefficienti!$B$2*B$2+Coefficienti!$B$3*$A8)*Parametri!$B$1+(Coefficienti!$B$4+Coefficienti!$B$5*B$2+Coefficienti!$B$6*$A8)*Parametri!$B$2)*(1-Parametri!$B$3)+((Coefficienti!$B$7+Coefficienti!$B$8*B$2+Coefficienti!$B$9*$A8)+Coefficienti!$B$10)*(1-Parametri!$B$4))*(1+Parametri!$B$5)+FerrGriglia!B7+Coefficienti!$B$11*Parametri!$B$6,2)*(1+Parametri!$B$7),2) | C8: =ROUND(ROUND((((Coefficienti!$B$1+Coefficienti!$B$2*C$2+Coefficienti!$B$3*$A8)*Parametri!$B$1+(Coefficienti!$B$4+Coefficienti!$B$5*C$2+Coefficienti!$B$6*$A8)*Parametri!$B$2)*(1-Parametri!$B$3)+((Coefficienti!$B$7+Coefficienti!$B$8*C$2+Coefficienti!$B$9*$A8)+Coefficienti!$B$10)*(1-Parametri!$B$4))*(1+Parametri!$B$5)+FerrGriglia!C7+Coefficienti!$B$11*Parametri!$B$6,2)*(1+Parametri!$B$7),2) | D8: =ROUND(ROUND((((Coefficienti!$B$1+Coefficienti!$B$2*D$2+Coefficienti!$B$3*$A8)*Parametri!$B$1+(Coefficienti!$B$4+Coefficienti!$B$5*D$2+Coefficienti!$B$6*$A8)*Parametri!$B$2)*(1-Parametri!$B$3)+((Coefficienti!$B$7+Coefficienti!$B$8*D$2+Coefficienti!$B$9*$A8)+Coefficienti!$B$10)*(1-Parametri!$B$4))*(1+Parametri!$B$5)+FerrGriglia!D7+Coefficienti!$B$11*Parametri!$B$6,2)*(1+Parametri!$B$7),2) | E8: =ROUND(ROUND((((Coefficienti!$B$1+Coefficienti!$B$2*E$2+Coefficienti!$B$3*$A8)*Parametri!$B$1+(Coefficienti!$B$4+Coefficienti!$B$5*E$2+Coefficienti!$B$6*$A8)*Parametri!$B$2)*(1-Parametri!$B$3)+((Coefficienti!$B$7+Coefficienti!$B$8*E$2+Coefficienti!$B$9*$A8)+Coefficienti!$B$10)*(1-Parametri!$B$4))*(1+Parametri!$B$5)+FerrGriglia!E7+Coefficienti!$B$11*Parametri!$B$6,2)*(1+Parametri!$B$7),2) | F8: =ROUND(ROUND((((Coefficienti!$B$1+Coefficienti!$B$2*F$2+Coefficienti!$B$3*$A8)*Parametri!$B$1+(Coefficienti!$B$4+Coefficienti!$B$5*F$2+Coefficienti!$B$6*$A8)*Parametri!$B$2)*(1-Parametri!$B$3)+((Coefficienti!$B$7+Coefficienti!$B$8*F$2+Coefficienti!$B$9*$A8)+Coefficienti!$B$10)*(1-Parametri!$B$4))*(1+Parametri!$B$5)+FerrGriglia!F7+Coefficienti!$B$11*Parametri!$B$6,2)*(1+Parametri!$B$7),2) | G8: =ROUND(ROUND((((Coefficienti!$B$1+Coefficienti!$B$2*G$2+Coefficienti!$B$3*$A8)*Parametri!$B$1+(Coefficienti!$B$4+Coefficienti!$B$5*G$2+Coefficienti!$B$6*$A8)*Parametri!$B$2)*(1-Parametri!$B$3)+((Coefficienti!$B$7+Coefficienti!$B$8*G$2+Coefficienti!$B$9*$A8)+Coefficienti!$B$10)*(1-Parametri!$B$4))*(1+Parametri!$B$5)+FerrGriglia!G7+Coefficienti!$B$11*Parametri!$B$6,2)*(1+Parametri!$B$7),2) | H8: =ROUND(ROUND((((Coefficienti!$B$1+Coefficienti!$B$2*H$2+Coefficienti!$B$3*$A8)*Parametri!$B$1+(Coefficienti!$B$4+Coefficienti!$B$5*H$2+Coefficienti!$B$6*$A8)*Parametri!$B$2)*(1-Parametri!$B$3)+((Coefficienti!$B$7+Coefficienti!$B$8*H$2+Coefficienti!$B$9*$A8)+Coefficienti!$B$10)*(1-Parametri!$B$4))*(1+Parametri!$B$5)+FerrGriglia!H7+Coefficienti!$B$11*Parametri!$B$6,2)*(1+Parametri!$B$7),2) | I8: =ROUND(ROUND((((Coefficienti!$B$1+Coefficienti!$B$2*I$2+Coefficienti!$B$3*$A8)*Parametri!$B$1+(Coefficienti!$B$4+Coefficienti!$B$5*I$2+Coefficienti!$B$6*$A8)*Parametri!$B$2)*(1-Parametri!$B$3)+((Coefficienti!$B$7+Coefficienti!$B$8*I$2+Coefficienti!$B$9*$A8)+Coefficienti!$B$10)*(1-Parametri!$B$4))*(1+Parametri!$B$5)+FerrGriglia!I7+Coefficienti!$B$11*Parametri!$B$6,2)*(1+Parametri!$B$7),2) | ... L8: =ROUND(ROUND((((Coefficienti!$B$1+Coefficienti!$B$2*L$2+Coefficienti!$B$3*$A8)*Parametri!$B$1+(Coefficienti!$B$4+Coefficienti!$B$5*L$2+Coefficienti!$B$6*$A8)*Parametri!$B$2)*(1-Parametri!$B$3)+((Coefficienti!$B$7+Coefficienti!$B$8*L$2+Coefficienti!$B$9*$A8)+Coefficienti!$B$10)*(1-Parametri!$B$4))*(1+Parametri!$B$5)+FerrGriglia!L7+Coefficienti!$B$11*Parametri!$B$6,2)*(1+Parametri!$B$7),2)
A9: 2500 | B9: =ROUND(ROUND((((Coefficienti!$B$1+Coefficienti!$B$2*B$2+Coefficienti!$B$3*$A9)*Parametri!$B$1+(Coefficienti!$B$4+Coefficienti!$B$5*B$2+Coefficienti!$B$6*$A9)*Parametri!$B$2)*(1-Parametri!$B$3)+((Coefficienti!$B$7+Coefficienti!$B$8*B$2+Coefficienti!$B$9*$A9)+Coefficienti!$B$10)*(1-Parametri!$B$4))*(1+Parametri!$B$5)+FerrGriglia!B8+Coefficienti!$B$11*Parametri!$B$6,2)*(1+Parametri!$B$7),2) | C9: =ROUND(ROUND((((Coefficienti!$B$1+Coefficienti!$B$2*C$2+Coefficienti!$B$3*$A9)*Parametri!$B$1+(Coefficienti!$B$4+Coefficienti!$B$5*C$2+Coefficienti!$B$6*$A9)*Parametri!$B$2)*(1-Parametri!$B$3)+((Coefficienti!$B$7+Coefficienti!$B$8*C$2+Coefficienti!$B$9*$A9)+Coefficienti!$B$10)*(1-Parametri!$B$4))*(1+Parametri!$B$5)+FerrGriglia!C8+Coefficienti!$B$11*Parametri!$B$6,2)*(1+Parametri!$B$7),2) | D9: =ROUND(ROUND((((Coefficienti!$B$1+Coefficienti!$B$2*D$2+Coefficienti!$B$3*$A9)*Parametri!$B$1+(Coefficienti!$B$4+Coefficienti!$B$5*D$2+Coefficienti!$B$6*$A9)*Parametri!$B$2)*(1-Parametri!$B$3)+((Coefficienti!$B$7+Coefficienti!$B$8*D$2+Coefficienti!$B$9*$A9)+Coefficienti!$B$10)*(1-Parametri!$B$4))*(1+Parametri!$B$5)+FerrGriglia!D8+Coefficienti!$B$11*Parametri!$B$6,2)*(1+Parametri!$B$7),2) | E9: =ROUND(ROUND((((Coefficienti!$B$1+Coefficienti!$B$2*E$2+Coefficienti!$B$3*$A9)*Parametri!$B$1+(Coefficienti!$B$4+Coefficienti!$B$5*E$2+Coefficienti!$B$6*$A9)*Parametri!$B$2)*(1-Parametri!$B$3)+((Coefficienti!$B$7+Coefficienti!$B$8*E$2+Coefficienti!$B$9*$A9)+Coefficienti!$B$10)*(1-Parametri!$B$4))*(1+Parametri!$B$5)+FerrGriglia!E8+Coefficienti!$B$11*Parametri!$B$6,2)*(1+Parametri!$B$7),2) | F9: =ROUND(ROUND((((Coefficienti!$B$1+Coefficienti!$B$2*F$2+Coefficienti!$B$3*$A9)*Parametri!$B$1+(Coefficienti!$B$4+Coefficienti!$B$5*F$2+Coefficienti!$B$6*$A9)*Parametri!$B$2)*(1-Parametri!$B$3)+((Coefficienti!$B$7+Coefficienti!$B$8*F$2+Coefficienti!$B$9*$A9)+Coefficienti!$B$10)*(1-Parametri!$B$4))*(1+Parametri!$B$5)+FerrGriglia!F8+Coefficienti!$B$11*Parametri!$B$6,2)*(1+Parametri!$B$7),2) | G9: =ROUND(ROUND((((Coefficienti!$B$1+Coefficienti!$B$2*G$2+Coefficienti!$B$3*$A9)*Parametri!$B$1+(Coefficienti!$B$4+Coefficienti!$B$5*G$2+Coefficienti!$B$6*$A9)*Parametri!$B$2)*(1-Parametri!$B$3)+((Coefficienti!$B$7+Coefficienti!$B$8*G$2+Coefficienti!$B$9*$A9)+Coefficienti!$B$10)*(1-Parametri!$B$4))*(1+Parametri!$B$5)+FerrGriglia!G8+Coefficienti!$B$11*Parametri!$B$6,2)*(1+Parametri!$B$7),2) | H9: =ROUND(ROUND((((Coefficienti!$B$1+Coefficienti!$B$2*H$2+Coefficienti!$B$3*$A9)*Parametri!$B$1+(Coefficienti!$B$4+Coefficienti!$B$5*H$2+Coefficienti!$B$6*$A9)*Parametri!$B$2)*(1-Parametri!$B$3)+((Coefficienti!$B$7+Coefficienti!$B$8*H$2+Coefficienti!$B$9*$A9)+Coefficienti!$B$10)*(1-Parametri!$B$4))*(1+Parametri!$B$5)+FerrGriglia!H8+Coefficienti!$B$11*Parametri!$B$6,2)*(1+Parametri!$B$7),2) | I9: =ROUND(ROUND((((Coefficienti!$B$1+Coefficienti!$B$2*I$2+Coefficienti!$B$3*$A9)*Parametri!$B$1+(Coefficienti!$B$4+Coefficienti!$B$5*I$2+Coefficienti!$B$6*$A9)*Parametri!$B$2)*(1-Parametri!$B$3)+((Coefficienti!$B$7+Coefficienti!$B$8*I$2+Coefficienti!$B$9*$A9)+Coefficienti!$B$10)*(1-Parametri!$B$4))*(1+Parametri!$B$5)+FerrGriglia!I8+Coefficienti!$B$11*Parametri!$B$6,2)*(1+Parametri!$B$7),2) | ... L9: =ROUND(ROUND((((Coefficienti!$B$1+Coefficienti!$B$2*L$2+Coefficienti!$B$3*$A9)*Parametri!$B$1+(Coefficienti!$B$4+Coefficienti!$B$5*L$2+Coefficienti!$B$6*$A9)*Parametri!$B$2)*(1-Parametri!$B$3)+((Coefficienti!$B$7+Coefficienti!$B$8*L$2+Coefficienti!$B$9*$A9)+Coefficienti!$B$10)*(1-Parametri!$B$4))*(1+Parametri!$B$5)+FerrGriglia!L8+Coefficienti!$B$11*Parametri!$B$6,2)*(1+Parametri!$B$7),2)
A10: 2600 | B10: =ROUND(ROUND((((Coefficienti!$B$1+Coefficienti!$B$2*B$2+Coefficienti!$B$3*$A10)*Parametri!$B$1+(Coefficienti!$B$4+Coefficienti!$B$5*B$2+Coefficienti!$B$6*$A10)*Parametri!$B$2)*(1-Parametri!$B$3)+((Coefficienti!$B$7+Coefficienti!$B$8*B$2+Coefficienti!$B$9*$A10)+Coefficienti!$B$10)*(1-Parametri!$B$4))*(1+Parametri!$B$5)+FerrGriglia!B9+Coefficienti!$B$11*Parametri!$B$6,2)*(1+Parametri!$B$7),2) | C10: =ROUND(ROUND((((Coefficienti!$B$1+Coefficienti!$B$2*C$2+Coefficienti!$B$3*$A10)*Parametri!$B$1+(Coefficienti!$B$4+Coefficienti!$B$5*C$2+Coefficienti!$B$6*$A10)*Parametri!$B$2)*(1-Parametri!$B$3)+((Coefficienti!$B$7+Coefficienti!$B$8*C$2+Coefficienti!$B$9*$A10)+Coefficienti!$B$10)*(1-Parametri!$B$4))*(1+Parametri!$B$5)+FerrGriglia!C9+Coefficienti!$B$11*Parametri!$B$6,2)*(1+Parametri!$B$7),2) | D10: =ROUND(ROUND((((Coefficienti!$B$1+Coefficienti!$B$2*D$2+Coefficienti!$B$3*$A10)*Parametri!$B$1+(Coefficienti!$B$4+Coefficienti!$B$5*D$2+Coefficienti!$B$6*$A10)*Parametri!$B$2)*(1-Parametri!$B$3)+((Coefficienti!$B$7+Coefficienti!$B$8*D$2+Coefficienti!$B$9*$A10)+Coefficienti!$B$10)*(1-Parametri!$B$4))*(1+Parametri!$B$5)+FerrGriglia!D9+Coefficienti!$B$11*Parametri!$B$6,2)*(1+Parametri!$B$7),2) | E10: =ROUND(ROUND((((Coefficienti!$B$1+Coefficienti!$B$2*E$2+Coefficienti!$B$3*$A10)*Parametri!$B$1+(Coefficienti!$B$4+Coefficienti!$B$5*E$2+Coefficienti!$B$6*$A10)*Parametri!$B$2)*(1-Parametri!$B$3)+((Coefficienti!$B$7+Coefficienti!$B$8*E$2+Coefficienti!$B$9*$A10)+Coefficienti!$B$10)*(1-Parametri!$B$4))*(1+Parametri!$B$5)+FerrGriglia!E9+Coefficienti!$B$11*Parametri!$B$6,2)*(1+Parametri!$B$7),2) | F10: =ROUND(ROUND((((Coefficienti!$B$1+Coefficienti!$B$2*F$2+Coefficienti!$B$3*$A10)*Parametri!$B$1+(Coefficienti!$B$4+Coefficienti!$B$5*F$2+Coefficienti!$B$6*$A10)*Parametri!$B$2)*(1-Parametri!$B$3)+((Coefficienti!$B$7+Coefficienti!$B$8*F$2+Coefficienti!$B$9*$A10)+Coefficienti!$B$10)*(1-Parametri!$B$4))*(1+Parametri!$B$5)+FerrGriglia!F9+Coefficienti!$B$11*Parametri!$B$6,2)*(1+Parametri!$B$7),2) | G10: =ROUND(ROUND((((Coefficienti!$B$1+Coefficienti!$B$2*G$2+Coefficienti!$B$3*$A10)*Parametri!$B$1+(Coefficienti!$B$4+Coefficienti!$B$5*G$2+Coefficienti!$B$6*$A10)*Parametri!$B$2)*(1-Parametri!$B$3)+((Coefficienti!$B$7+Coefficienti!$B$8*G$2+Coefficienti!$B$9*$A10)+Coefficienti!$B$10)*(1-Parametri!$B$4))*(1+Parametri!$B$5)+FerrGriglia!G9+Coefficienti!$B$11*Parametri!$B$6,2)*(1+Parametri!$B$7),2) | H10: =ROUND(ROUND((((Coefficienti!$B$1+Coefficienti!$B$2*H$2+Coefficienti!$B$3*$A10)*Parametri!$B$1+(Coefficienti!$B$4+Coefficienti!$B$5*H$2+Coefficienti!$B$6*$A10)*Parametri!$B$2)*(1-Parametri!$B$3)+((Coefficienti!$B$7+Coefficienti!$B$8*H$2+Coefficienti!$B$9*$A10)+Coefficienti!$B$10)*(1-Parametri!$B$4))*(1+Parametri!$B$5)+FerrGriglia!H9+Coefficienti!$B$11*Parametri!$B$6,2)*(1+Parametri!$B$7),2) | I10: =ROUND(ROUND((((Coefficienti!$B$1+Coefficienti!$B$2*I$2+Coefficienti!$B$3*$A10)*Parametri!$B$1+(Coefficienti!$B$4+Coefficienti!$B$5*I$2+Coefficienti!$B$6*$A10)*Parametri!$B$2)*(1-Parametri!$B$3)+((Coefficienti!$B$7+Coefficienti!$B$8*I$2+Coefficienti!$B$9*$A10)+Coefficienti!$B$10)*(1-Parametri!$B$4))*(1+Parametri!$B$5)+FerrGriglia!I9+Coefficienti!$B$11*Parametri!$B$6,2)*(1+Parametri!$B$7),2) | ... L10: =ROUND(ROUND((((Coefficienti!$B$1+Coefficienti!$B$2*L$2+Coefficienti!$B$3*$A10)*Parametri!$B$1+(Coefficienti!$B$4+Coefficienti!$B$5*L$2+Coefficienti!$B$6*$A10)*Parametri!$B$2)*(1-Parametri!$B$3)+((Coefficienti!$B$7+Coefficienti!$B$8*L$2+Coefficienti!$B$9*$A10)+Coefficienti!$B$10)*(1-Parametri!$B$4))*(1+Parametri!$B$5)+FerrGriglia!L9+Coefficienti!$B$11*Parametri!$B$6,2)*(1+Parametri!$B$7),2)
A11: 2700 | B11: =ROUND(ROUND((((Coefficienti!$B$1+Coefficienti!$B$2*B$2+Coefficienti!$B$3*$A11)*Parametri!$B$1+(Coefficienti!$B$4+Coefficienti!$B$5*B$2+Coefficienti!$B$6*$A11)*Parametri!$B$2)*(1-Parametri!$B$3)+((Coefficienti!$B$7+Coefficienti!$B$8*B$2+Coefficienti!$B$9*$A11)+Coefficienti!$B$10)*(1-Parametri!$B$4))*(1+Parametri!$B$5)+FerrGriglia!B10+Coefficienti!$B$11*Parametri!$B$6,2)*(1+Parametri!$B$7),2) | C11: =ROUND(ROUND((((Coefficienti!$B$1+Coefficienti!$B$2*C$2+Coefficienti!$B$3*$A11)*Parametri!$B$1+(Coefficienti!$B$4+Coefficienti!$B$5*C$2+Coefficienti!$B$6*$A11)*Parametri!$B$2)*(1-Parametri!$B$3)+((Coefficienti!$B$7+Coefficienti!$B$8*C$2+Coefficienti!$B$9*$A11)+Coefficienti!$B$10)*(1-Parametri!$B$4))*(1+Parametri!$B$5)+FerrGriglia!C10+Coefficienti!$B$11*Parametri!$B$6,2)*(1+Parametri!$B$7),2) | D11: =ROUND(ROUND((((Coefficienti!$B$1+Coefficienti!$B$2*D$2+Coefficienti!$B$3*$A11)*Parametri!$B$1+(Coefficienti!$B$4+Coefficienti!$B$5*D$2+Coefficienti!$B$6*$A11)*Parametri!$B$2)*(1-Parametri!$B$3)+((Coefficienti!$B$7+Coefficienti!$B$8*D$2+Coefficienti!$B$9*$A11)+Coefficienti!$B$10)*(1-Parametri!$B$4))*(1+Parametri!$B$5)+FerrGriglia!D10+Coefficienti!$B$11*Parametri!$B$6,2)*(1+Parametri!$B$7),2) | E11: =ROUND(ROUND((((Coefficienti!$B$1+Coefficienti!$B$2*E$2+Coefficienti!$B$3*$A11)*Parametri!$B$1+(Coefficienti!$B$4+Coefficienti!$B$5*E$2+Coefficienti!$B$6*$A11)*Parametri!$B$2)*(1-Parametri!$B$3)+((Coefficienti!$B$7+Coefficienti!$B$8*E$2+Coefficienti!$B$9*$A11)+Coefficienti!$B$10)*(1-Parametri!$B$4))*(1+Parametri!$B$5)+FerrGriglia!E10+Coefficienti!$B$11*Parametri!$B$6,2)*(1+Parametri!$B$7),2) | F11: =ROUND(ROUND((((Coefficienti!$B$1+Coefficienti!$B$2*F$2+Coefficienti!$B$3*$A11)*Parametri!$B$1+(Coefficienti!$B$4+Coefficienti!$B$5*F$2+Coefficienti!$B$6*$A11)*Parametri!$B$2)*(1-Parametri!$B$3)+((Coefficienti!$B$7+Coefficienti!$B$8*F$2+Coefficienti!$B$9*$A11)+Coefficienti!$B$10)*(1-Parametri!$B$4))*(1+Parametri!$B$5)+FerrGriglia!F10+Coefficienti!$B$11*Parametri!$B$6,2)*(1+Parametri!$B$7),2) | G11: =ROUND(ROUND((((Coefficienti!$B$1+Coefficienti!$B$2*G$2+Coefficienti!$B$3*$A11)*Parametri!$B$1+(Coefficienti!$B$4+Coefficienti!$B$5*G$2+Coefficienti!$B$6*$A11)*Parametri!$B$2)*(1-Parametri!$B$3)+((Coefficienti!$B$7+Coefficienti!$B$8*G$2+Coefficienti!$B$9*$A11)+Coefficienti!$B$10)*(1-Parametri!$B$4))*(1+Parametri!$B$5)+FerrGriglia!G10+Coefficienti!$B$11*Parametri!$B$6,2)*(1+Parametri!$B$7),2) | H11: =ROUND(ROUND((((Coefficienti!$B$1+Coefficienti!$B$2*H$2+Coefficienti!$B$3*$A11)*Parametri!$B$1+(Coefficienti!$B$4+Coefficienti!$B$5*H$2+Coefficienti!$B$6*$A11)*Parametri!$B$2)*(1-Parametri!$B$3)+((Coefficienti!$B$7+Coefficienti!$B$8*H$2+Coefficienti!$B$9*$A11)+Coefficienti!$B$10)*(1-Parametri!$B$4))*(1+Parametri!$B$5)+FerrGriglia!H10+Coefficienti!$B$11*Parametri!$B$6,2)*(1+Parametri!$B$7),2) | I11: =ROUND(ROUND((((Coefficienti!$B$1+Coefficienti!$B$2*I$2+Coefficienti!$B$3*$A11)*Parametri!$B$1+(Coefficienti!$B$4+Coefficienti!$B$5*I$2+Coefficienti!$B$6*$A11)*Parametri!$B$2)*(1-Parametri!$B$3)+((Coefficienti!$B$7+Coefficienti!$B$8*I$2+Coefficienti!$B$9*$A11)+Coefficienti!$B$10)*(1-Parametri!$B$4))*(1+Parametri!$B$5)+FerrGriglia!I10+Coefficienti!$B$11*Parametri!$B$6,2)*(1+Parametri!$B$7),2) | ... L11: =ROUND(ROUND((((Coefficienti!$B$1+Coefficienti!$B$2*L$2+Coefficienti!$B$3*$A11)*Parametri!$B$1+(Coefficienti!$B$4+Coefficienti!$B$5*L$2+Coefficienti!$B$6*$A11)*Parametri!$B$2)*(1-Parametri!$B$3)+((Coefficienti!$B$7+Coefficienti!$B$8*L$2+Coefficienti!$B$9*$A11)+Coefficienti!$B$10)*(1-Parametri!$B$4))*(1+Parametri!$B$5)+FerrGriglia!L10+Coefficienti!$B$11*Parametri!$B$6,2)*(1+Parametri!$B$7),2)
A14: COSTO SERRAMENTO (materiale scontato + sfrido + manodopera)
A15: H/L | B15: 800 | C15: 900 | D15: 1000 | E15: 1100 | F15: 1200 | G15: 1300 | H15: 1400 | I15: 1500 | J15: 1600 | K15: 1700 | L15: 1800
A16: 1900 | B16: =ROUND((((Coefficienti!$B$1+Coefficienti!$B$2*B$15+Coefficienti!$B$3*$A16)*Parametri!$B$1+(Coefficienti!$B$4+Coefficienti!$B$5*B$15+Coefficienti!$B$6*$A16)*Parametri!$B$2)*(1-Parametri!$B$3)+((Coefficienti!$B$7+Coefficienti!$B$8*B$15+Coefficienti!$B$9*$A16)+Coefficienti!$B$10)*(1-Parametri!$B$4))*(1+Parametri!$B$5)+FerrGriglia!B2+Coefficienti!$B$11*Parametri!$B$6,2) | C16: =ROUND((((Coefficienti!$B$1+Coefficienti!$B$2*C$15+Coefficienti!$B$3*$A16)*Parametri!$B$1+(Coefficienti!$B$4+Coefficienti!$B$5*C$15+Coefficienti!$B$6*$A16)*Parametri!$B$2)*(1-Parametri!$B$3)+((Coefficienti!$B$7+Coefficienti!$B$8*C$15+Coefficienti!$B$9*$A16)+Coefficienti!$B$10)*(1-Parametri!$B$4))*(1+Parametri!$B$5)+FerrGriglia!C2+Coefficienti!$B$11*Parametri!$B$6,2) | D16: =ROUND((((Coefficienti!$B$1+Coefficienti!$B$2*D$15+Coefficienti!$B$3*$A16)*Parametri!$B$1+(Coefficienti!$B$4+Coefficienti!$B$5*D$15+Coefficienti!$B$6*$A16)*Parametri!$B$2)*(1-Parametri!$B$3)+((Coefficienti!$B$7+Coefficienti!$B$8*D$15+Coefficienti!$B$9*$A16)+Coefficienti!$B$10)*(1-Parametri!$B$4))*(1+Parametri!$B$5)+FerrGriglia!D2+Coefficienti!$B$11*Parametri!$B$6,2) | E16: =ROUND((((Coefficienti!$B$1+Coefficienti!$B$2*E$15+Coefficienti!$B$3*$A16)*Parametri!$B$1+(Coefficienti!$B$4+Coefficienti!$B$5*E$15+Coefficienti!$B$6*$A16)*Parametri!$B$2)*(1-Parametri!$B$3)+((Coefficienti!$B$7+Coefficienti!$B$8*E$15+Coefficienti!$B$9*$A16)+Coefficienti!$B$10)*(1-Parametri!$B$4))*(1+Parametri!$B$5)+FerrGriglia!E2+Coefficienti!$B$11*Parametri!$B$6,2) | F16: =ROUND((((Coefficienti!$B$1+Coefficienti!$B$2*F$15+Coefficienti!$B$3*$A16)*Parametri!$B$1+(Coefficienti!$B$4+Coefficienti!$B$5*F$15+Coefficienti!$B$6*$A16)*Parametri!$B$2)*(1-Parametri!$B$3)+((Coefficienti!$B$7+Coefficienti!$B$8*F$15+Coefficienti!$B$9*$A16)+Coefficienti!$B$10)*(1-Parametri!$B$4))*(1+Parametri!$B$5)+FerrGriglia!F2+Coefficienti!$B$11*Parametri!$B$6,2) | G16: =ROUND((((Coefficienti!$B$1+Coefficienti!$B$2*G$15+Coefficienti!$B$3*$A16)*Parametri!$B$1+(Coefficienti!$B$4+Coefficienti!$B$5*G$15+Coefficienti!$B$6*$A16)*Parametri!$B$2)*(1-Parametri!$B$3)+((Coefficienti!$B$7+Coefficienti!$B$8*G$15+Coefficienti!$B$9*$A16)+Coefficienti!$B$10)*(1-Parametri!$B$4))*(1+Parametri!$B$5)+FerrGriglia!G2+Coefficienti!$B$11*Parametri!$B$6,2) | H16: =ROUND((((Coefficienti!$B$1+Coefficienti!$B$2*H$15+Coefficienti!$B$3*$A16)*Parametri!$B$1+(Coefficienti!$B$4+Coefficienti!$B$5*H$15+Coefficienti!$B$6*$A16)*Parametri!$B$2)*(1-Parametri!$B$3)+((Coefficienti!$B$7+Coefficienti!$B$8*H$15+Coefficienti!$B$9*$A16)+Coefficienti!$B$10)*(1-Parametri!$B$4))*(1+Parametri!$B$5)+FerrGriglia!H2+Coefficienti!$B$11*Parametri!$B$6,2) | I16: =ROUND((((Coefficienti!$B$1+Coefficienti!$B$2*I$15+Coefficienti!$B$3*$A16)*Parametri!$B$1+(Coefficienti!$B$4+Coefficienti!$B$5*I$15+Coefficienti!$B$6*$A16)*Parametri!$B$2)*(1-Parametri!$B$3)+((Coefficienti!$B$7+Coefficienti!$B$8*I$15+Coefficienti!$B$9*$A16)+Coefficienti!$B$10)*(1-Parametri!$B$4))*(1+Parametri!$B$5)+FerrGriglia!I2+Coefficienti!$B$11*Parametri!$B$6,2) | ... L16: =ROUND((((Coefficienti!$B$1+Coefficienti!$B$2*L$15+Coefficienti!$B$3*$A16)*Parametri!$B$1+(Coefficienti!$B$4+Coefficienti!$B$5*L$15+Coefficienti!$B$6*$A16)*Parametri!$B$2)*(1-Parametri!$B$3)+((Coefficienti!$B$7+Coefficienti!$B$8*L$15+Coefficienti!$B$9*$A16)+Coefficienti!$B$10)*(1-Parametri!$B$4))*(1+Parametri!$B$5)+FerrGriglia!L2+Coefficienti!$B$11*Parametri!$B$6,2)
A17: 2000 | B17: =ROUND((((Coefficienti!$B$1+Coefficienti!$B$2*B$15+Coefficienti!$B$3*$A17)*Parametri!$B$1+(Coefficienti!$B$4+Coefficienti!$B$5*B$15+Coefficienti!$B$6*$A17)*Parametri!$B$2)*(1-Parametri!$B$3)+((Coefficienti!$B$7+Coefficienti!$B$8*B$15+Coefficienti!$B$9*$A17)+Coefficienti!$B$10)*(1-Parametri!$B$4))*(1+Parametri!$B$5)+FerrGriglia!B3+Coefficienti!$B$11*Parametri!$B$6,2) | C17: =ROUND((((Coefficienti!$B$1+Coefficienti!$B$2*C$15+Coefficienti!$B$3*$A17)*Parametri!$B$1+(Coefficienti!$B$4+Coefficienti!$B$5*C$15+Coefficienti!$B$6*$A17)*Parametri!$B$2)*(1-Parametri!$B$3)+((Coefficienti!$B$7+Coefficienti!$B$8*C$15+Coefficienti!$B$9*$A17)+Coefficienti!$B$10)*(1-Parametri!$B$4))*(1+Parametri!$B$5)+FerrGriglia!C3+Coefficienti!$B$11*Parametri!$B$6,2) | D17: =ROUND((((Coefficienti!$B$1+Coefficienti!$B$2*D$15+Coefficienti!$B$3*$A17)*Parametri!$B$1+(Coefficienti!$B$4+Coefficienti!$B$5*D$15+Coefficienti!$B$6*$A17)*Parametri!$B$2)*(1-Parametri!$B$3)+((Coefficienti!$B$7+Coefficienti!$B$8*D$15+Coefficienti!$B$9*$A17)+Coefficienti!$B$10)*(1-Parametri!$B$4))*(1+Parametri!$B$5)+FerrGriglia!D3+Coefficienti!$B$11*Parametri!$B$6,2) | E17: =ROUND((((Coefficienti!$B$1+Coefficienti!$B$2*E$15+Coefficienti!$B$3*$A17)*Parametri!$B$1+(Coefficienti!$B$4+Coefficienti!$B$5*E$15+Coefficienti!$B$6*$A17)*Parametri!$B$2)*(1-Parametri!$B$3)+((Coefficienti!$B$7+Coefficienti!$B$8*E$15+Coefficienti!$B$9*$A17)+Coefficienti!$B$10)*(1-Parametri!$B$4))*(1+Parametri!$B$5)+FerrGriglia!E3+Coefficienti!$B$11*Parametri!$B$6,2) | F17: =ROUND((((Coefficienti!$B$1+Coefficienti!$B$2*F$15+Coefficienti!$B$3*$A17)*Parametri!$B$1+(Coefficienti!$B$4+Coefficienti!$B$5*F$15+Coefficienti!$B$6*$A17)*Parametri!$B$2)*(1-Parametri!$B$3)+((Coefficienti!$B$7+Coefficienti!$B$8*F$15+Coefficienti!$B$9*$A17)+Coefficienti!$B$10)*(1-Parametri!$B$4))*(1+Parametri!$B$5)+FerrGriglia!F3+Coefficienti!$B$11*Parametri!$B$6,2) | G17: =ROUND((((Coefficienti!$B$1+Coefficienti!$B$2*G$15+Coefficienti!$B$3*$A17)*Parametri!$B$1+(Coefficienti!$B$4+Coefficienti!$B$5*G$15+Coefficienti!$B$6*$A17)*Parametri!$B$2)*(1-Parametri!$B$3)+((Coefficienti!$B$7+Coefficienti!$B$8*G$15+Coefficienti!$B$9*$A17)+Coefficienti!$B$10)*(1-Parametri!$B$4))*(1+Parametri!$B$5)+FerrGriglia!G3+Coefficienti!$B$11*Parametri!$B$6,2) | H17: =ROUND((((Coefficienti!$B$1+Coefficienti!$B$2*H$15+Coefficienti!$B$3*$A17)*Parametri!$B$1+(Coefficienti!$B$4+Coefficienti!$B$5*H$15+Coefficienti!$B$6*$A17)*Parametri!$B$2)*(1-Parametri!$B$3)+((Coefficienti!$B$7+Coefficienti!$B$8*H$15+Coefficienti!$B$9*$A17)+Coefficienti!$B$10)*(1-Parametri!$B$4))*(1+Parametri!$B$5)+FerrGriglia!H3+Coefficienti!$B$11*Parametri!$B$6,2) | I17: =ROUND((((Coefficienti!$B$1+Coefficienti!$B$2*I$15+Coefficienti!$B$3*$A17)*Parametri!$B$1+(Coefficienti!$B$4+Coefficienti!$B$5*I$15+Coefficienti!$B$6*$A17)*Parametri!$B$2)*(1-Parametri!$B$3)+((Coefficienti!$B$7+Coefficienti!$B$8*I$15+Coefficienti!$B$9*$A17)+Coefficienti!$B$10)*(1-Parametri!$B$4))*(1+Parametri!$B$5)+FerrGriglia!I3+Coefficienti!$B$11*Parametri!$B$6,2) | ... L17: =ROUND((((Coefficienti!$B$1+Coefficienti!$B$2*L$15+Coefficienti!$B$3*$A17)*Parametri!$B$1+(Coefficienti!$B$4+Coefficienti!$B$5*L$15+Coefficienti!$B$6*$A17)*Parametri!$B$2)*(1-Parametri!$B$3)+((Coefficienti!$B$7+Coefficienti!$B$8*L$15+Coefficienti!$B$9*$A17)+Coefficienti!$B$10)*(1-Parametri!$B$4))*(1+Parametri!$B$5)+FerrGriglia!L3+Coefficienti!$B$11*Parametri!$B$6,2)
A18: 2100 | B18: =ROUND((((Coefficienti!$B$1+Coefficienti!$B$2*B$15+Coefficienti!$B$3*$A18)*Parametri!$B$1+(Coefficienti!$B$4+Coefficienti!$B$5*B$15+Coefficienti!$B$6*$A18)*Parametri!$B$2)*(1-Parametri!$B$3)+((Coefficienti!$B$7+Coefficienti!$B$8*B$15+Coefficienti!$B$9*$A18)+Coefficienti!$B$10)*(1-Parametri!$B$4))*(1+Parametri!$B$5)+FerrGriglia!B4+Coefficienti!$B$11*Parametri!$B$6,2) | C18: =ROUND((((Coefficienti!$B$1+Coefficienti!$B$2*C$15+Coefficienti!$B$3*$A18)*Parametri!$B$1+(Coefficienti!$B$4+Coefficienti!$B$5*C$15+Coefficienti!$B$6*$A18)*Parametri!$B$2)*(1-Parametri!$B$3)+((Coefficienti!$B$7+Coefficienti!$B$8*C$15+Coefficienti!$B$9*$A18)+Coefficienti!$B$10)*(1-Parametri!$B$4))*(1+Parametri!$B$5)+FerrGriglia!C4+Coefficienti!$B$11*Parametri!$B$6,2) | D18: =ROUND((((Coefficienti!$B$1+Coefficienti!$B$2*D$15+Coefficienti!$B$3*$A18)*Parametri!$B$1+(Coefficienti!$B$4+Coefficienti!$B$5*D$15+Coefficienti!$B$6*$A18)*Parametri!$B$2)*(1-Parametri!$B$3)+((Coefficienti!$B$7+Coefficienti!$B$8*D$15+Coefficienti!$B$9*$A18)+Coefficienti!$B$10)*(1-Parametri!$B$4))*(1+Parametri!$B$5)+FerrGriglia!D4+Coefficienti!$B$11*Parametri!$B$6,2) | E18: =ROUND((((Coefficienti!$B$1+Coefficienti!$B$2*E$15+Coefficienti!$B$3*$A18)*Parametri!$B$1+(Coefficienti!$B$4+Coefficienti!$B$5*E$15+Coefficienti!$B$6*$A18)*Parametri!$B$2)*(1-Parametri!$B$3)+((Coefficienti!$B$7+Coefficienti!$B$8*E$15+Coefficienti!$B$9*$A18)+Coefficienti!$B$10)*(1-Parametri!$B$4))*(1+Parametri!$B$5)+FerrGriglia!E4+Coefficienti!$B$11*Parametri!$B$6,2) | F18: =ROUND((((Coefficienti!$B$1+Coefficienti!$B$2*F$15+Coefficienti!$B$3*$A18)*Parametri!$B$1+(Coefficienti!$B$4+Coefficienti!$B$5*F$15+Coefficienti!$B$6*$A18)*Parametri!$B$2)*(1-Parametri!$B$3)+((Coefficienti!$B$7+Coefficienti!$B$8*F$15+Coefficienti!$B$9*$A18)+Coefficienti!$B$10)*(1-Parametri!$B$4))*(1+Parametri!$B$5)+FerrGriglia!F4+Coefficienti!$B$11*Parametri!$B$6,2) | G18: =ROUND((((Coefficienti!$B$1+Coefficienti!$B$2*G$15+Coefficienti!$B$3*$A18)*Parametri!$B$1+(Coefficienti!$B$4+Coefficienti!$B$5*G$15+Coefficienti!$B$6*$A18)*Parametri!$B$2)*(1-Parametri!$B$3)+((Coefficienti!$B$7+Coefficienti!$B$8*G$15+Coefficienti!$B$9*$A18)+Coefficienti!$B$10)*(1-Parametri!$B$4))*(1+Parametri!$B$5)+FerrGriglia!G4+Coefficienti!$B$11*Parametri!$B$6,2) | H18: =ROUND((((Coefficienti!$B$1+Coefficienti!$B$2*H$15+Coefficienti!$B$3*$A18)*Parametri!$B$1+(Coefficienti!$B$4+Coefficienti!$B$5*H$15+Coefficienti!$B$6*$A18)*Parametri!$B$2)*(1-Parametri!$B$3)+((Coefficienti!$B$7+Coefficienti!$B$8*H$15+Coefficienti!$B$9*$A18)+Coefficienti!$B$10)*(1-Parametri!$B$4))*(1+Parametri!$B$5)+FerrGriglia!H4+Coefficienti!$B$11*Parametri!$B$6,2) | I18: =ROUND((((Coefficienti!$B$1+Coefficienti!$B$2*I$15+Coefficienti!$B$3*$A18)*Parametri!$B$1+(Coefficienti!$B$4+Coefficienti!$B$5*I$15+Coefficienti!$B$6*$A18)*Parametri!$B$2)*(1-Parametri!$B$3)+((Coefficienti!$B$7+Coefficienti!$B$8*I$15+Coefficienti!$B$9*$A18)+Coefficienti!$B$10)*(1-Parametri!$B$4))*(1+Parametri!$B$5)+FerrGriglia!I4+Coefficienti!$B$11*Parametri!$B$6,2) | ... L18: =ROUND((((Coefficienti!$B$1+Coefficienti!$B$2*L$15+Coefficienti!$B$3*$A18)*Parametri!$B$1+(Coefficienti!$B$4+Coefficienti!$B$5*L$15+Coefficienti!$B$6*$A18)*Parametri!$B$2)*(1-Parametri!$B$3)+((Coefficienti!$B$7+Coefficienti!$B$8*L$15+Coefficienti!$B$9*$A18)+Coefficienti!$B$10)*(1-Parametri!$B$4))*(1+Parametri!$B$5)+FerrGriglia!L4+Coefficienti!$B$11*Parametri!$B$6,2)
A19: 2200 | B19: =ROUND((((Coefficienti!$B$1+Coefficienti!$B$2*B$15+Coefficienti!$B$3*$A19)*Parametri!$B$1+(Coefficienti!$B$4+Coefficienti!$B$5*B$15+Coefficienti!$B$6*$A19)*Parametri!$B$2)*(1-Parametri!$B$3)+((Coefficienti!$B$7+Coefficienti!$B$8*B$15+Coefficienti!$B$9*$A19)+Coefficienti!$B$10)*(1-Parametri!$B$4))*(1+Parametri!$B$5)+FerrGriglia!B5+Coefficienti!$B$11*Parametri!$B$6,2) | C19: =ROUND((((Coefficienti!$B$1+Coefficienti!$B$2*C$15+Coefficienti!$B$3*$A19)*Parametri!$B$1+(Coefficienti!$B$4+Coefficienti!$B$5*C$15+Coefficienti!$B$6*$A19)*Parametri!$B$2)*(1-Parametri!$B$3)+((Coefficienti!$B$7+Coefficienti!$B$8*C$15+Coefficienti!$B$9*$A19)+Coefficienti!$B$10)*(1-Parametri!$B$4))*(1+Parametri!$B$5)+FerrGriglia!C5+Coefficienti!$B$11*Parametri!$B$6,2) | D19: =ROUND((((Coefficienti!$B$1+Coefficienti!$B$2*D$15+Coefficienti!$B$3*$A19)*Parametri!$B$1+(Coefficienti!$B$4+Coefficienti!$B$5*D$15+Coefficienti!$B$6*$A19)*Parametri!$B$2)*(1-Parametri!$B$3)+((Coefficienti!$B$7+Coefficienti!$B$8*D$15+Coefficienti!$B$9*$A19)+Coefficienti!$B$10)*(1-Parametri!$B$4))*(1+Parametri!$B$5)+FerrGriglia!D5+Coefficienti!$B$11*Parametri!$B$6,2) | E19: =ROUND((((Coefficienti!$B$1+Coefficienti!$B$2*E$15+Coefficienti!$B$3*$A19)*Parametri!$B$1+(Coefficienti!$B$4+Coefficienti!$B$5*E$15+Coefficienti!$B$6*$A19)*Parametri!$B$2)*(1-Parametri!$B$3)+((Coefficienti!$B$7+Coefficienti!$B$8*E$15+Coefficienti!$B$9*$A19)+Coefficienti!$B$10)*(1-Parametri!$B$4))*(1+Parametri!$B$5)+FerrGriglia!E5+Coefficienti!$B$11*Parametri!$B$6,2) | F19: =ROUND((((Coefficienti!$B$1+Coefficienti!$B$2*F$15+Coefficienti!$B$3*$A19)*Parametri!$B$1+(Coefficienti!$B$4+Coefficienti!$B$5*F$15+Coefficienti!$B$6*$A19)*Parametri!$B$2)*(1-Parametri!$B$3)+((Coefficienti!$B$7+Coefficienti!$B$8*F$15+Coefficienti!$B$9*$A19)+Coefficienti!$B$10)*(1-Parametri!$B$4))*(1+Parametri!$B$5)+FerrGriglia!F5+Coefficienti!$B$11*Parametri!$B$6,2) | G19: =ROUND((((Coefficienti!$B$1+Coefficienti!$B$2*G$15+Coefficienti!$B$3*$A19)*Parametri!$B$1+(Coefficienti!$B$4+Coefficienti!$B$5*G$15+Coefficienti!$B$6*$A19)*Parametri!$B$2)*(1-Parametri!$B$3)+((Coefficienti!$B$7+Coefficienti!$B$8*G$15+Coefficienti!$B$9*$A19)+Coefficienti!$B$10)*(1-Parametri!$B$4))*(1+Parametri!$B$5)+FerrGriglia!G5+Coefficienti!$B$11*Parametri!$B$6,2) | H19: =ROUND((((Coefficienti!$B$1+Coefficienti!$B$2*H$15+Coefficienti!$B$3*$A19)*Parametri!$B$1+(Coefficienti!$B$4+Coefficienti!$B$5*H$15+Coefficienti!$B$6*$A19)*Parametri!$B$2)*(1-Parametri!$B$3)+((Coefficienti!$B$7+Coefficienti!$B$8*H$15+Coefficienti!$B$9*$A19)+Coefficienti!$B$10)*(1-Parametri!$B$4))*(1+Parametri!$B$5)+FerrGriglia!H5+Coefficienti!$B$11*Parametri!$B$6,2) | I19: =ROUND((((Coefficienti!$B$1+Coefficienti!$B$2*I$15+Coefficienti!$B$3*$A19)*Parametri!$B$1+(Coefficienti!$B$4+Coefficienti!$B$5*I$15+Coefficienti!$B$6*$A19)*Parametri!$B$2)*(1-Parametri!$B$3)+((Coefficienti!$B$7+Coefficienti!$B$8*I$15+Coefficienti!$B$9*$A19)+Coefficienti!$B$10)*(1-Parametri!$B$4))*(1+Parametri!$B$5)+FerrGriglia!I5+Coefficienti!$B$11*Parametri!$B$6,2) | ... L19: =ROUND((((Coefficienti!$B$1+Coefficienti!$B$2*L$15+Coefficienti!$B$3*$A19)*Parametri!$B$1+(Coefficienti!$B$4+Coefficienti!$B$5*L$15+Coefficienti!$B$6*$A19)*Parametri!$B$2)*(1-Parametri!$B$3)+((Coefficienti!$B$7+Coefficienti!$B$8*L$15+Coefficienti!$B$9*$A19)+Coefficienti!$B$10)*(1-Parametri!$B$4))*(1+Parametri!$B$5)+FerrGriglia!L5+Coefficienti!$B$11*Parametri!$B$6,2)
A20: 2300 | B20: =ROUND((((Coefficienti!$B$1+Coefficienti!$B$2*B$15+Coefficienti!$B$3*$A20)*Parametri!$B$1+(Coefficienti!$B$4+Coefficienti!$B$5*B$15+Coefficienti!$B$6*$A20)*Parametri!$B$2)*(1-Parametri!$B$3)+((Coefficienti!$B$7+Coefficienti!$B$8*B$15+Coefficienti!$B$9*$A20)+Coefficienti!$B$10)*(1-Parametri!$B$4))*(1+Parametri!$B$5)+FerrGriglia!B6+Coefficienti!$B$11*Parametri!$B$6,2) | C20: =ROUND((((Coefficienti!$B$1+Coefficienti!$B$2*C$15+Coefficienti!$B$3*$A20)*Parametri!$B$1+(Coefficienti!$B$4+Coefficienti!$B$5*C$15+Coefficienti!$B$6*$A20)*Parametri!$B$2)*(1-Parametri!$B$3)+((Coefficienti!$B$7+Coefficienti!$B$8*C$15+Coefficienti!$B$9*$A20)+Coefficienti!$B$10)*(1-Parametri!$B$4))*(1+Parametri!$B$5)+FerrGriglia!C6+Coefficienti!$B$11*Parametri!$B$6,2) | D20: =ROUND((((Coefficienti!$B$1+Coefficienti!$B$2*D$15+Coefficienti!$B$3*$A20)*Parametri!$B$1+(Coefficienti!$B$4+Coefficienti!$B$5*D$15+Coefficienti!$B$6*$A20)*Parametri!$B$2)*(1-Parametri!$B$3)+((Coefficienti!$B$7+Coefficienti!$B$8*D$15+Coefficienti!$B$9*$A20)+Coefficienti!$B$10)*(1-Parametri!$B$4))*(1+Parametri!$B$5)+FerrGriglia!D6+Coefficienti!$B$11*Parametri!$B$6,2) | E20: =ROUND((((Coefficienti!$B$1+Coefficienti!$B$2*E$15+Coefficienti!$B$3*$A20)*Parametri!$B$1+(Coefficienti!$B$4+Coefficienti!$B$5*E$15+Coefficienti!$B$6*$A20)*Parametri!$B$2)*(1-Parametri!$B$3)+((Coefficienti!$B$7+Coefficienti!$B$8*E$15+Coefficienti!$B$9*$A20)+Coefficienti!$B$10)*(1-Parametri!$B$4))*(1+Parametri!$B$5)+FerrGriglia!E6+Coefficienti!$B$11*Parametri!$B$6,2) | F20: =ROUND((((Coefficienti!$B$1+Coefficienti!$B$2*F$15+Coefficienti!$B$3*$A20)*Parametri!$B$1+(Coefficienti!$B$4+Coefficienti!$B$5*F$15+Coefficienti!$B$6*$A20)*Parametri!$B$2)*(1-Parametri!$B$3)+((Coefficienti!$B$7+Coefficienti!$B$8*F$15+Coefficienti!$B$9*$A20)+Coefficienti!$B$10)*(1-Parametri!$B$4))*(1+Parametri!$B$5)+FerrGriglia!F6+Coefficienti!$B$11*Parametri!$B$6,2) | G20: =ROUND((((Coefficienti!$B$1+Coefficienti!$B$2*G$15+Coefficienti!$B$3*$A20)*Parametri!$B$1+(Coefficienti!$B$4+Coefficienti!$B$5*G$15+Coefficienti!$B$6*$A20)*Parametri!$B$2)*(1-Parametri!$B$3)+((Coefficienti!$B$7+Coefficienti!$B$8*G$15+Coefficienti!$B$9*$A20)+Coefficienti!$B$10)*(1-Parametri!$B$4))*(1+Parametri!$B$5)+FerrGriglia!G6+Coefficienti!$B$11*Parametri!$B$6,2) | H20: =ROUND((((Coefficienti!$B$1+Coefficienti!$B$2*H$15+Coefficienti!$B$3*$A20)*Parametri!$B$1+(Coefficienti!$B$4+Coefficienti!$B$5*H$15+Coefficienti!$B$6*$A20)*Parametri!$B$2)*(1-Parametri!$B$3)+((Coefficienti!$B$7+Coefficienti!$B$8*H$15+Coefficienti!$B$9*$A20)+Coefficienti!$B$10)*(1-Parametri!$B$4))*(1+Parametri!$B$5)+FerrGriglia!H6+Coefficienti!$B$11*Parametri!$B$6,2) | I20: =ROUND((((Coefficienti!$B$1+Coefficienti!$B$2*I$15+Coefficienti!$B$3*$A20)*Parametri!$B$1+(Coefficienti!$B$4+Coefficienti!$B$5*I$15+Coefficienti!$B$6*$A20)*Parametri!$B$2)*(1-Parametri!$B$3)+((Coefficienti!$B$7+Coefficienti!$B$8*I$15+Coefficienti!$B$9*$A20)+Coefficienti!$B$10)*(1-Parametri!$B$4))*(1+Parametri!$B$5)+FerrGriglia!I6+Coefficienti!$B$11*Parametri!$B$6,2) | ... L20: =ROUND((((Coefficienti!$B$1+Coefficienti!$B$2*L$15+Coefficienti!$B$3*$A20)*Parametri!$B$1+(Coefficienti!$B$4+Coefficienti!$B$5*L$15+Coefficienti!$B$6*$A20)*Parametri!$B$2)*(1-Parametri!$B$3)+((Coefficienti!$B$7+Coefficienti!$B$8*L$15+Coefficienti!$B$9*$A20)+Coefficienti!$B$10)*(1-Parametri!$B$4))*(1+Parametri!$B$5)+FerrGriglia!L6+Coefficienti!$B$11*Parametri!$B$6,2)
A21: 2400 | B21: =ROUND((((Coefficienti!$B$1+Coefficienti!$B$2*B$15+Coefficienti!$B$3*$A21)*Parametri!$B$1+(Coefficienti!$B$4+Coefficienti!$B$5*B$15+Coefficienti!$B$6*$A21)*Parametri!$B$2)*(1-Parametri!$B$3)+((Coefficienti!$B$7+Coefficienti!$B$8*B$15+Coefficienti!$B$9*$A21)+Coefficienti!$B$10)*(1-Parametri!$B$4))*(1+Parametri!$B$5)+FerrGriglia!B7+Coefficienti!$B$11*Parametri!$B$6,2) | C21: =ROUND((((Coefficienti!$B$1+Coefficienti!$B$2*C$15+Coefficienti!$B$3*$A21)*Parametri!$B$1+(Coefficienti!$B$4+Coefficienti!$B$5*C$15+Coefficienti!$B$6*$A21)*Parametri!$B$2)*(1-Parametri!$B$3)+((Coefficienti!$B$7+Coefficienti!$B$8*C$15+Coefficienti!$B$9*$A21)+Coefficienti!$B$10)*(1-Parametri!$B$4))*(1+Parametri!$B$5)+FerrGriglia!C7+Coefficienti!$B$11*Parametri!$B$6,2) | D21: =ROUND((((Coefficienti!$B$1+Coefficienti!$B$2*D$15+Coefficienti!$B$3*$A21)*Parametri!$B$1+(Coefficienti!$B$4+Coefficienti!$B$5*D$15+Coefficienti!$B$6*$A21)*Parametri!$B$2)*(1-Parametri!$B$3)+((Coefficienti!$B$7+Coefficienti!$B$8*D$15+Coefficienti!$B$9*$A21)+Coefficienti!$B$10)*(1-Parametri!$B$4))*(1+Parametri!$B$5)+FerrGriglia!D7+Coefficienti!$B$11*Parametri!$B$6,2) | E21: =ROUND((((Coefficienti!$B$1+Coefficienti!$B$2*E$15+Coefficienti!$B$3*$A21)*Parametri!$B$1+(Coefficienti!$B$4+Coefficienti!$B$5*E$15+Coefficienti!$B$6*$A21)*Parametri!$B$2)*(1-Parametri!$B$3)+((Coefficienti!$B$7+Coefficienti!$B$8*E$15+Coefficienti!$B$9*$A21)+Coefficienti!$B$10)*(1-Parametri!$B$4))*(1+Parametri!$B$5)+FerrGriglia!E7+Coefficienti!$B$11*Parametri!$B$6,2) | F21: =ROUND((((Coefficienti!$B$1+Coefficienti!$B$2*F$15+Coefficienti!$B$3*$A21)*Parametri!$B$1+(Coefficienti!$B$4+Coefficienti!$B$5*F$15+Coefficienti!$B$6*$A21)*Parametri!$B$2)*(1-Parametri!$B$3)+((Coefficienti!$B$7+Coefficienti!$B$8*F$15+Coefficienti!$B$9*$A21)+Coefficienti!$B$10)*(1-Parametri!$B$4))*(1+Parametri!$B$5)+FerrGriglia!F7+Coefficienti!$B$11*Parametri!$B$6,2) | G21: =ROUND((((Coefficienti!$B$1+Coefficienti!$B$2*G$15+Coefficienti!$B$3*$A21)*Parametri!$B$1+(Coefficienti!$B$4+Coefficienti!$B$5*G$15+Coefficienti!$B$6*$A21)*Parametri!$B$2)*(1-Parametri!$B$3)+((Coefficienti!$B$7+Coefficienti!$B$8*G$15+Coefficienti!$B$9*$A21)+Coefficienti!$B$10)*(1-Parametri!$B$4))*(1+Parametri!$B$5)+FerrGriglia!G7+Coefficienti!$B$11*Parametri!$B$6,2) | H21: =ROUND((((Coefficienti!$B$1+Coefficienti!$B$2*H$15+Coefficienti!$B$3*$A21)*Parametri!$B$1+(Coefficienti!$B$4+Coefficienti!$B$5*H$15+Coefficienti!$B$6*$A21)*Parametri!$B$2)*(1-Parametri!$B$3)+((Coefficienti!$B$7+Coefficienti!$B$8*H$15+Coefficienti!$B$9*$A21)+Coefficienti!$B$10)*(1-Parametri!$B$4))*(1+Parametri!$B$5)+FerrGriglia!H7+Coefficienti!$B$11*Parametri!$B$6,2) | I21: =ROUND((((Coefficienti!$B$1+Coefficienti!$B$2*I$15+Coefficienti!$B$3*$A21)*Parametri!$B$1+(Coefficienti!$B$4+Coefficienti!$B$5*I$15+Coefficienti!$B$6*$A21)*Parametri!$B$2)*(1-Parametri!$B$3)+((Coefficienti!$B$7+Coefficienti!$B$8*I$15+Coefficienti!$B$9*$A21)+Coefficienti!$B$10)*(1-Parametri!$B$4))*(1+Parametri!$B$5)+FerrGriglia!I7+Coefficienti!$B$11*Parametri!$B$6,2) | ... L21: =ROUND((((Coefficienti!$B$1+Coefficienti!$B$2*L$15+Coefficienti!$B$3*$A21)*Parametri!$B$1+(Coefficienti!$B$4+Coefficienti!$B$5*L$15+Coefficienti!$B$6*$A21)*Parametri!$B$2)*(1-Parametri!$B$3)+((Coefficienti!$B$7+Coefficienti!$B$8*L$15+Coefficienti!$B$9*$A21)+Coefficienti!$B$10)*(1-Parametri!$B$4))*(1+Parametri!$B$5)+FerrGriglia!L7+Coefficienti!$B$11*Parametri!$B$6,2)
A22: 2500 | B22: =ROUND((((Coefficienti!$B$1+Coefficienti!$B$2*B$15+Coefficienti!$B$3*$A22)*Parametri!$B$1+(Coefficienti!$B$4+Coefficienti!$B$5*B$15+Coefficienti!$B$6*$A22)*Parametri!$B$2)*(1-Parametri!$B$3)+((Coefficienti!$B$7+Coefficienti!$B$8*B$15+Coefficienti!$B$9*$A22)+Coefficienti!$B$10)*(1-Parametri!$B$4))*(1+Parametri!$B$5)+FerrGriglia!B8+Coefficienti!$B$11*Parametri!$B$6,2) | C22: =ROUND((((Coefficienti!$B$1+Coefficienti!$B$2*C$15+Coefficienti!$B$3*$A22)*Parametri!$B$1+(Coefficienti!$B$4+Coefficienti!$B$5*C$15+Coefficienti!$B$6*$A22)*Parametri!$B$2)*(1-Parametri!$B$3)+((Coefficienti!$B$7+Coefficienti!$B$8*C$15+Coefficienti!$B$9*$A22)+Coefficienti!$B$10)*(1-Parametri!$B$4))*(1+Parametri!$B$5)+FerrGriglia!C8+Coefficienti!$B$11*Parametri!$B$6,2) | D22: =ROUND((((Coefficienti!$B$1+Coefficienti!$B$2*D$15+Coefficienti!$B$3*$A22)*Parametri!$B$1+(Coefficienti!$B$4+Coefficienti!$B$5*D$15+Coefficienti!$B$6*$A22)*Parametri!$B$2)*(1-Parametri!$B$3)+((Coefficienti!$B$7+Coefficienti!$B$8*D$15+Coefficienti!$B$9*$A22)+Coefficienti!$B$10)*(1-Parametri!$B$4))*(1+Parametri!$B$5)+FerrGriglia!D8+Coefficienti!$B$11*Parametri!$B$6,2) | E22: =ROUND((((Coefficienti!$B$1+Coefficienti!$B$2*E$15+Coefficienti!$B$3*$A22)*Parametri!$B$1+(Coefficienti!$B$4+Coefficienti!$B$5*E$15+Coefficienti!$B$6*$A22)*Parametri!$B$2)*(1-Parametri!$B$3)+((Coefficienti!$B$7+Coefficienti!$B$8*E$15+Coefficienti!$B$9*$A22)+Coefficienti!$B$10)*(1-Parametri!$B$4))*(1+Parametri!$B$5)+FerrGriglia!E8+Coefficienti!$B$11*Parametri!$B$6,2) | F22: =ROUND((((Coefficienti!$B$1+Coefficienti!$B$2*F$15+Coefficienti!$B$3*$A22)*Parametri!$B$1+(Coefficienti!$B$4+Coefficienti!$B$5*F$15+Coefficienti!$B$6*$A22)*Parametri!$B$2)*(1-Parametri!$B$3)+((Coefficienti!$B$7+Coefficienti!$B$8*F$15+Coefficienti!$B$9*$A22)+Coefficienti!$B$10)*(1-Parametri!$B$4))*(1+Parametri!$B$5)+FerrGriglia!F8+Coefficienti!$B$11*Parametri!$B$6,2) | G22: =ROUND((((Coefficienti!$B$1+Coefficienti!$B$2*G$15+Coefficienti!$B$3*$A22)*Parametri!$B$1+(Coefficienti!$B$4+Coefficienti!$B$5*G$15+Coefficienti!$B$6*$A22)*Parametri!$B$2)*(1-Parametri!$B$3)+((Coefficienti!$B$7+Coefficienti!$B$8*G$15+Coefficienti!$B$9*$A22)+Coefficienti!$B$10)*(1-Parametri!$B$4))*(1+Parametri!$B$5)+FerrGriglia!G8+Coefficienti!$B$11*Parametri!$B$6,2) | H22: =ROUND((((Coefficienti!$B$1+Coefficienti!$B$2*H$15+Coefficienti!$B$3*$A22)*Parametri!$B$1+(Coefficienti!$B$4+Coefficienti!$B$5*H$15+Coefficienti!$B$6*$A22)*Parametri!$B$2)*(1-Parametri!$B$3)+((Coefficienti!$B$7+Coefficienti!$B$8*H$15+Coefficienti!$B$9*$A22)+Coefficienti!$B$10)*(1-Parametri!$B$4))*(1+Parametri!$B$5)+FerrGriglia!H8+Coefficienti!$B$11*Parametri!$B$6,2) | I22: =ROUND((((Coefficienti!$B$1+Coefficienti!$B$2*I$15+Coefficienti!$B$3*$A22)*Parametri!$B$1+(Coefficienti!$B$4+Coefficienti!$B$5*I$15+Coefficienti!$B$6*$A22)*Parametri!$B$2)*(1-Parametri!$B$3)+((Coefficienti!$B$7+Coefficienti!$B$8*I$15+Coefficienti!$B$9*$A22)+Coefficienti!$B$10)*(1-Parametri!$B$4))*(1+Parametri!$B$5)+FerrGriglia!I8+Coefficienti!$B$11*Parametri!$B$6,2) | ... L22: =ROUND((((Coefficienti!$B$1+Coefficienti!$B$2*L$15+Coefficienti!$B$3*$A22)*Parametri!$B$1+(Coefficienti!$B$4+Coefficienti!$B$5*L$15+Coefficienti!$B$6*$A22)*Parametri!$B$2)*(1-Parametri!$B$3)+((Coefficienti!$B$7+Coefficienti!$B$8*L$15+Coefficienti!$B$9*$A22)+Coefficienti!$B$10)*(1-Parametri!$B$4))*(1+Parametri!$B$5)+FerrGriglia!L8+Coefficienti!$B$11*Parametri!$B$6,2)
A23: 2600 | B23: =ROUND((((Coefficienti!$B$1+Coefficienti!$B$2*B$15+Coefficienti!$B$3*$A23)*Parametri!$B$1+(Coefficienti!$B$4+Coefficienti!$B$5*B$15+Coefficienti!$B$6*$A23)*Parametri!$B$2)*(1-Parametri!$B$3)+((Coefficienti!$B$7+Coefficienti!$B$8*B$15+Coefficienti!$B$9*$A23)+Coefficienti!$B$10)*(1-Parametri!$B$4))*(1+Parametri!$B$5)+FerrGriglia!B9+Coefficienti!$B$11*Parametri!$B$6,2) | C23: =ROUND((((Coefficienti!$B$1+Coefficienti!$B$2*C$15+Coefficienti!$B$3*$A23)*Parametri!$B$1+(Coefficienti!$B$4+Coefficienti!$B$5*C$15+Coefficienti!$B$6*$A23)*Parametri!$B$2)*(1-Parametri!$B$3)+((Coefficienti!$B$7+Coefficienti!$B$8*C$15+Coefficienti!$B$9*$A23)+Coefficienti!$B$10)*(1-Parametri!$B$4))*(1+Parametri!$B$5)+FerrGriglia!C9+Coefficienti!$B$11*Parametri!$B$6,2) | D23: =ROUND((((Coefficienti!$B$1+Coefficienti!$B$2*D$15+Coefficienti!$B$3*$A23)*Parametri!$B$1+(Coefficienti!$B$4+Coefficienti!$B$5*D$15+Coefficienti!$B$6*$A23)*Parametri!$B$2)*(1-Parametri!$B$3)+((Coefficienti!$B$7+Coefficienti!$B$8*D$15+Coefficienti!$B$9*$A23)+Coefficienti!$B$10)*(1-Parametri!$B$4))*(1+Parametri!$B$5)+FerrGriglia!D9+Coefficienti!$B$11*Parametri!$B$6,2) | E23: =ROUND((((Coefficienti!$B$1+Coefficienti!$B$2*E$15+Coefficienti!$B$3*$A23)*Parametri!$B$1+(Coefficienti!$B$4+Coefficienti!$B$5*E$15+Coefficienti!$B$6*$A23)*Parametri!$B$2)*(1-Parametri!$B$3)+((Coefficienti!$B$7+Coefficienti!$B$8*E$15+Coefficienti!$B$9*$A23)+Coefficienti!$B$10)*(1-Parametri!$B$4))*(1+Parametri!$B$5)+FerrGriglia!E9+Coefficienti!$B$11*Parametri!$B$6,2) | F23: =ROUND((((Coefficienti!$B$1+Coefficienti!$B$2*F$15+Coefficienti!$B$3*$A23)*Parametri!$B$1+(Coefficienti!$B$4+Coefficienti!$B$5*F$15+Coefficienti!$B$6*$A23)*Parametri!$B$2)*(1-Parametri!$B$3)+((Coefficienti!$B$7+Coefficienti!$B$8*F$15+Coefficienti!$B$9*$A23)+Coefficienti!$B$10)*(1-Parametri!$B$4))*(1+Parametri!$B$5)+FerrGriglia!F9+Coefficienti!$B$11*Parametri!$B$6,2) | G23: =ROUND((((Coefficienti!$B$1+Coefficienti!$B$2*G$15+Coefficienti!$B$3*$A23)*Parametri!$B$1+(Coefficienti!$B$4+Coefficienti!$B$5*G$15+Coefficienti!$B$6*$A23)*Parametri!$B$2)*(1-Parametri!$B$3)+((Coefficienti!$B$7+Coefficienti!$B$8*G$15+Coefficienti!$B$9*$A23)+Coefficienti!$B$10)*(1-Parametri!$B$4))*(1+Parametri!$B$5)+FerrGriglia!G9+Coefficienti!$B$11*Parametri!$B$6,2) | H23: =ROUND((((Coefficienti!$B$1+Coefficienti!$B$2*H$15+Coefficienti!$B$3*$A23)*Parametri!$B$1+(Coefficienti!$B$4+Coefficienti!$B$5*H$15+Coefficienti!$B$6*$A23)*Parametri!$B$2)*(1-Parametri!$B$3)+((Coefficienti!$B$7+Coefficienti!$B$8*H$15+Coefficienti!$B$9*$A23)+Coefficienti!$B$10)*(1-Parametri!$B$4))*(1+Parametri!$B$5)+FerrGriglia!H9+Coefficienti!$B$11*Parametri!$B$6,2) | I23: =ROUND((((Coefficienti!$B$1+Coefficienti!$B$2*I$15+Coefficienti!$B$3*$A23)*Parametri!$B$1+(Coefficienti!$B$4+Coefficienti!$B$5*I$15+Coefficienti!$B$6*$A23)*Parametri!$B$2)*(1-Parametri!$B$3)+((Coefficienti!$B$7+Coefficienti!$B$8*I$15+Coefficienti!$B$9*$A23)+Coefficienti!$B$10)*(1-Parametri!$B$4))*(1+Parametri!$B$5)+FerrGriglia!I9+Coefficienti!$B$11*Parametri!$B$6,2) | ... L23: =ROUND((((Coefficienti!$B$1+Coefficienti!$B$2*L$15+Coefficienti!$B$3*$A23)*Parametri!$B$1+(Coefficienti!$B$4+Coefficienti!$B$5*L$15+Coefficienti!$B$6*$A23)*Parametri!$B$2)*(1-Parametri!$B$3)+((Coefficienti!$B$7+Coefficienti!$B$8*L$15+Coefficienti!$B$9*$A23)+Coefficienti!$B$10)*(1-Parametri!$B$4))*(1+Parametri!$B$5)+FerrGriglia!L9+Coefficienti!$B$11*Parametri!$B$6,2)
